Workbook
Name _PM25: #REF!
Name _PM25: #REF!
Name _PM25: #REF!
Name _PM25: #REF!
Name _PM25: #REF!
Name _PM25: #REF!
Name _PM25: #REF!
Name _PM25: #REF!
Name _PM32: #REF!
Name _PM32: #REF!
Name _PM32: #REF!
Name _PM32: #REF!
Name _PM32: #REF!
Name _PM32: #REF!
Name _PM32: #REF!
Name _PM32: #REF!
Name KONST1: #REF!
Name KONST1: #REF!
Name KONST1: #REF!
Name KONST1: #REF!
Name KONST1: #REF!
Name KONST1: #REF!
Name KONST1: #REF!
Name KONST1: #REF!
Name KONST2: #REF!
Name KONST2: #REF!
Name KONST2: #REF!
Name KONST2: #REF!
Name KONST2: #REF!
Name KONST2: #REF!
Name KONST2: #REF!
Name KONST2: #REF!
Name KONST3: #REF!
Name KONST3: #REF!
Name KONST3: #REF!
Name KONST3: #REF!
Name KONST3: #REF!
Name KONST3: #REF!
Name KONST3: #REF!
Name KONST3: #REF!
Name MASS1: #REF!
Name MASS1: #REF!
Name MASS1: #REF!
Name MASS1: #REF!
Name MASS2: #REF!
Name MASS2: #REF!
Name MASS2: #REF!
Name MASS2: #REF!
Name MASS3: #REF!
Name MASS3: #REF!
Name MASS3: #REF!
Name MASS3: #REF!
Name MASS4: #REF!
Name MASS4: #REF!
Name MASS4: #REF!
Name MASS4: #REF!
Name MASS5: #REF!
Name MASS5: #REF!
Name MASS5: #REF!
Name MASS5: #REF!

Sheet Data
B1: PP | E1: GS | I1: CT90 | R1: UCS | S1: Undis | T1: Remol | V1: TRX UU | Z1: DS
A2: SG | B2: 1 | C2: 2 | E2: 0 | F2: 60.1 | G2: berat | I2: 0.9945 | J2: 0.9909 | K2: 0.98 | L2: 0.954 | M2: 0.896 | N2: 0.8152 | O2: 0.7 | P2: 0.7182 | V2: 0 | W2: 0 | X2: 0
B3: 10.454 | C3: 10.46 | E3: 0 | F3: 20 | G3: suhu | I3: 0.9923 | J3: 0.9873 | K3: 0.9716 | L3: 0.94 | M3: 0.8814 | N3: 0.8012 | V3: 6 | W3: 15 | X3: 33
B4: 25 | C4: 25 | E4: 0 | F4: 55 | I4: 0.992 | J4: 0.9868 | K4: 0.9702 | L4: 0.9378 | M4: 0.8792 | N4: 0.7967 | V4: 11 | W4: 25 | X4: 45
B5: 158.621 | C5: 159.368 | E5: 0 | F5: 54 | I5: 0.9917 | J5: 0.986 | K5: 0.968 | L5: 0.9356 | M5: 0.8761 | N5: 0.7928 | V5: 16 | W5: 33 | X5: 55
A6: MC | B6: 137 | C6: 46 | E6: 0 | F6: 53 | I6: 0.9914 | J6: 0.9853 | K6: 0.9664 | L6: 0.933 | M6: 0.8721 | N6: 0.7886 | V6: 21 | W6: 38 | X6: 63
B7: 96.888 | C7: 105.404 | E7: 0 | F7: 51 | I7: 0.9912 | J7: 0.9847 | K7: 0.9648 | L7: 0.9293 | M7: 0.8681 | N7: 0.7814 | V7: 25 | W7: 43 | X7: 69
B8: 70.671 | C8: 75.591 | E8: 0 | F8: 48 | I8: 0.991 | J8: 0.984 | K8: 0.9633 | L8: 0.926 | M8: 0.8614 | N8: 0.7732 | V8: 29 | W8: 47 | X8: 75
A9: UW | B9: 1 | E9: 0 | F9: 46 | I9: 0.9909 | J9: 0.9832 | K9: 0.9616 | L9: 0.922 | M9: 0.8541 | N9: 0.7654 | V9: 31 | W9: 51 | X9: 80
B10: 94.969 | E10: 0.957 | F10: 44 | I10: 0.9909 | J10: 0.9826 | K10: 0.9599 | L10: 0.917 | M10: 0.8447 | N10: 0.7541 | V10: 35 | W10: 54 | X10: 85
E11: 1.982 | F11: 37 | I11: 0.9909 | J11: 0.982 | K11: 0.958 | L11: 0.9098 | M11: 0.8355 | N11: 0.7415 | V11: 37 | W11: 58 | X11: 89
E12: 2.222 | F12: 25 | I12: 0.9909 | J12: 0.9812 | K12: 0.9562 | L12: 0.9041 | M12: 0.8287 | N12: 0.7272 | V12: 39 | W12: 60 | X12: 94
E13: 1.968 | I13: 0.9909 | J13: 0.9809 | K13: 0.9548 | L13: 0.9 | M13: 0.8222 | N13: 0.7163 | V13: 41 | W13: 62 | X13: 100
E14: 0.818 | I14: 0.9909 | J14: 0.9806 | K14: 0.9544 | L14: 0.897 | M14: 0.8193 | N14: 0.7102 | V14: 43 | W14: 64 | X14: 102
E15: 1.14 | I15: 0.9909 | J15: 0.98 | K15: 0.954 | L15: 0.896 | M15: 0.8152 | N15: 0.7 | O15: 0.7182 | P15: 0.7436 | V15: 45 | W15: 66 | X15: 105
H16: dry soil | I16: 47.283937 | K16: 47.283937 | V16: 47 | W16: 68 | X16: 110
H17: container no | I17: 1 | K17: 1 | V17: 49 | W17: 70 | X17: 113
H18: con + wet soil | I18: 75.611 | K18: 75.611 | V18: 51 | W18: 72 | X18: 115
H19: container w | I19: 8.834 | K19: 8.834 | V19: 53 | W19: 74 | X19: 118
V20: 55 | W20: 76 | X20: 120
V21: 56 | W21: 77 | X21: 122
V22: 58 | W22: 78 | X22: 124
V23: 59 | W23: 79 | X23: 126
V24: 59 | W24: 79.5 | X24: 128
V25: 59 | W25: 80 | X25: 130
V26: 59 | W26: 80 | X26: 131
V27: 59 | W27: 80 | X27: 131.5
V28: 59 | W28: 80 | X28: 132
W29: 80 | X29: 132
W30: 80 | X30: 132
X31: 132
X32: 132

Sheet Resume
D3: GEOLAND QUATTRO TECHNOLAB
D4: JL. Nata Endah, Komplek Indahco No.22 Kel. Margahayu Tengah
D5: Kec. Margahayu, Kab. Bandung 40225
D6: Telp/WhatsApp : 082115618130
D7: Email : geolandquattro@gmail.com; geolandquattro@geolandtechnolab.com
C9: LAPORAN HASIL UJI
C10: Report of Analysis
C11: =Details!B2 -> MGS/02/VI/2026
C12: Nama Pelanggan | E12: : | F12: =Details!B4 -> PT Itamatra Nusantara
C13: ( Customer Name ) | J13: LAB ID | K13: =": "&Details!B7 -> : 23-GQT--19-UDS-1-BH-05-0,00-0,50-100726-001
C15: Alamat | E15: : | F15: =Details!B5 -> Ganda Ganda, Petasia, Morowali Regency, Central Sulawesi | J15: Kode Sampel | L15: : | M15: =Details!B1 -> BH-05_UDS-01
C16: ( Addres ) | J16: ( Sampel Code )
C18: Proyek | E18: : | F18: =Details!B8 -> hidroplogi | J18: Kedalaman | L18: : | M18: =Details!B13&" m" -> 0,00-0,50 m
C19: ( Project ) | J19: ( Depth )
C21: Lokasi | E21: : | F21: =Details!B9 -> Morowali Utara | J21: Tanggal Terima Sampel | L21: : | M21: =Details!B18 -> 46213
C22: ( Location ) | J22: ( Received Date )
J24: Tanggal Analisis | L24: : | M24: =TEXT(Details!B19, "dd mmmm yyyy") & " - " & TEXT(Details!C18,"dd mmmm yyyy") -> 14 July 2026 - 00 January 1900
J25: ( Date of Analysis )
J27: Tanggal Laporan | L27: : | M27: =Details!B17 -> 0
J28: ( Report Date )
C30: No | D30: Parameter | G30: Metode Uji | H30: Sampel | K30: Hasil Pengujian
H31: Unit | I31: Satuan | K31: Hasil | N31: Keterangan
C32: Batas & Parameter Fisik / Index and Physical Properties
C33: 1 | D33: Berat Isi | G33: SNI 03 - 3637 : 1994 | H33: Yn | I33: gr/cm3 | K33: =PP!J39 -> 1.6849798 | N33: -
D34: Unit Weight
C35: 2 | D35: Berat Jenis | G35: SNI 1964 : 2008 | H35: Gs | I35: - | K35: =PP!J24 -> 2.6497359 | N35: -
D36: Specific Gravity
C37: 3 | D37: Kadar Air | G37: SNI 1965 : 2008 | H37: W | I37: % | K37: =PP!J33 -> 44.621389 | N37: -
D38: Moisture Content
C39: 4 | D39: Berat Kering | G39: SNI 03 - 3637 : 1994 | H39: ρd | I39: gr/cm3 | K39: =PP!J41 -> 1.1650972 | N39: -
D40: Dry Density
C41: 5 | D41: Rasio Pori | G41: SNI 03 - 3637 : 1994 | H41: n | I41: - | K41: =PP!J43 -> 0.56029686 | N41: -
D42: Porosity
C43: 6 | D43: Derajat Saturasi | G43: SNI 03 - 3637 : 1994 | H43: Sr | I43: % | K43: =PP!J44 -> 92.786986 | N43: -
D44: Degree of Saturation
C45: Sieve Analysis & Hydrometer test
C46: 7 | D46: Lempung | G46: SNI 3423 : 2008 | H46: - | I46: % | K46: ='A. GS'!Z3 -> 65.05 | N46: -
D47: Clay
C48: 8 | D48: Lanau | G48: SNI 3423 : 2008 | H48: - | I48: % | K48: ='A. GS'!Y3 -> 20.8 | N48: -
D49: Silt
...

Sheet PP
K2: Client | M2: =Details!B4 -> PT Itamatra Nusantara
K3: Project | M3: =Details!B8 -> hidroplogi
K4: Job No. | M4: =Details!B3 -> PO-GQT-19 | P4: Date | R4: =Details!B28 -> 46204
K5: Tested By | M5: =Details!B20 -> Rizki | P5: Checked By | R5: =Details!B22 -> AS Sumartadji
B7: INDEX PROPERTIES
AA8: 45819.675 | AC8: 0
C9: Location | E9: : AW 1 - 10 SALAK | F9: JL.MAYAMIN -SAMARINDA / KAWASAN STATION SEMPAJA | G9: =Details!B9 -> Morowali Utara | N9: Sample Type | O9: : | V9: temperature | W9: relative density | X9: correction | Z9: calibration of picnometer + water at 25 C | AD9: berat picnometer
N10: Sample No. | O10: : | W10: of water | X10: factor of K | Z10: No | AA10: weight (gr) | AD10: No. | AE10: berat (gr)
C11: Bore Hole No | J11: =Details!B1 -> BH-05_UDS-01 | V11: 18 | W11: 0.9986244 | X11: 1.0004 | Z11: 1 | AA11: 152.1022 | AD11: 1 | AE11: 52.9908
C12: Sample ID | Z12: 2 | AA12: 152.857 | AD12: 2 | AE12: 53.7774
C13: Depth | H13: meter | J13: =Details!B13 -> 0,00-0,50 | V13: 19 | W13: 0.9984347 | X13: 1.0002 | Z13: 3 | AA13: 153.2238 | AD13: 3 | AE13: 53.9802
C14: Soil Description | J14: ='A. GS'!H12 -> silty CLAY with sand | V14: 20 | W14: 0.9982343 | X14: 1 | Z14: 4 | AA14: 151.1122 | AD14: 4 | AE14: 51.4122
V15: 21 | W15: 0.9980233 | X15: 0.9998 | Z15: 5 | AA15: 154.83 | AD15: 5 | AE15: 55.0112
C16: SPECIFIC GRAVITY TEST (SNI 1964 : 2008) | V16: 22 | W16: 0.9978019 | X16: 0.9996 | Z16: 6 | AA16: 159.4988 | AD16: 6 | AE16: 63.0732
C17: Pycnometer No. | I17: R | J17: =Data!B2 -> 1 | K17: =Data!C2 -> 2 | V17: 23 | W17: 0.9975702 | X17: 0.9993 | Z17: 7 | AA17: 153.368 | AD17: 7 | AE17: 53.5314
C18: Wt. Of dry Soil (A) | H18: g | I18: 50 | J18: =Data!B3 -> 10.454 | K18: =Data!C3 -> 10.46 | V18: 24 | W18: 0.9973286 | X18: 0.9991 | Z18: 8 | AA18: 154.6622 | AD18: 8 | AE18: 59.7316
C19: Temperature (T) | H19: 0C | I19: 27 | J19: =Data!B4 -> 25 | K19: =Data!C4 -> 25 | V19: 25 | W19: 0.997077 | X19: 0.9989 | Z19: 9 | AA19: 164.126 | AD19: 9 | AE19: 59.7628
C20: Wt. Pycnometer + Water + Soil (B) | H20: g | I20: 165.92 | J20: =Data!B5 -> 158.621 | K20: =Data!C5 -> 159.368 | V20: 26 | W20: 0.9968156 | X20: 0.9986 | Z20: 10 | AA20: 155.2866 | AD20: 10 | AE20: 59.0038
C21: Wt Pycnometer + Water at T 0C (C) | H21: g | I21: 134.67 | J21: =IF(OR(J17="",J18="",J19="",J20=""),"",((VLOOKUP(J19,$V$11:$X$24,2)/$W$19)*(VLOOKUP(J17,$Z$11:$AA$68,2)-VLOOKUP(J17,$AD$11:$AE$68,2)))+VLOOKUP(J17,$AD$11:$AE$68,2,FALSE)) -> 152.1022 | K21: =IF(OR(K17="",K18="",K19="",K20=""),"",((VLOOKUP(K19,$V$11:$X$24,2)/$W$19)*(VLOOKUP(K17,$Z$11:$AA$68,2)-VLOOKUP(K17,$AD$11:$AE$68,2)))+VLOOKUP(K17,$AD$11:$AE$68,2,FALSE)) -> 152.857 | V21: 27 | W21: 0.9965451 | X21: 0.9983 | Z21: 11 | AA21: 156.669 | AD21: 11 | AE21: 58.2254
C22: A+(C-B) | H22: g | I22: =+(I18+I21)-I20 -> 18.75 | J22: =IF(OR(J17="",J18="",J19="",J20=""),"",J18+(J21-J20)) -> 3.9352 | K22: =IF(OR(K17="",K18="",K19="",K20=""),"",K18+(K21-K20)) -> 3.949 | V22: 28 | W22: 0.9962652 | X22: 0.998 | Z22: 12 | AA22: 158.2136 | AD22: 12 | AE22: 62.6674
C23: Specific Gravity (Gs) | I23: =+(I18/I22)*(0.99655) -> 2.6574667 | J23: =IF(OR(J17="",J18="",J20=""),"",(J18/J22)*(VLOOKUP(J19,$V$11:$X$24,3))) -> 2.6536137 | K23: =IF(OR(K17="",K18="",K20=""),"",(K18/K22)*(VLOOKUP(K19,$V$11:$X$24,3))) -> 2.6458582 | V23: 29 | W23: 0.9959761 | X23: 0.9977 | Z23: 13 | AA23: 156.4662 | AD23: 13 | AE23: 59.2952
C24: SPECIFIC GRAVITY Average (Gs) | J24: =IF(OR(J17="",J18="",J19="",J20=""),"",AVERAGE(J23:K23)) -> 2.6497359 | V24: 30 | W24: 0.995678 | X24: 0.9974 | Z24: 14 | AA24: 158.0556 | AD24: 14 | AE24: 61.0316
C25: MOISTURE CONTENT TEST (SNI 1965 : 2008) | Z25: 15 | AA25: 155.1908 | AD25: 15 | AE25: 60.3026
C26: No. Container | I26: ID | J26: =Data!B6 -> 137 | K26: =Data!C6 -> 46 | Z26: 16 | AA26: 159.4982 | AD26: 16 | AE26: 86.9434
C27: Wt. Container + Wet Soil | H27: g | I27: 203.12 | J27: =Data!B7 -> 96.888 | K27: =Data!C7 -> 105.404 | Z27: 17 | AA27: 155.9656 | AD27: 17 | AE27: 59.3672 | AG27: =60.14-7.47 -> 52.67 | AH27: =AG27/31.865 -> 1.6529107
C28: Wt. Container + Dry Soil | H28: g | I28: 166.84 | J28: =Data!B8 -> 70.671 | K28: =Data!C8 -> 75.591 | Z28: 18 | AA28: 157.4324 | AD28: 18 | AE28: 59.6842 | AG28: =51.74-7.47 -> 44.27
C29: Wt. Container | H29: g | I29: 45.87 | J29: =IFERROR(VLOOKUP(J26,ATB!$AN$9:$AO$212,2,0),"") -> 11.711 | K29: =IFERROR(VLOOKUP(K26,ATB!$AN$9:$AO$212,2,0),"") -> 9.01 | Z29: 19 | AA29: 156.4718 | AD29: 19 | AE29: 59.9944 | AG29: =((AG27-AG28)/AG28)*100 -> 18.974475
C30: Wt. Water | H30: g | I30: =I27-I28 -> 36.28 | J30: =IF(OR(J26="",J27="",J28="",J29=""),"",J27-J28) -> 26.217 | K30: =IF(OR(K26="",K27="",K28="",K29=""),"",K27-K28) -> 29.813 | Z30: 20 | AA30: 127.3896 | AD30: 20 | AE30: 40.2316
C31: Wt. Dry Soil | H31: g | I31: =+I28-I29 -> 120.97 | J31: =IF(OR(J26="",J27="",J28="",J29=""),"",J28-J29) -> 58.96 | K31: =IF(OR(K26="",K27="",K28="",K29=""),"",K28-K29) -> 66.581
C32: Moisture Content (w) | H32: % | I32: =+(I30/I31)*100 -> 29.990907 | J32: =IF(OR(J26="",J27="",J28="",J29=""),"",(J30/J31)*100) -> 44.465739 | K32: =IF(OR(K26="",K27="",K28="",K29=""),"",(K30/K31)*100) -> 44.777038
C33: MOISTURE CONTENT Average (w) | H33: % | J33: =IF(OR(J26="",J27="",J28="",J29=""),"",AVERAGE(J32:K32)) -> 44.621389 | AA33: 152.1022 | AE33: 52.9908
C34: DENSITY TEST (SNI 03-3637 : 1994) | AA34: 152.857 | AE34: 53.7774
C35: No. Ring | J35: =Data!B9 -> 1
C36: Wt. Ring + Wet Soil | H36: g | J36: =Data!B10 -> 94.969
C37: Wt. Ring | H37: g | J37: =IF(OR(J35="",J36=""),"",VLOOKUP(J35,$J$50:$L$110,2,FALSE)) -> 36.499
C38: Vol. Wet Soil (= Vol. Ring) | H38: cm3 | J38: =IF(OR(J35="",J36=""),"",VLOOKUP(J35,$J$50:$L$69,3,FALSE)) -> 34.700713
C39: BULK DENSITY (gm) | H39: Mg/m3 | J39: =IF(OR(J35="",J36=""),"",(J36-J37)/J38) -> 1.6849798
C41: DRY DENSITY (gd) | H41: Mg/m3 | J41: =IF(OR(J33="",J35="",J36=""),"",J39/(1+(J33/100))) -> 1.1650972
C42: VOID RATIO (e) | J42: =IF(OR(J24="",J33="",J35="",J36=""),"",((J24*1)/J41)-1) -> 1.2742617
C43: POROSITY (n) | J43: =IF(OR(J33="",J35="",J36="",J42=""),"",J42/(1+J42)) -> 0.56029686
...

Sheet A. GS
F3: Project | G3: =Details!B8 -> hidroplogi | K3: =G10 -> 0 | L3: =G4 -> 0 | M3: =G3 -> hidroplogi | N3: =G5 -> PO-GQT-19 | O3: =G6 -> 0 | Q3: =C10 -> 0 | R3: =C12 -> 0,00-0,50 | S3: =I6 -> 0 | T3: =F11 -> Sample Type : | U3: =F12 -> Sample Description : | V3: =IF($M$14=$AI$27,AG29,AP29) -> 0 | W3: =IF($M$14=$AI$27,AH29,AQ29) -> 0.004530709 | X3: =IF($M$14=$AI$27,AI29,AR29) -> 14.145469 | Y3: =IF($M$14=$AI$27,AJ29,AS29) -> 20.8 | Z3: =IF($M$14=$AI$27,AK29,AT29) -> 65.05 | AA3: =C62 -> 0 | AB3: =J62 -> 0 | AC3: Sieve opening | AD3: Percent finer | AL3: =C11 -> BH-05_UDS-01
AB4: =100-AD4 -> 64.302112 | AC4: =+$H$58 -> 0.0011815643 | AD4: =+I58 -> 35.697888 | AE4: =$I$58 -> 35.697888 | AF4: =IF(AE4>0,AE4,"-") -> 35.697888 | AG4: =IF(AND($AC4<101.6,$AC4>76.2),$AC4,"-") -> - | AH4: =IF(AND($AC4<76.2,$AC4>4.75),$AC4,"-") -> - | AI4: =IF(AND($AC4<4.75,$AC4>=0.075),$AC4,"-") -> - | AJ4: =IF(AND($AC4<0.075,$AC4>=0.005),$AC4,"-") -> - | AK4: =IF($AC4<0.005,$AC4,"-") -> 0.0011815643 | AP4: =IF(AND($AC3<200,$AC3>60),$AC3,"-") -> - | AQ4: =IF(AND($AC3<60.2,$AC3>2),$AC3,"-") -> - | AR4: =IF(AND($AC3<2,$AC3>=0.06),$AC3,"-") -> - | AS4: =IF(AND($AC3<0.06,$AC3>=0.002),$AC3,"-") -> - | AT4: =IF($AC3<0.002,$AC3,"-") -> - | AX4: T | AY4: dynamic viscosity | AZ4: density of water
F5: Job No. | G5: =Details!B3 -> PO-GQT-19 | H5: Date | AB5: =100-AD5 -> 45.517245 | AC5: =+$H$57 -> 0.0026871137 | AD5: =+I57 -> 54.482755 | AE5: =$I$57-$I$58 -> 18.784867 | AF5: =IF(AE5>0,AE5,"-") -> 18.784867 | AG5: =IF(AND($AC5<101.6,$AC5>76.2),$AC5,"-") -> - | AH5: =IF(AND($AC5<76.2,$AC5>4.75),$AC5,"-") -> - | AI5: =IF(AND($AC5<4.75,$AC5>=0.075),$AC5,"-") -> - | AJ5: =IF(AND($AC5<0.075,$AC5>=0.005),$AC5,"-") -> - | AK5: =IF($AC5<0.005,$AC5,"-") -> 0.0026871137 | AP5: =IF(AND($AC4<200,$AC4>60),$AC4,"-") -> - | AQ5: =IF(AND($AC4<60.2,$AC4>2),$AC4,"-") -> - | AR5: =IF(AND($AC4<2,$AC4>=0.06),$AC4,"-") -> - | AS5: =IF(AND($AC4<0.06,$AC4>=0.002),$AC4,"-") -> - | AT5: =IF($AC4<0.002,$AC4,"-") -> 0.0011815643 | AX5: 0 | AY5: 1.7865 | AZ5: 0.99984
F6: Tested By | H6: Checked By | AB6: =100-AD6 -> 34.559405 | AC6: =+$H$56 -> 0.0051171305 | AD6: =+I56 -> 65.440595 | AE6: =$I$56-$I$57 -> 10.957839 | AF6: =IF(AE6>0,AE6,"-") -> 10.957839 | AG6: =IF(AND($AC6<101.6,$AC6>76.2),$AC6,"-") -> - | AH6: =IF(AND($AC6<76.2,$AC6>4.75),$AC6,"-") -> - | AI6: =IF(AND($AC6<4.75,$AC6>=0.075),$AC6,"-") -> - | AJ6: =IF(AND($AC6<0.075,$AC6>=0.005),$AC6,"-") -> 0.0051171305 | AK6: =IF($AC6<0.005,$AC6,"-") -> - | AP6: =IF(AND($AC5<200,$AC5>60),$AC5,"-") -> - | AQ6: =IF(AND($AC5<60.2,$AC5>2),$AC5,"-") -> - | AR6: =IF(AND($AC5<2,$AC5>=0.06),$AC5,"-") -> - | AS6: =IF(AND($AC5<0.06,$AC5>=0.002),$AC5,"-") -> 0.0026871137 | AT6: =IF($AC5<0.002,$AC5,"-") -> - | AX6: 5 | AY6: 1.5138 | AZ6: 0.99995
AB7: =100-AD7 -> 31.428594 | AC7: =+$H$55 -> 0.0071294274 | AD7: =+I55 -> 68.571406 | AE7: =$I$55-$I$56 -> 3.1308112 | AF7: =IF(AE7>0,AE7,"-") -> 3.1308112 | AG7: =IF(AND($AC7<101.6,$AC7>76.2),$AC7,"-") -> - | AH7: =IF(AND($AC7<76.2,$AC7>4.75),$AC7,"-") -> - | AI7: =IF(AND($AC7<4.75,$AC7>=0.075),$AC7,"-") -> - | AJ7: =IF(AND($AC7<0.075,$AC7>=0.005),$AC7,"-") -> 0.0071294274 | AK7: =IF($AC7<0.005,$AC7,"-") -> - | AP7: =IF(AND($AC6<200,$AC6>60),$AC6,"-") -> - | AQ7: =IF(AND($AC6<60.2,$AC6>2),$AC6,"-") -> - | AR7: =IF(AND($AC6<2,$AC6>=0.06),$AC6,"-") -> - | AS7: =IF(AND($AC6<0.06,$AC6>=0.002),$AC6,"-") -> 0.0051171305 | AT7: =IF($AC6<0.002,$AC6,"-") -> - | AX7: 10 | AY7: 1.3037 | AZ7: 0.9997
A8: PARTICLE SIZE DISTRIBUTION ANALYSIS | AB8: =100-AD8 -> 28.297783 | AC8: =+$H$54 -> 0.0099284866 | AD8: =+I54 -> 71.702217 | AE8: =$I$54-$I$55 -> 3.1308112 | AF8: =IF(AE8>0,AE8,"-") -> 3.1308112 | AG8: =IF(AND($AC8<101.6,$AC8>76.2),$AC8,"-") -> - | AH8: =IF(AND($AC8<76.2,$AC8>4.75),$AC8,"-") -> - | AI8: =IF(AND($AC8<4.75,$AC8>=0.075),$AC8,"-") -> - | AJ8: =IF(AND($AC8<0.075,$AC8>=0.005),$AC8,"-") -> 0.0099284866 | AK8: =IF($AC8<0.005,$AC8,"-") -> - | AP8: =IF(AND($AC7<200,$AC7>60),$AC7,"-") -> - | AQ8: =IF(AND($AC7<60.2,$AC7>2),$AC7,"-") -> - | AR8: =IF(AND($AC7<2,$AC7>=0.06),$AC7,"-") -> - | AS8: =IF(AND($AC7<0.06,$AC7>=0.002),$AC7,"-") -> 0.0071294274 | AT8: =IF($AC7<0.002,$AC7,"-") -> - | AX8: 15 | AY8: 1.1369 | AZ8: 0.99909
AB9: =100-AD9 -> 23.601566 | AC9: =+$H$53 -> 0.01678847 | AD9: =+I53 -> 76.398434 | AE9: =$I$53-$I$54 -> 4.6962168 | AF9: =IF(AE9>0,AE9,"-") -> 4.6962168 | AG9: =IF(AND($AC9<101.6,$AC9>76.2),$AC9,"-") -> - | AH9: =IF(AND($AC9<76.2,$AC9>4.75),$AC9,"-") -> - | AI9: =IF(AND($AC9<4.75,$AC9>=0.075),$AC9,"-") -> - | AJ9: =IF(AND($AC9<0.075,$AC9>=0.005),$AC9,"-") -> 0.01678847 | AK9: =IF($AC9<0.005,$AC9,"-") -> - | AP9: =IF(AND($AC8<200,$AC8>60),$AC8,"-") -> - | AQ9: =IF(AND($AC8<60.2,$AC8>2),$AC8,"-") -> - | AR9: =IF(AND($AC8<2,$AC8>=0.06),$AC8,"-") -> - | AS9: =IF(AND($AC8<0.06,$AC8>=0.002),$AC8,"-") -> 0.0099284866 | AT9: =IF($AC8<0.002,$AC8,"-") -> - | AX9: 20 | AY9: 1.0019 | AZ9: 0.9982
B10: Location : | C10: =Details!B10 -> 0 | AB10: =100-AD10 -> 20.470755 | AC10: =+$H$52 -> 0.026105787 | AD10: =+I52 -> 79.529245 | AE10: =$I$52-$I$53 -> 3.1308112 | AF10: =IF(AE10>0,AE10,"-") -> 3.1308112 | AG10: =IF(AND($AC10<101.6,$AC10>76.2),$AC10,"-") -> - | AH10: =IF(AND($AC10<76.2,$AC10>4.75),$AC10,"-") -> - | AI10: =IF(AND($AC10<4.75,$AC10>=0.075),$AC10,"-") -> - | AJ10: =IF(AND($AC10<0.075,$AC10>=0.005),$AC10,"-") -> 0.026105787 | AK10: =IF($AC10<0.005,$AC10,"-") -> - | AP10: =IF(AND($AC9<200,$AC9>60),$AC9,"-") -> - | AQ10: =IF(AND($AC9<60.2,$AC9>2),$AC9,"-") -> - | AR10: =IF(AND($AC9<2,$AC9>=0.06),$AC9,"-") -> - | AS10: =IF(AND($AC9<0.06,$AC9>=0.002),$AC9,"-") -> 0.01678847 | AT10: =IF($AC9<0.002,$AC9,"-") -> - | AX10: 25 | AY10: 0.8909 | AZ10: 0.99704
B11: Hole No. : | C11: =Details!B1 -> BH-05_UDS-01 | F11: Sample Type : | AB11: =100-AD11 -> 18.905349 | AC11: =+$H$51 -> 0.036604707 | AD11: =+I51 -> 81.094651 | AE11: =$I$51-$I$52 -> 1.5654056 | AF11: =IF(AE11>0,AE11,"-") -> 1.5654056 | AG11: =IF(AND($AC11<101.6,$AC11>76.2),$AC11,"-") -> - | AH11: =IF(AND($AC11<76.2,$AC11>4.75),$AC11,"-") -> - | AI11: =IF(AND($AC11<4.75,$AC11>=0.075),$AC11,"-") -> - | AJ11: =IF(AND($AC11<0.075,$AC11>=0.005),$AC11,"-") -> 0.036604707 | AK11: =IF($AC11<0.005,$AC11,"-") -> - | AP11: =IF(AND($AC10<200,$AC10>60),$AC10,"-") -> - | AQ11: =IF(AND($AC10<60.2,$AC10>2),$AC10,"-") -> - | AR11: =IF(AND($AC10<2,$AC10>=0.06),$AC10,"-") -> - | AS11: =IF(AND($AC10<0.06,$AC10>=0.002),$AC10,"-") -> 0.026105787 | AT11: =IF($AC10<0.002,$AC10,"-") -> - | AX11: 30 | AY11: 0.7982 | AZ11: 0.99565
B12: Depth : | C12: =Details!B13 -> 0,00-0,50 | D12: m | F12: Sample Description : | H12: =IF(AH29>90,"GRAVEL", IF(AJ29>90,"SILT", IF(AK29>90,"CLAY", IF(AI29>90,"SAND", TRIM( SUBSTITUTE( _xlfn.TEXTJOIN(" ",TRUE, IF(AND(AH29>=AJ29,AH29>=AK29,AH29>=AI29), ( TRIM( IF(_xlfn.TEXTJOIN(", ",TRUE, IF(LARGE(AH29:AK29,2)>=15,CHOOSE(MATCH(LARGE(AH29:AK29,2),AH29:AK29,0),"gravelly","sandy","silty","clayey"),""), IF(LARGE(AH29:AK29,3)>=15,CHOOSE(MATCH(LARGE(AH29:AK29,3),AH29:AK29,0),"gravelly","sandy","silty","clayey"),"") )<>"",_xlfn.TEXTJOIN(", ",TRUE, IF(LARGE(AH29:AK29,2)>=15,CHOOSE(MATCH(LARGE(AH29:AK29,2),AH29:AK29,0),"gravelly","sandy","silty","clayey"),""), IF(LARGE(AH29:AK29,3)>=15,CHOOSE(MATCH(LARGE(AH29:AK29,3),AH29:AK29,0),"gravelly","sandy","silty","clayey"),"") )&" GRAVEL", "GRAVEL" ) )& IF(_xlfn.TEXTJOIN(" and ",TRUE, IF(AND(LARGE(AH29:AK29,2)>0,LARGE(AH29:AK29,2)<15), IF(LARGE(AH29:AK29,2)<5,"trace "&CHOOSE(MATCH(LARGE(AH29:AK29,2),AH29:AK29,0),"gravel","sand","silt","clay"),CHOOSE(MATCH(LARGE(AH29:AK29,2),AH29:AK29,0),"gravel","sand","silt","clay")), "" ), IF(AND(LARGE(AH29:AK29,3)>0,LARGE(AH29:AK29,3)<15), IF(LARGE(AH29:AK29,3)<5,"trace "&CHOOSE(MATCH(LARGE(AH29:AK29,3),AH29:AK29,0),"gravel","sand","silt","clay"),CHOOSE(MATCH(LARGE(AH29:AK29,3),AH29:AK29,0),"gravel","sand","silt","clay")), "" ) )<>""," with "&_xlfn.TEXTJOIN(" and ",TRUE, IF(AND(LARGE(AH29:AK29,2)>0,LARGE(AH29:AK29,2)<15), IF(LARGE(AH29:AK29,2)<5,"trace "&CHOOSE(MATCH(LARGE(AH29:AK29,2),AH29:AK29,0),"gravel","sand","silt","clay"),CHOOSE(MATCH(LARGE(AH29:AK29,2),AH29:AK29,0),"gravel","sand","silt","clay")), "" ), IF(AND(LARGE(AH29:AK29,3)>0,LARGE(AH29:AK29,3)<15), IF(LARGE(AH29:AK29,3)<5,"trace "&CHOOSE(MATCH(LARGE(AH29:AK29,3),AH29:AK29,0),"gravel","sand","silt","clay"),CHOOSE(MATCH(LARGE(AH29:AK29,3),AH29:AK29,0),"gravel","sand","silt","clay")), "" ) ),"") ), "" ), IF(AND(AJ29>=AH29,AJ29>=AK29,AJ29>=AI29), ( TRIM( IF(_xlfn.TEXTJOIN(", ",TRUE, IF(LARGE(AH29:AK29,2)>=15,CHOOSE(MATCH(LARGE(AH29:AK29,2),AH29:AK29,0),"gravelly","sandy","silty","clayey"),""), IF(LARGE(AH29:AK29,3)>=15,CHOOSE(MATCH(LARGE(AH29:AK29,3),AH29:AK29,0),"gravelly","sandy","silty","clayey"),"") )<>"",_xlfn.TEXTJOIN(", ",TRUE, IF(LARGE(AH29:AK29,2)>=15,CHOOSE(MATCH(LARGE(AH29:AK29,2),AH29:AK29,0),"gravelly","sandy","silty","clayey"),""), IF(LARGE(AH29:AK29,3)>=15,CHOOSE(MATCH(LARGE(AH29:AK29,3),AH29:AK29,0),"gravelly","sandy","silty","clayey"),"") )&" SILT", "SILT" ) )& IF(_xlfn.TEXTJOIN(" and ",TRUE, IF(AND(LARGE(AH29:AK29,2)>0,LARGE(AH29:AK29,2)<15), IF(LARGE(AH29:AK29,2)<5,"trace "&CHOOSE(MATCH(LARGE(AH29:AK29,2),AH29:AK29,0),"gravel","sand","silt","clay"),CHOOSE(MATCH(LARGE(AH29:AK29,2),AH29:AK29,0),"gravel","sand","silt","clay")), "" ), IF(AND(LARGE(AH29:AK29,3)>0,LARGE(AH29:AK29,3)<15), IF(LARGE(AH29:AK29,3)<5,"trace "&CHOOSE(MATCH(LARGE(AH29:AK29,3),AH29:AK29,0),"gravel","sand","silt","clay"),CHOOSE(MATCH(LARGE(AH29:AK29,3),AH29:AK29,0),"gravel","sand","silt","clay")), "" ) )<>""," with "&_xlfn.TEXTJOIN(" and ",TRUE, IF(AND(LARGE(AH29:AK29,2)>0,LARGE(AH29:AK29,2)<15), IF(LARGE(AH29:AK29,2)<5,"trace "&CHOOSE(MATCH(LARGE(AH29:AK29,2),AH29:AK29,0),"gravel","sand","silt","clay"),CHOOSE(MATCH(LARGE(AH29:AK29,2),AH29:AK29,0),"gravel","sand","silt","clay")), "" ), IF(AND(LARGE(AH29:AK29,3)>0,LARGE(AH29:AK29,3)<15), IF(LARGE(AH29:AK29,3)<5,"trace "&CHOOSE(MATCH(LARGE(AH29:AK29,3),AH29:AK29,0),"gravel","sand","silt","clay"),CHOOSE(MATCH(LARGE(AH29:AK29,3),AH29:AK29,0),"gravel","sand","silt","clay")), "" ) ),"") ), "" ), IF(AND(AK29>=AH29,AK29>=AJ29,AK29>=AI29), ( TRIM( IF(_xlfn.TEXTJOIN(", ",TRUE, IF(LARGE(AH29:AK29,2)>=15,CHOOSE(MATCH(LARGE(AH29:AK29,2),AH29:AK29,0),"gravelly","sandy","silty","clayey"),""), IF(LARGE(AH29:AK29,3)>=15,CHOOSE(MATCH(LARGE(AH29:AK29,3),AH29:AK29,0),"gravelly","sandy","silty","clayey"),"") )<>"",_xlfn.TEXTJOIN(", ",TRUE, IF(LARGE(AH29:AK29,2)>=15,CHOOSE(MATCH(LARGE(AH29:AK29,2),AH29:AK29,0),"gravelly","sandy","silty","clayey"),""), IF(LARGE(AH29:AK29,3)>=15,CHOOSE(MATCH(LARGE(AH29:AK29,3),AH29:AK29,0),"gravelly","sandy","silty","clayey"),"") )&" CLAY", "CLAY" ) )& IF(_xlfn.TEXTJOIN(" and ",TRUE, IF(AND(LARGE(AH29:AK29,2)>0,LARGE(AH29:AK29,2)<15), IF(LARGE(AH29:AK29,2)<5,"trace "&CHOOSE(MATCH(LARGE(AH29:AK29,2),AH29:AK29,0),"gravel","sand","silt","clay"),CHOOSE(MATCH(LARGE(AH29:AK29,2),AH29:AK29,0),"gravel","sand","silt","clay")), "" ), IF(AND(LARGE(AH29:AK29,3)>0,LARGE(AH29:AK29,3)<15), IF(LARGE(AH29:AK29,3)<5,"trace "&CHOOSE(MATCH(LARGE(AH29:AK29,3),AH29:AK29,0),"gravel","sand","silt","clay"),CHOOSE(MATCH(LARGE(AH29:AK29,3),AH29:AK29,0),"gravel","sand","silt","clay")), "" ) )<>""," with "&_xlfn.TEXTJOIN(" and ",TRUE, IF(AND(LARGE(AH29:AK29,2)>0,LARGE(AH29:AK29,2)<15), IF(LARGE(AH29:AK29,2)<5,"trace "&CHOOSE(MATCH(LARGE(AH29:AK29,2),AH29:AK29,0),"gravel","sand","silt","clay"),CHOOSE(MATCH(LARGE(AH29:AK29,2),AH29:AK29,0),"gravel","sand","silt","clay")), "" ), IF(AND(LARGE(AH29:AK29,3)>0,LARGE(AH29:AK29,3)<15), IF(LARGE(AH29:AK29,3)<5,"trace "&CHOOSE(MATCH(LARGE(AH29:AK29,3),AH29:AK29,0),"gravel","sand","silt","clay"),CHOOSE(MATCH(LARGE(AH29:AK29,3),AH29:AK29,0),"gravel","sand","silt","clay")), "" ) ),"") ), "" ), IF(AND(AI29>=AH29,AI29>=AJ29,AI29>=AK29), ( TRIM( IF(_xlfn.TEXTJOIN(", ",TRUE, IF(LARGE(AH29:AK29,2)>=15,CHOOSE(MATCH(LARGE(AH29:AK29,2),AH29:AK29,0),"gravelly","sandy","silty","clayey"),""), IF(LARGE(AH29:AK29,3)>=15,CHOOSE(MATCH(LARGE(AH29:AK29,3),AH29:AK29,0),"gravelly","sandy","silty","clayey"),"") )<>"",_xlfn.TEXTJOIN(", ",TRUE, IF(LARGE(AH29:AK29,2)>=15,CHOOSE(MATCH(LARGE(AH29:AK29,2),AH29:AK29,0),"gravelly","sandy","silty","clayey"),""), IF(LARGE(AH29:AK29,3)>=15,CHOOSE(MATCH(LARGE(AH29:AK29,3),AH29:AK29,0),"gravelly","sandy","silty","clayey"),"") )&" SAND", "SAND" ) )& IF(_xlfn.TEXTJOIN(" and ",TRUE, IF(AND(LARGE(AH29:AK29,2)>0,LARGE(AH29:AK29,2)<15), IF(LARGE(AH29:AK29,2)<5,"trace "&CHOOSE(MATCH(LARGE(AH29:AK29,2),AH29:AK29,0),"gravel","sand","silt","clay"),CHOOSE(MATCH(LARGE(AH29:AK29,2),AH29:AK29,0),"gravel","sand","silt","clay")), "" ), IF(AND(LARGE(AH29:AK29,3)>0,LARGE(AH29:AK29,3)<15), IF(LARGE(AH29:AK29,3)<5,"trace "&CHOOSE(MATCH(LARGE(AH29:AK29,3),AH29:AK29,0),"gravel","sand","silt","clay"),CHOOSE(MATCH(LARGE(AH29:AK29,3),AH29:AK29,0),"gravel","sand","silt","clay")), "" ) )<>""," with "&_xlfn.TEXTJOIN(" and ",TRUE, IF(AND(LARGE(AH29:AK29,2)>0,LARGE(AH29:AK29,2)<15), IF(LARGE(AH29:AK29,2)<5,"trace "&CHOOSE(MATCH(LARGE(AH29:AK29,2),AH29:AK29,0),"gravel","sand","silt","clay"),CHOOSE(MATCH(LARGE(AH29:AK29,2),AH29:AK29,0),"gravel","sand","silt","clay")), "" ), IF(AND(LARGE(AH29:AK29,3)>0,LARGE(AH29:AK29,3)<15), IF(LARGE(AH29:AK29,3)<5,"trace "&CHOOSE(MATCH(LARGE(AH29:AK29,3),AH29:AK29,0),"gravel","sand","silt","clay"),CHOOSE(MATCH(LARGE(AH29:AK29,3),AH29:AK29,0),"gravel","sand","silt","clay")), "" ) ),"") ), "" ) ), " and with "," and")))))) -> silty CLAY with sand | AB12: =100-AD12 -> 17.339944 | AC12: =+$H$50 -> 0.051318318 | AD12: =+I50 -> 82.660056 | AE12: =$I$50-$I$51 -> 1.5654056 | AF12: =IF(AE12>0,AE12,"-") -> 1.5654056 | AG12: =IF(AND($AC12<101.6,$AC12>76.2),$AC12,"-") -> - | AH12: =IF(AND($AC12<76.2,$AC12>4.75),$AC12,"-") -> - | AI12: =IF(AND($AC12<4.75,$AC12>=0.075),$AC12,"-") -> - | AJ12: =IF(AND($AC12<0.075,$AC12>=0.005),$AC12,"-") -> 0.051318318 | AK12: =IF($AC12<0.005,$AC12,"-") -> - | AP12: =IF(AND($AC11<200,$AC11>60),$AC11,"-") -> - | AQ12: =IF(AND($AC11<60.2,$AC11>2),$AC11,"-") -> - | AR12: =IF(AND($AC11<2,$AC11>=0.06),$AC11,"-") -> - | AS12: =IF(AND($AC11<0.06,$AC11>=0.002),$AC11,"-") -> 0.036604707 | AT12: =IF($AC11<0.002,$AC11,"-") -> - | AX12: 40 | AY12: 0.654 | AZ12: 0.99222
O13: 0.005 | P13: 0 | R13: 0.075 | S13: 0 | U13: 4.26 | V13: 0 | AB13: =100-AD13 -> 14.179163 | AC13: =+$C$35 -> 0.074 | AD13: =+G35 -> 85.820837 | AE13: =$E$35 -> 1.7788319 | AF13: =IF(AE13>0,AE13,"-") -> 1.7788319 | AG13: =IF(AND($AC13<101.6,$AC13>76.2),$AC13,"-") -> - | AH13: =IF(AND($AC13<76.2,$AC13>4.75),$AC13,"-") -> - | AI13: =IF(AND($AC13<4.75,$AC13>=0.075),$AC13,"-") -> - | AJ13: =IF(AND($AC13<0.075,$AC13>=0.005),$AC13,"-") -> 0.074 | AK13: =IF($AC13<0.005,$AC13,"-") -> - | AP13: =IF(AND($AC12<200,$AC12>60),$AC12,"-") -> - | AQ13: =IF(AND($AC12<60.2,$AC12>2),$AC12,"-") -> - | AR13: =IF(AND($AC12<2,$AC12>=0.06),$AC12,"-") -> - | AS13: =IF(AND($AC12<0.06,$AC12>=0.002),$AC12,"-") -> 0.051318318 | AT13: =IF($AC12<0.002,$AC12,"-") -> -
B14: SIEVE ANALYSIS | L14: Graphic Type | M14: ASTM D 422 | O14: 0.005 | P14: 100 | R14: 0.075 | S14: 100 | U14: 4.26 | V14: 100 | AB14: =100-AD14 -> 12.400331 | AC14: =+$C$34 -> 0.149 | AD14: =+G34 -> 87.599669 | AE14: =$E$34 -> 1.2763899 | AF14: =IF(AE14>0,AE14,"-") -> 1.2763899 | AG14: =IF(AND($AC14<101.6,$AC14>76.2),$AC14,"-") -> - | AH14: =IF(AND($AC14<76.2,$AC14>4.75),$AC14,"-") -> - | AI14: =IF(AND($AC14<4.75,$AC14>=0.075),$AC14,"-") -> 0.149 | AJ14: =IF(AND($AC14<0.075,$AC14>=0.005),$AC14,"-") -> - | AK14: =IF($AC14<0.005,$AC14,"-") -> - | AP14: =IF(AND($AC13<200,$AC13>60),$AC13,"-") -> - | AQ14: =IF(AND($AC13<60.2,$AC13>2),$AC13,"-") -> - | AR14: =IF(AND($AC13<2,$AC13>=0.06),$AC13,"-") -> 0.074 | AS14: =IF(AND($AC13<0.06,$AC13>=0.002),$AC13,"-") -> - | AT14: =IF($AC13<0.002,$AC13,"-") -> -
AB15: =100-AD15 -> 11.123941 | AC15: =+$C$33 -> 0.177 | AD15: =+G33 -> 88.876059 | AE15: =$E$33 -> 3.0708256 | AF15: =IF(AE15>0,AE15,"-") -> 3.0708256 | AG15: =IF(AND($AC15<101.6,$AC15>76.2),$AC15,"-") -> - | AH15: =IF(AND($AC15<76.2,$AC15>4.75),$AC15,"-") -> - | AI15: =IF(AND($AC15<4.75,$AC15>=0.075),$AC15,"-") -> 0.177 | AJ15: =IF(AND($AC15<0.075,$AC15>=0.005),$AC15,"-") -> - | AK15: =IF($AC15<0.005,$AC15,"-") -> - | AP15: =IF(AND($AC14<200,$AC14>60),$AC14,"-") -> - | AQ15: =IF(AND($AC14<60.2,$AC14>2),$AC14,"-") -> - | AR15: =IF(AND($AC14<2,$AC14>=0.06),$AC14,"-") -> 0.149 | AS15: =IF(AND($AC14<0.06,$AC14>=0.002),$AC14,"-") -> - | AT15: =IF($AC14<0.002,$AC14,"-") -> - | AX15: 0 | AY15: =+(0.000000000153808*AX15^6)-(0.0000000215035*AX15^5)+(0.000001335*AX15^4)-(0.0000539985*AX15^3)+(0.001865353*AX15^2)-(0.062670029*AX15)+1.7865 -> 1.7865 | AZ15: =+(0.00000000000294863*AX15^6)-(0.000000000349145*AX15^5)+(0.0000000151156*AX15^4)-(0.000000247168*AX15^3)-(0.00000563567*AX15^2)+(0.0000548713*AX15)+0.99984 -> 0.99984
B16: Initial weight of dry soil : | D16: =+D50+D36 -> 64.087 | E16: g | AB16: =100-AD16 -> 8.0531153 | AC16: =+$C$32 -> 0.42 | AD16: =+G32 -> 91.946885 | AE16: =$E$32 -> 3.4671618 | AF16: =IF(AE16>0,AE16,"-") -> 3.4671618 | AG16: =IF(AND($AC16<101.6,$AC16>76.2),$AC16,"-") -> - | AH16: =IF(AND($AC16<76.2,$AC16>4.75),$AC16,"-") -> - | AI16: =IF(AND($AC16<4.75,$AC16>=0.075),$AC16,"-") -> 0.42 | AJ16: =IF(AND($AC16<0.075,$AC16>=0.005),$AC16,"-") -> - | AK16: =IF($AC16<0.005,$AC16,"-") -> - | AP16: =IF(AND($AC15<200,$AC15>60),$AC15,"-") -> - | AQ16: =IF(AND($AC15<60.2,$AC15>2),$AC15,"-") -> - | AR16: =IF(AND($AC15<2,$AC15>=0.06),$AC15,"-") -> 0.177 | AS16: =IF(AND($AC15<0.06,$AC15>=0.002),$AC15,"-") -> - | AT16: =IF($AC15<0.002,$AC15,"-") -> - | AX16: 5 | AY16: =+(0.000000000153808*AX16^6)-(0.0000000215035*AX16^5)+(0.000001335*AX16^4)-(0.0000539985*AX16^3)+(0.001865353*AX16^2)-(0.062670029*AX16)+1.7865 -> 1.5138034 | AZ16: =+(0.00000000000294863*AX16^6)-(0.000000000349145*AX16^5)+(0.0000000151156*AX16^4)-(0.000000247168*AX16^3)-(0.00000563567*AX16^2)+(0.0000548713*AX16)+0.99984 -> 0.99995097
AB17: =100-AD17 -> 4.5859535 | AC17: =+$C$31 -> 0.84 | AD17: =IF(AD16=100,100,G31) -> 95.414047 | AE17: =$E$31 -> 3.0926709 | AF17: =IF(AE17>0,AE17,"-") -> 3.0926709 | AG17: =IF(AND($AC17<101.6,$AC17>76.2),$AC17,"-") -> - | AH17: =IF(AND($AC17<76.2,$AC17>4.75),$AC17,"-") -> - | AI17: =IF(AND($AC17<4.75,$AC17>=0.075),$AC17,"-") -> 0.84 | AJ17: =IF(AND($AC17<0.075,$AC17>=0.005),$AC17,"-") -> - | AK17: =IF($AC17<0.005,$AC17,"-") -> - | AP17: =IF(AND($AC16<200,$AC16>60),$AC16,"-") -> - | AQ17: =IF(AND($AC16<60.2,$AC16>2),$AC16,"-") -> - | AR17: =IF(AND($AC16<2,$AC16>=0.06),$AC16,"-") -> 0.42 | AS17: =IF(AND($AC16<0.06,$AC16>=0.002),$AC16,"-") -> - | AT17: =IF($AC16<0.002,$AC16,"-") -> - | AX17: 10 | AY17: =+(0.000000000153808*AX17^6)-(0.0000000215035*AX17^5)+(0.000001335*AX17^4)-(0.0000539985*AX17^3)+(0.001865353*AX17^2)-(0.062670029*AX17)+1.7865 -> 1.30369 | AZ17: =+(0.00000000000294863*AX17^6)-(0.000000000349145*AX17^5)+(0.0000000151156*AX17^4)-(0.000000247168*AX17^3)-(0.00000563567*AX17^2)+(0.0000548713*AX17)+0.99984 -> 0.99969717
B18: Sieve | C18: Sieve | D18: Wt. Soil | E18: Percent | F18: Cumulative | G18: Percent | AB18: =100-AD18 -> 1.4932826 | AC18: =+$C$30 -> 2.38 | AD18: =IF(AD17=100,100,G30) -> 98.506717 | AE18: =$E$30 -> 1.4932826 | AF18: =IF(AE18>0,AE18,"-") -> 1.4932826 | AG18: =IF(AND($AC18<101.6,$AC18>76.2),$AC18,"-") -> - | AH18: =IF(AND($AC18<76.2,$AC18>4.75),$AC18,"-") -> - | AI18: =IF(AND($AC18<4.75,$AC18>=0.075),$AC18,"-") -> 2.38 | AJ18: =IF(AND($AC18<0.075,$AC18>=0.005),$AC18,"-") -> - | AK18: =IF($AC18<0.005,$AC18,"-") -> - | AP18: =IF(AND($AC17<200,$AC17>60),$AC17,"-") -> - | AQ18: =IF(AND($AC17<60.2,$AC17>2),$AC17,"-") -> - | AR18: =IF(AND($AC17<2,$AC17>=0.06),$AC17,"-") -> 0.84 | AS18: =IF(AND($AC17<0.06,$AC17>=0.002),$AC17,"-") -> - | AT18: =IF($AC17<0.002,$AC17,"-") -> - | AX18: 15 | AY18: =+(0.000000000153808*AX18^6)-(0.0000000215035*AX18^5)+(0.000001335*AX18^4)-(0.0000539985*AX18^3)+(0.001865353*AX18^2)-(0.062670029*AX18)+1.7865 -> 1.1369162 | AZ18: =+(0.00000000000294863*AX18^6)-(0.000000000349145*AX18^5)+(0.0000000151156*AX18^4)-(0.000000247168*AX18^3)-(0.00000563567*AX18^2)+(0.0000548713*AX18)+0.99984 -> 0.99909453
B19: No. | C19: Opening | D19: Retained | E19: Retained | F19: Percent | G19: Finer | L19: =AK29 -> 65.05 | M19: =AJ29 -> 20.8 | O19: =AI29 -> 14.145469 | AB19: =100-AD19 -> 0 | AC19: =+$C$29 -> 4.76 | AD19: =IF(AD18=100,100,G29) -> 100 | AE19: =$E$29 -> 0 | AF19: =IF(AE19>0,AE19,"-") -> - | AG19: =IF(AND($AC19<101.6,$AC19>76.2),$AC19,"-") -> - | AH19: =IF(AND($AC19<76.2,$AC19>4.75),$AC19,"-") -> 4.76 | AI19: =IF(AND($AC19<4.75,$AC19>=0.075),$AC19,"-") -> - | AJ19: =IF(AND($AC19<0.075,$AC19>=0.005),$AC19,"-") -> - | AK19: =IF($AC19<0.005,$AC19,"-") -> - | AP19: =IF(AND($AC18<200,$AC18>60),$AC18,"-") -> - | AQ19: =IF(AND($AC18<60.2,$AC18>2),$AC18,"-") -> 2.38 | AR19: =IF(AND($AC18<2,$AC18>=0.06),$AC18,"-") -> - | AS19: =IF(AND($AC18<0.06,$AC18>=0.002),$AC18,"-") -> - | AT19: =IF($AC18<0.002,$AC18,"-") -> - | AX19: 20 | AY19: =+(0.000000000153808*AX19^6)-(0.0000000215035*AX19^5)+(0.000001335*AX19^4)-(0.0000539985*AX19^3)+(0.001865353*AX19^2)-(0.062670029*AX19)+1.7865 -> 1.0018851 | AZ19: =+(0.00000000000294863*AX19^6)-(0.000000000349145*AX19^5)+(0.0000000151156*AX19^4)-(0.000000247168*AX19^3)-(0.00000563567*AX19^2)+(0.0000548713*AX19)+0.99984 -> 0.99819576
F20: Retained | AB20: =100-AD20 -> 0 | AC20: =+$C$28 -> 9.525 | AD20: =IF(AD19=100,100,G28) -> 100 | AE20: =$E$28 -> 0 | AF20: =IF(AE20>0,AE20,"-") -> - | AG20: =IF(AND($AC20<101.6,$AC20>76.2),$AC20,"-") -> - | AH20: =IF(AND($AC20<76.2,$AC20>4.75),$AC20,"-") -> 9.525 | AI20: =IF(AND($AC20<4.75,$AC20>=0.075),$AC20,"-") -> - | AJ20: =IF(AND($AC20<0.075,$AC20>=0.005),$AC20,"-") -> - | AK20: =IF($AC20<0.005,$AC20,"-") -> - | AP20: =IF(AND($AC19<200,$AC19>60),$AC19,"-") -> - | AQ20: =IF(AND($AC19<60.2,$AC19>2),$AC19,"-") -> 4.76 | AR20: =IF(AND($AC19<2,$AC19>=0.06),$AC19,"-") -> - | AS20: =IF(AND($AC19<0.06,$AC19>=0.002),$AC19,"-") -> - | AT20: =IF($AC19<0.002,$AC19,"-") -> - | AX20: 25 | AY20: =+(0.000000000153808*AX20^6)-(0.0000000215035*AX20^5)+(0.000001335*AX20^4)-(0.0000539985*AX20^3)+(0.001865353*AX20^2)-(0.062670029*AX20)+1.7865 -> 0.89090838 | AZ20: =+(0.00000000000294863*AX20^6)-(0.000000000349145*AX20^5)+(0.0000000151156*AX20^4)-(0.000000247168*AX20^3)-(0.00000563567*AX20^2)+(0.0000548713*AX20)+0.99984 -> 0.99704228
C21: mm | E21: % | F21: % | G21: % | AB21: =100-AD21 -> 0 | AC21: =+$C$27 -> 12.7 | AD21: =IF(AD20=100,100,G27) -> 100 | AE21: =$E$27 -> 0 | AF21: =IF(AE21>0,AE21,"-") -> - | AG21: =IF(AND($AC21<101.6,$AC21>76.2),$AC21,"-") -> - | AH21: =IF(AND($AC21<76.2,$AC21>4.75),$AC21,"-") -> 12.7 | AI21: =IF(AND($AC21<4.75,$AC21>=0.075),$AC21,"-") -> - | AJ21: =IF(AND($AC21<0.075,$AC21>=0.005),$AC21,"-") -> - | AK21: =IF($AC21<0.005,$AC21,"-") -> - | AP21: =IF(AND($AC20<200,$AC20>60),$AC20,"-") -> - | AQ21: =IF(AND($AC20<60.2,$AC20>2),$AC20,"-") -> 9.525 | AR21: =IF(AND($AC20<2,$AC20>=0.06),$AC20,"-") -> - | AS21: =IF(AND($AC20<0.06,$AC20>=0.002),$AC20,"-") -> - | AT21: =IF($AC20<0.002,$AC20,"-") -> - | AX21: 30 | AY21: =+(0.000000000153808*AX21^6)-(0.0000000215035*AX21^5)+(0.000001335*AX21^4)-(0.0000539985*AX21^3)+(0.001865353*AX21^2)-(0.062670029*AX21)+1.7865 -> 0.79819831 | AZ21: =+(0.00000000000294863*AX21^6)-(0.000000000349145*AX21^5)+(0.0000000151156*AX21^4)-(0.000000247168*AX21^3)-(0.00000563567*AX21^2)+(0.0000548713*AX21)+0.99984 -> 0.99564946
B22: 3" | C22: 101.6 | D22: =Data!E2 -> 0 | E22: =D22/$D$16*100 -> 0 | F22: =+E22 -> 0 | G22: =100-F22 -> 100 | AB22: =100-AD22 -> 0 | AC22: =+$C$26 -> 19.05 | AD22: =IF(AD21=100,100,G26) -> 100 | AE22: =$E$26 -> 0 | AF22: =IF(AE22>0,AE22,"-") -> - | AG22: =IF(AND($AC22<101.6,$AC22>76.2),$AC22,"-") -> - | AH22: =IF(AND($AC22<76.2,$AC22>4.75),$AC22,"-") -> 19.05 | AI22: =IF(AND($AC22<4.75,$AC22>=0.075),$AC22,"-") -> - | AJ22: =IF(AND($AC22<0.075,$AC22>=0.005),$AC22,"-") -> - | AK22: =IF($AC22<0.005,$AC22,"-") -> - | AP22: =IF(AND($AC21<200,$AC21>60),$AC21,"-") -> - | AQ22: =IF(AND($AC21<60.2,$AC21>2),$AC21,"-") -> 12.7 | AR22: =IF(AND($AC21<2,$AC21>=0.06),$AC21,"-") -> - | AS22: =IF(AND($AC21<0.06,$AC21>=0.002),$AC21,"-") -> - | AT22: =IF($AC21<0.002,$AC21,"-") -> - | AX22: 40 | AY22: =+(0.000000000153808*AX22^6)-(0.0000000215035*AX22^5)+(0.000001335*AX22^4)-(0.0000539985*AX22^3)+(0.001865353*AX22^2)-(0.062670029*AX22)+1.7865 -> 0.65399881 | AZ22: =+(0.00000000000294863*AX22^6)-(0.000000000349145*AX22^5)+(0.0000000151156*AX22^4)-(0.000000247168*AX22^3)-(0.00000563567*AX22^2)+(0.0000548713*AX22)+0.99984 -> 0.9922201
B23: 2" | C23: 75 | D23: =Data!E3 -> 0 | E23: =D23/$D$16*100 -> 0 | F23: =F22+E23 -> 0 | G23: =100-F23 -> 100 | AB23: =100-AD23 -> 0 | AC23: =+$C$25 -> 25.4 | AD23: =IF(AD22=100,100,G25) -> 100 | AE23: =$E$25 -> 0 | AF23: =IF(AE23>0,AE23,"-") -> - | AG23: =IF(AND($AC23<101.6,$AC23>76.2),$AC23,"-") -> - | AH23: =IF(AND($AC23<76.2,$AC23>4.75),$AC23,"-") -> 25.4 | AI23: =IF(AND($AC23<4.75,$AC23>=0.075),$AC23,"-") -> - | AJ23: =IF(AND($AC23<0.075,$AC23>=0.005),$AC23,"-") -> - | AK23: =IF($AC23<0.005,$AC23,"-") -> - | AP23: =IF(AND($AC22<200,$AC22>60),$AC22,"-") -> - | AQ23: =IF(AND($AC22<60.2,$AC22>2),$AC22,"-") -> 19.05 | AR23: =IF(AND($AC22<2,$AC22>=0.06),$AC22,"-") -> - | AS23: =IF(AND($AC22<0.06,$AC22>=0.002),$AC22,"-") -> - | AT23: =IF($AC22<0.002,$AC22,"-") -> - | AX23: 27 | AY23: =+(0.000000000153808*AX23^6)-(0.0000000215035*AX23^5)+(0.000001335*AX23^4)-(0.0000539985*AX23^3)+(0.001865353*AX23^2)-(0.062670029*AX23)+1.7865 -> 0.85190946 | AZ23: =+(0.00000000000294863*AX23^6)-(0.000000000349145*AX23^5)+(0.0000000151156*AX23^4)-(0.000000247168*AX23^3)-(0.00000563567*AX23^2)+(0.0000548713*AX23)+0.99984 -> 0.99651367
B24: 1 1/2" | C24: 38.1 | D24: =Data!E4 -> 0 | E24: =D24/$D$16*100 -> 0 | F24: =F23+E24 -> 0 | G24: =100-F24 -> 100 | AB24: =100-AD24 -> 0 | AC24: =+$C$24 -> 38.1 | AD24: =IF(AD23=100,100,G24) -> 100 | AE24: =$E$24 -> 0 | AF24: =IF(AE24>0,AE24,"-") -> - | AG24: =IF(AND($AC24<101.6,$AC24>76.2),$AC24,"-") -> - | AH24: =IF(AND($AC24<76.2,$AC24>4.75),$AC24,"-") -> 38.1 | AI24: =IF(AND($AC24<4.75,$AC24>=0.075),$AC24,"-") -> - | AJ24: =IF(AND($AC24<0.075,$AC24>=0.005),$AC24,"-") -> - | AK24: =IF($AC24<0.005,$AC24,"-") -> - | AP24: =IF(AND($AC23<200,$AC23>60),$AC23,"-") -> - | AQ24: =IF(AND($AC23<60.2,$AC23>2),$AC23,"-") -> 25.4 | AR24: =IF(AND($AC23<2,$AC23>=0.06),$AC23,"-") -> - | AS24: =IF(AND($AC23<0.06,$AC23>=0.002),$AC23,"-") -> - | AT24: =IF($AC23<0.002,$AC23,"-") -> - | AX24: 26 | AY24: =+(0.000000000153808*AX24^6)-(0.0000000215035*AX24^5)+(0.000001335*AX24^4)-(0.0000539985*AX24^3)+(0.001865353*AX24^2)-(0.062670029*AX24)+1.7865 -> 0.87106575 | AZ24: =+(0.00000000000294863*AX24^6)-(0.000000000349145*AX24^5)+(0.0000000151156*AX24^4)-(0.000000247168*AX24^3)-(0.00000563567*AX24^2)+(0.0000548713*AX24)+0.99984 -> 0.99678274
B25: 1" | C25: 25.4 | D25: =Data!E5 -> 0 | E25: =D25/$D$16*100 -> 0 | F25: =F24+E25 -> 0 | G25: =100-F25 -> 100 | AB25: =100-AD25 -> 0 | AC25: =+$C$23 -> 75 | AD25: =IF(AD24=100,100,G23) -> 100 | AE25: =$E$23 -> 0 | AF25: =IF(AE25>0,AE25,"-") -> - | AG25: =IF(AND($AC25<101.6,$AC25>76.2),$AC25,"-") -> - | AH25: =IF(AND($AC25<76.2,$AC25>4.75),$AC25,"-") -> 75 | AI25: =IF(AND($AC25<4.75,$AC25>=0.075),$AC25,"-") -> - | AJ25: =IF(AND($AC25<0.075,$AC25>=0.005),$AC25,"-") -> - | AK25: =IF($AC25<0.005,$AC25,"-") -> - | AP25: =IF(AND($AC24<200,$AC24>60),$AC24,"-") -> - | AQ25: =IF(AND($AC24<60.2,$AC24>2),$AC24,"-") -> 38.1 | AR25: =IF(AND($AC24<2,$AC24>=0.06),$AC24,"-") -> - | AS25: =IF(AND($AC24<0.06,$AC24>=0.002),$AC24,"-") -> - | AT25: =IF($AC24<0.002,$AC24,"-") -> -
B26: 3/4" | C26: 19.05 | D26: =Data!E6 -> 0 | E26: =D26/$D$16*100 -> 0 | F26: =F25+E26 -> 0 | G26: =100-F26 -> 100 | AB26: =100-AD26 -> 0 | AC26: =+$C$22 -> 101.6 | AD26: =IF(AD25=100,100,G22) -> 100 | AE26: =$E$22 -> 0 | AF26: =IF(AE26>0,AE26,"-") -> - | AG26: =IF(AND($AC26<101.6,$AC26>76.2),$AC26,"-") -> - | AH26: =IF(AND($AC26<76.2,$AC26>4.75),$AC26,"-") -> - | AI26: =IF(AND($AC26<4.75,$AC26>=0.075),$AC26,"-") -> - | AJ26: =IF(AND($AC26<0.075,$AC26>=0.005),$AC26,"-") -> - | AK26: =IF($AC26<0.005,$AC26,"-") -> - | AP26: =IF(AND($AC25<200,$AC25>60),$AC25,"-") -> 75 | AQ26: =IF(AND($AC25<60.2,$AC25>2),$AC25,"-") -> - | AR26: =IF(AND($AC25<2,$AC25>=0.06),$AC25,"-") -> - | AS26: =IF(AND($AC25<0.06,$AC25>=0.002),$AC25,"-") -> - | AT26: =IF($AC25<0.002,$AC25,"-") -> -
B27: 1/2" | C27: 12.7 | D27: =Data!E7 -> 0 | E27: =D27/$D$16*100 -> 0 | F27: =F26+E27 -> 0 | G27: =100-F27 -> 100 | AI27: ASTM D 422 | AR27: BS 1377
B28: 3/8" | C28: 9.525 | D28: =Data!E8 -> 0 | E28: =D28/$D$16*100 -> 0 | F28: =F27+E28 -> 0 | G28: =100-F28 -> 100 | AG28: Cobbles | AH28: Gravel | AI28: Sand | AJ28: Silt | AK28: Clay | AP28: Cobbles | AQ28: Gravel | AR28: Sand | AS28: Silt | AT28: Clay
B29: 4 | C29: 4.76 | D29: =Data!E9 -> 0 | E29: =D29/$D$16*100 -> 0 | F29: =F28+E29 -> 0 | G29: =100-F29 -> 100 | AG29: =100-SUM(AH29:AK29) -> 0 | AH29: =AH33-SUM(AI29:AK29) -> 0.004530709 | AI29: =AH36-SUM(AJ29:AK29) -> 14.145469 | AJ29: =AI39-AK29 -> 20.8 | AK29: =ROUND(AH42,2) -> 65.05 | AP29: =100-SUM(AQ29:AT29) -> 0 | AQ29: =AQ33-SUM(AR29:AT29) -> 2.0098492 | AR29: =AQ36-SUM(AS29:AT29) -> 13.990151 | AS29: =AR39-AT29 -> 36.27 | AT29: =ROUND(AQ42,2) -> 47.73
B30: 8 | C30: 2.38 | D30: =Data!E10 -> 0.957 | E30: =D30/$D$16*100 -> 1.4932826 | F30: =F29+E30 -> 1.4932826 | G30: =100-F30 -> 98.506717
B31: 20 | C31: 0.84 | D31: =Data!E11 -> 1.982 | E31: =D31/$D$16*100 -> 3.0926709 | F31: =F30+E31 -> 4.5859535 | G31: =100-F31 -> 95.414047 | AE31: Cobbles | AF31: max | AG31: =MAX(AG4:AG26) -> 0 | AH31: =IF(AG31=0,100,VLOOKUP(AG31,$AC$4:$AD$26,2)) -> 100 | AN31: Cobbles | AO31: max | AP31: =MAX(AP5:AP26) -> 75 | AQ31: =IF(AP31=0,100,VLOOKUP(AP31,$AC$4:$AD$26,2)) -> 100
B32: 40 | C32: 0.42 | D32: =Data!E12 -> 2.222 | E32: =D32/$D$16*100 -> 3.4671618 | F32: =F31+E32 -> 8.0531153 | G32: =100-F32 -> 91.946885 | AF32: min | AG32: =MIN(AG4:AG26) -> 0 | AH32: =IF(AG32=0,100,VLOOKUP(AG32,$AC$4:$AD$26,2)) -> 100 | AO32: min | AP32: =MIN(AP5:AP26) -> 75 | AQ32: =IF(AP32=0,100,VLOOKUP(AP32,$AC$4:$AD$26,2)) -> 100
B33: 80 | C33: 0.177 | D33: =Data!E13 -> 1.968 | E33: =D33/$D$16*100 -> 3.0708256 | F33: =F32+E33 -> 11.123941 | G33: =100-F33 -> 88.876059 | AG33: 76.2 | AH33: =IF(AG32=0,100,((LOG(AG33)-LOG(AG34))/(LOG(AG32)-LOG(AG34)))*(AH32-AH34)+AH34) -> 100 | AP33: 60 | AQ33: =IF(AP32=0,100,((LOG(AP33)-LOG(AP34))/(LOG(AP32)-LOG(AP34)))*(AQ32-AQ34)+AQ34) -> 100
B34: 100 | C34: 0.149 | D34: =Data!E14 -> 0.818 | E34: =D34/$D$16*100 -> 1.2763899 | F34: =F33+E34 -> 12.400331 | G34: =100-F34 -> 87.599669 | AE34: gravel | AF34: max | AG34: =MAX(AH4:AH27) -> 75 | AH34: =VLOOKUP(AG34,$AC$4:$AD$26,2) -> 100 | AN34: gravel | AO34: max | AP34: =MAX(AQ5:AQ27) -> 38.1 | AQ34: =VLOOKUP(AP34,$AC$4:$AD$26,2) -> 100
B35: 200 | C35: 0.074 | D35: =Data!E15 -> 1.14 | E35: =D35/$D$16*100 -> 1.7788319 | F35: =F34+E35 -> 14.179163 | G35: =100-F35 -> 85.820837 | AF35: min | AG35: =MIN(AH4:AH27) -> 4.76 | AH35: =VLOOKUP(AG35,$AC$4:$AD$26,2) -> 100 | AO35: min | AP35: =MIN(AQ5:AQ27) -> 2.38 | AQ35: =VLOOKUP(AP35,$AC$4:$AD$26,2) -> 98.506717
B36: Pan | D36: =SUM(D22:D35) -> 9.087 | E36: =D36/$D$16*100 -> 14.179163 | F36: =F35+E36 -> 28.358325 | AG36: 4.75 | AH36: =((LOG(AG36)-LOG(AG37))/(LOG(AG35)-LOG(AG37)))*(AH35-AH37)+AH37 -> 99.995469 | AP36: 2 | AQ36: =((LOG(AP36)-LOG(AP37))/(LOG(AP35)-LOG(AP37)))*(AQ35-AQ37)+AQ37 -> 97.990151
AE37: Sand | AF37: max | AG37: =MAX(AI4:AI27) -> 2.38 | AH37: =VLOOKUP(AG37,$AC$4:$AD$26,2) -> 98.506717 | AN37: Sand | AO37: max | AP37: =MAX(AR5:AR27) -> 0.84 | AQ37: =VLOOKUP(AP37,$AC$4:$AD$26,2) -> 95.414047
D38: =SUM(D22:D36) -> 18.174 | E38: =SUM(E22:E37) -> 28.358325 | AF38: min | AG38: =MIN(AI4:AI27) -> 0.149 | AH38: =VLOOKUP(AG38,AC4:AD26,2) -> 87.599669 | AO38: min | AP38: =MIN(AR5:AR27) -> 0.074 | AQ38: =VLOOKUP(AP38,AC4:AD26,2) -> 85.820837
B39: HYDROMETER ANALYSIS SNI 3423 : 2008 | AG39: 0.075 | AH39: =((LOG(AG39)-LOG(AG40))/(LOG(AG38)-LOG(AG40)))*(AH38-AH40)+AH40 -> 85.854954 | AI39: =ROUND(AH39,2) -> 85.85 | AP39: 0.06 | AQ39: =((LOG(AP39)-LOG(AP40))/(LOG(AP38)-LOG(AP40)))*(AQ38-AQ40)+AQ40 -> 84.009774 | AR39: =ROUND(AQ39,0) -> 84
AE40: Silt | AF40: max | AG40: =MAX(AJ4:AJ27) -> 0.074 | AH40: =VLOOKUP(AG40,AC4:AD26,2) -> 85.820837 | AN40: Silt | AO40: max | AP40: =MAX(AS5:AS27) -> 0.051318318 | AQ40: =VLOOKUP(AP40,AC4:AD26,2) -> 82.660056
B41: Weight of soil : | D41: =Data!F2 -> 60.1 | E41: g | F41: Tube No. | H41: : | AF41: min | AG41: =MIN(AJ4:AJ27) -> 0.0051171305 | AH41: =VLOOKUP(AG41,AC4:AD26,2) -> 65.440595 | AO41: min | AP41: =MIN(AS5:AS27) -> 0.0026871137 | AQ41: =VLOOKUP(AP41,AC4:AD26,2) -> 54.482755
B42: Specific Gravity (Gs) : | D42: =PP!J24 -> 2.6497359 | F42: Hydrometer No. | H42: : | AG42: 0.005 | AH42: =((LOG(AG42)-LOG(AG43))/(LOG(AG41)-LOG(AG43)))*(AH41-AH43)+AH43 -> 65.046667 | AP42: 0.002 | AQ42: =((LOG(AP42)-LOG(AP43))/(LOG(AP41)-LOG(AP43)))*(AQ41-AQ43)+AQ43 -> 47.730852
...

Sheet GS
G4: GEOLAND QUATTRO TECHNOLAB
G5: JL. Nata Endah, Komplek Indahco No.22 Kel. Margahayu Tengah
G6: Kec. Margahayu, Kab. Bandung 40225
G7: Telp/WhatsApp : 082115618130
G8: Email : geolandquattro@gmail.com; geolandquattro@geolandtechnolab.com
D11: UJI ANALISIS UKURAN BUTIR / SIEVE AND HYDROMETER ANALYSIS
D12: SNI 3423:2008
E14: Deskripsi Sampel / Sample Description
E15: Pelanggan / Client | G15: : | H15: =Details!B4 -> PT Itamatra Nusantara | L15: Penguji / Test by | N15: : | O15: PT. MGS
E16: Proyek / Project | G16: : | H16: =Details!B8 -> hidroplogi | L16: No. PKS | N16: : | O16: 001/PKS GQT-MGS/VIII/2025
E17: No Sampel / Sample Number | G17: : | H17: =Details!B1 -> BH-05_UDS-01 | L17: Tanggal / Dated | N17: : | O17: =Details!B29 -> 46212
E18: Id Lab / Lab ID | G18: : | H18: =Details!B7 -> 23-GQT--19-UDS-1-BH-05-0,00-0,50-100726-001 | L18: Diperiksa / Checked by | N18: : | O18: =Details!B22 -> AS Sumartadji
E19: Kedalaman / Depth | G19: : | H19: =Details!B13&" m" -> 0,00-0,50 m | L19: No. Lampiran | N19: : | O19: =Details!B2 -> MGS/02/VI/2026
E20: Tipe Tanah / Soil Type | G20: : | H20: ='A. GS'!H12 -> silty CLAY with sand
E21: Warna / Colour | G21: : | H21: =Details!B15 -> Abu-abu / Gray
E22: Berat Jenis / Specific Gravity | G22: : | H22: =PP!J24 -> 2.6497359
E23: Jenis Sampel / Type of Sample | G23: : | H23: =Details!B16 -> Undisturbed Sample / UDS
F24: =Details!C15 -> Disclaimer : | G24: =Details!C16 -> The samples were received as Undisturbed Sample / UDS and the validity of the sampling process was not verified by the laboratory.
F25: HASIL/ Result | G25: Lempung/Clay | I25: Lanau/Silt | J25: Halus/Fine | K25: Sedang/Medium | L25: Kasar/Coarse | M25: Halus/Fine | P25: Kasar/Coarse
J26: Pasir/Sand | M26: Kerikil/ Gravel
F27: % | G27: ='A. GS'!Z3 -> 65.05 | I27: ='A. GS'!Y3 -> 20.8 | J27: ='A. GS'!X3 -> 14.145469 | M27: =100-SUM(G27:L27) -> 0.004530709 | P27: =100-SUM(G27:M27) -> 0
F29: HASIL ANALISIS MEKANIKAL/ Mechanical Analysis Results
F31: ANALISIS SARINGAN/ SIEVE ANALYSIS | K31: ANALISIS HIDROMETER/HIDROMETER ANALYSIS
F32: UKURAN SARINGAN
F33: Standar, mm | G33: No. Saringan / Sieve No. | I33: Persen Lolos / Percent Passing | K33: Lebih Kecil / Les Than | L33: Persen / Percent
F34: 101.6 | G34: 3" | I34: ='A. GS'!G22 -> 100 | K34: 0.02 mm | L34: %
F35: 75 | G35: 2" | I35: ='A. GS'!G23 -> 100 | K35: {=_xlfn._xlws.FILTER('A. GS'!$H$50:$H$58, ('A. GS'!$H$50:$H$58>0.002)*('A. GS'!$H$50:$H$58<=0.02))} -> 0.01678847 | L35: =_xlfn.IFNA(VLOOKUP(K35,'A. GS'!$H$50:$I$58,2,0)," - ") -> 76.398434
F36: 38.1 | G36: 1 1/2" | I36: ='A. GS'!G24 -> 100 | K36: 0.0099284866 | L36: =_xlfn.IFNA(VLOOKUP(K36,'A. GS'!$H$50:$I$58,2,0)," - ") -> 71.702217
F37: 25.4 | G37: 1" | I37: ='A. GS'!G25 -> 100 | K37: 0.0071294274 | L37: =_xlfn.IFNA(VLOOKUP(K37,'A. GS'!$H$50:$I$58,2,0)," - ") -> 68.571406
F38: 19.05 | G38: 3/4" | I38: ='A. GS'!G26 -> 100 | K38: 0.0051171305 | L38: =_xlfn.IFNA(VLOOKUP(K38,'A. GS'!$H$50:$I$58,2,0)," - ") -> 65.440595
F39: 12.7 | G39: 1/2" | I39: ='A. GS'!G27 -> 100 | K39: 0.0026871137 | L39: =_xlfn.IFNA(VLOOKUP(K39,'A. GS'!$H$50:$I$58,2,0)," - ") -> 54.482755
F40: 9.525 | G40: 3/8" | I40: ='A. GS'!G28 -> 100 | L40: =_xlfn.IFNA(VLOOKUP(K40,'A. GS'!$H$50:$I$58,2,0)," - ") -> -
F41: 4.76 | G41: 4 | I41: ='A. GS'!G29 -> 100 | K41: 0,002 mm
F42: 2.38 | G42: 8 | I42: ='A. GS'!G30 -> 98.506717 | K42: {=_xlfn._xlws.FILTER('A. GS'!$H$50:$H$58, ('A. GS'!$H$50:$H$58>0.001)*('A. GS'!$H$50:$H$58<=0.002))} -> 0.0011815643 | L42: =_xlfn.IFNA(VLOOKUP(K42,'A. GS'!$H$50:$I$58,2,0)," - ") -> 35.697888
F43: 0.84 | G43: 20 | I43: ='A. GS'!G31 -> 95.414047 | L43: =_xlfn.IFNA(VLOOKUP(K43,'A. GS'!$H$50:$I$58,2,0)," - ") -> -
F44: 0.42 | G44: 40 | I44: ='A. GS'!G32 -> 91.946885 | L44: =_xlfn.IFNA(VLOOKUP(K44,'A. GS'!$H$50:$I$58,2,0)," - ") -> -
F45: 0.177 | G45: 80 | I45: ='A. GS'!G33 -> 88.876059 | K45: 0,001 mm
F46: 0.149 | G46: 100 | I46: ='A. GS'!G34 -> 87.599669 | K46: {=IFERROR(_xlfn._xlws.FILTER('A. GS'!$H$50:$H$58,'A. GS'!$H$50:$H$58<=0.001),"-")} -> - | L46: =_xlfn.IFNA(VLOOKUP(K46,'A. GS'!$H$50:$I$58,2,0)," - ") -> -
F47: 0.074 | G47: 200 | I47: ='A. GS'!G35 -> 85.820837
N50: Notes :
...

Sheet ATB
H3: GEOLAND QUATTRO TECHNOLAB
H4: JL. Nata Endah, Komplek Indahco No.22 Kel. Margahayu Tengah
H5: Kec. Margahayu, Kab. Bandung 40225
H6: Telp/WhatsApp : 082115618130
H7: Email : geolandquattro@gmail.com; geolandquattro@geolandtechnolab.com
C10: UJI BATAS PLASTIS, BATAS CAIR
C11: SNI 1967 : 2008 | AN11: No | AO11: Berat
C13: Deskripsi Sampel / Sample Description | AN13: 1 | AO13: 9.03
C14: Pelanggan / Client | J14: : | K14: =Details!B4 -> PT Itamatra Nusantara | W14: Penguji / Test by | AB14: : | AC14: PT. MGS | AJ14: kalo di uji dan NP, di sisi di isi NP | AN14: 2 | AO14: 8.842
C15: Proyek / Project | J15: : | K15: =Details!B8 -> hidroplogi | W15: No. PKS | AB15: : | AC15: 001/PKS GQT-MGS/VIII/2025 | AN15: 3 | AO15: 9.041
C16: Id Lab / Lab Id | J16: : | K16: =Details!B7 -> 23-GQT--19-UDS-1-BH-05-0,00-0,50-100726-001 | W16: Tanggal / Dated | AB16: : | AC16: =Details!B30 -> 46214 | AN16: 4 | AO16: 8.936
C17: No Sampel / Sample No | J17: : | K17: =Details!B1 -> BH-05_UDS-01 | W17: Diperiksa / Checked by | AB17: : | AC17: =Details!B22 -> AS Sumartadji | AN17: 5 | AO17: 8.856
C18: Kedalaman / Depth | J18: : | K18: =Details!B13&" m" -> 0,00-0,50 m | W18: No. Lampiran | AB18: : | AC18: =Details!B2 -> MGS/02/VI/2026 | AI18: Vertical Iine | AK18: Horizontal Line | AN18: 6 | AO18: 8.726
C19: Jenis Tanah / Soil Type | J19: : | K19: =Details!B14 -> silty CLAY with sand | AI19: X | AJ19: Y | AK19: X | AL19: Y | AN19: 7 | AO19: 8.882
C20: Berat Jenis / Specific Gravity | J20: : | K20: =PP!J24 -> 2.6497359 | AI20: 25 | AJ20: 0 | AK20: 1 | AL20: =AI30 -> NP | AN20: 8 | AO20: 8.818
C21: Warna / Colour | J21: : | K21: =Details!B15 -> Abu-abu / Gray | AI21: 25 | AJ21: =AI30 -> NP | AK21: 25 | AL21: =AI30 -> NP | AN21: 9 | AO21: 8.799
C22: Jenis Sampel / Sample Type | J22: : | K22: =Details!B16 -> Undisturbed Sample / UDS | AN22: 10 | AO22: 8.793
E23: =Details!C15 -> Disclaimer : | H23: =Details!C16 -> The samples were received as Undisturbed Sample / UDS and the validity of the sampling process was not verified by the laboratory. | AI23: Graphic Trend line | AN23: 11 | AO23: 8.804
D24: Uji Batas Cair / Liquids Limit Test | AN24: 12 | AO24: 8.928
D25: PARAMETER | S25: 1 | V25: 2 | Y25: 3 | AB25: 4 | AI25: X | AJ25: Y | AN25: 13 | AO25: 8.877
D26: Banyak Pukulan/No. of blows | AI26: =Y26 -> 0 | AJ26: =Y34 | AN26: 14 | AO26: 8.892
D27: No. Cawan | AI27: =V26 -> 0 | AJ27: =V34 | AN27: 15 | AO27: 8.993
D28: Berat cawan kosong / wt. empty can | R28: ( gr ) | S28: =IFERROR(VLOOKUP(S27,$AN$11:$AO$212,2,0),"") | V28: =IFERROR(VLOOKUP(V27,$AN$11:$AO$212,2,0),"") | Y28: =IFERROR(VLOOKUP(Y27,$AN$9:$AO$212,2,0),"") | AB28: =IFERROR(VLOOKUP(AB27,$AN$9:$AO$212,2,0),"") | AN28: 16 | AO28: 8.909
D29: Berat cawan + Tanah basah / wt.of can + moist soil | R29: ( gr ) | AI29: LIQUID LIMIT | AN29: 17 | AO29: 9.049
D30: Berat cawan + Tanah Kering / wt. of can + dry soil | R30: ( gr ) | AI30: {=IF(OR(AI26="",AI27="",AJ26="",AJ27=""),"NP",TREND(AJ26:AJ27,AI26:AI27,25))} -> NP | AJ30: % | AN30: 18 | AO30: 8.934
D31: Berat tanah basah / wt. of moist soil | R31: ( gr ) | S31: =IF(OR(S28="",S29=""),"",(S29-S28)) | V31: =IF(OR(V28="",V29=""),"",(V29-V28)) | Y31: =IF(OR(Y28="",Y29=""),"",(Y29-Y28)) | AB31: =IF(OR(AB28="",AB29=""),"",(AB29-AB28)) | AN31: 19 | AO31: 8.961
D32: Berat tanah kering / wt. of dry soil | R32: ( gr ) | S32: =IF(OR(S28="",S30=""),"",(S30-S28)) | V32: =IF(OR(V28="",V30=""),"",(V30-V28)) | Y32: =IF(OR(Y28="",Y30=""),"",(Y30-Y28)) | AB32: =IF(OR(AB28="",AB30=""),"",(AB30-AB28)) | AH32: LL | AI32: =AI30 -> NP | AN32: 20 | AO32: 8.776
D33: Berat air / wt. of water | R33: ( gr ) | S33: =IF(OR(S29="",S30=""),"",S29-S30) | V33: =IF(OR(V29="",V30=""),"",V29-V30) | Y33: =IF(OR(Y29="",Y30=""),"",Y29-Y30) | AB33: =IF(OR(AB29="",AB30=""),"",AB29-AB30) | AH33: PL | AI33: =AB53 -> NP | AN33: 21 | AO33: 8.903
D34: Kadar air/ Moisture content (Mc) | R34: ( % ) | S34: =IF(OR(S32="",S33=""),"",S33/S32*100) | V34: =IF(OR(V32="",V33=""),"",V33/V32*100) | Y34: =IF(OR(Y32="",Y33=""),"",Y33/Y32*100) | AB34: =IF(OR(AB32="",AB33=""),"",AB33/AB32*100) | AH34: PI | AI34: =AD53 -> NP | AN34: 22 | AO34: 8.843
AN35: 23 | AO35: 8.84
AI36: LL | AJ36: A-Line | AK36: U-Line | AN36: 24 | AO36: 9.01
AI37: 0 | AN37: 25 | AO37: 8.812
AI38: 8 | AK38: 0 | AN38: 26 | AO38: 8.846
AI39: 20 | AJ39: 0 | AK39: 10.8 | AN39: 27 | AO39: 8.914
AI40: 30 | AJ40: 7.3 | AK40: 19.8 | AN40: 28 | AO40: 9.9
AI41: 40 | AJ41: 14.6 | AK41: 28.8 | AN41: 29 | AO41: 8.9
AI42: 50 | AJ42: 21.9 | AK42: 37.8 | AN42: 30 | AO42: 8.854
AI43: 60 | AJ43: 29.2 | AK43: 46.8 | AN43: 31 | AO43: 8.815
AI44: 70 | AJ44: 36.5 | AK44: 55.8 | AN44: 32 | AO44: 8.985
AI45: 80 | AJ45: 43.8 | AK45: 64.8 | AN45: 33 | AO45: 8.897
...

Sheet Consol
Y1: No ring | Z1: =Data!I17 -> 1 | AJ1: DATA RING
AK2: cm | AL2: cm | AM2: g
F3: GEOLAND QUATTRO TECHNOLAB | X3: Height of Ring | Z3: =VLOOKUP($Z$1,AJ3:AM12,3,TRUE) -> 2.01 | AA3: cm | AC3: PARAMETER TANAH SEMULA | AJ3: Ring | AK3: Diameter | AL3: Tinggi | AM3: berat | AO3: PARAMETER TANAH SETELAH PENGUJIAN
F4: JL. Nata Endah, Komplek Indahco No.22 Kel. Margahayu Tengah | X4: Ring Diameter | Z4: =VLOOKUP($Z$1,AJ4:AM12,2,TRUE) -> 5.07 | AA4: cm | AC4: Luas Benda Uji | AF4: A | AG4: =PI()*(Z4/2)^2 -> 20.188581 | AH4: cm2 | AJ4: 1 | AK4: 5.07 | AL4: 2.01 | AM4: 41.467
F5: Kec. Margahayu, Kab. Bandung 40225 | X5: Weight of ring | Z5: =VLOOKUP($Z$1,AJ3:AM12,4,TRUE) -> 41.467 | AA5: gr | AC5: Volume Benda Uji | AF5: Vo | AG5: =PI()*(Z4/2)^2*Z3 -> 40.579048 | AH5: cm3 | AJ5: 2 | AK5: 5.02 | AL5: 2.01 | AM5: 44.958
F6: Telp/WhatsApp : 082115618130 | X6: Weight of Soil + Ring | Z6: 125.198 | AA6: gr
F7: Email : geolandquattro@gmail.com; geolandquattro@geolandtechnolab.com | AC7: Massa benda uji semula | AF7: m | AG7: =Z6-Z5 -> 83.731 | AH7: gr | AJ7: 3 | AK7: 5.06 | AL7: 1.97 | AM7: 42.502 | AO7: massa tanah setelah pengujian | AR7: mf | AS7: =Z14-Z13 -> 66.777 | AT7: gr
D9: CONSOLIDATION TEST | AC9: Massa Kering Benda uji Semula | AF9: mk | AG9: =Data!I16 -> 47.283937 | AH9: gr | AJ9: 4 | AK9: 5.05 | AL9: 2.04 | AM9: 48.853 | AO9: Kadar air setelah pengujian | AS9: =Z18/Z17*100 -> 7.4172377 | AT9: %
D10: SNI 2812 : 2011 | AC10: Weight of water | AG10: =AG7-AG9 -> 36.447063 | AH10: gr | AJ10: 5 | AK10: 5.05 | AL10: 2.02 | AM10: 45.231 | AO10: Berat volume tanah setelah pengujian | AR10: 𝜸nf | AS10: =AS7/AG5 -> 1.6456029
E12: Deskripsi Sampel / Sample Description | M12: Penguji / Test by | P12: : | Q12: PT. MGS | X12: CONTAINER NO. | AC12: Kadar air semula | AF12: Wo | AG12: =(AG10/AG9)*100 -> 77.081279 | AH12: % | AJ12: 6 | AK12: 5.05 | AL12: 2 | AM12: 47.069 | AO12: Berat volume benda uji kering setelah pengujian | AR12: 𝜸df | AS12: =Z17/AG5 -> 1.5319728 | AT12: %
E13: Pelanggan / Client | G13: : | H13: =Details!B4 -> PT Itamatra Nusantara | M13: No. PKS | P13: : | Q13: 001/PKS GQT-MGS/VIII/2025 | X13: WT. CONTAINER | Z13: =Data!I19 -> 8.834 | AC13: berat vol. benda uji semula | AF13: 𝜸no | AG13: =AG7/AG5 -> 2.0634047 | AH13: gr/cm3 | AO13: Derajat kejenuhan air setelah pengujian | AR13: So
E14: Proyek / Project | G14: : | H14: =Details!B8 -> hidroplogi | M14: Tanggal / Dated | P14: : | Q14: =Details!B31 -> 46219 | X14: WT. CONTAINER + WET SOIL | Z14: =Data!I18 -> 75.611 | AC14: berat vol. benda uji kering semula | AF14: 𝜸d0 | AG14: =AG9/AG5 -> 1.1652303
E15: Id Lab / Lab id | G15: : | H15: =Details!B7 -> 23-GQT--19-UDS-1-BH-05-0,00-0,50-100726-001 | M15: Diperiksa / Checked by | P15: : | Q15: =Details!B22 -> AS Sumartadji | X15: WT. CONTAINER + DRY SOIL | Z15: 71 | AC15: Weight of wet Soil | AG15: =AG7 -> 83.731 | AH15: gr
E16: No Sampel / Sample No | G16: : | H16: =Details!B1 -> BH-05_UDS-01 | M16: No. Lampiran | P16: : | Q16: =Details!B2 -> MGS/02/VI/2026 | X16: WT. WET SOIL | Z16: =Z14-Z13 -> 66.777 | AC16: Berat volume air | AF16: 𝜸w | AG16: =AG10/AG5 -> 0.89817442 | AH16: gr/cm3
E17: Kedalaman / Depth | G17: : | H17: =Details!B13&" m" -> 0,00-0,50 m | X17: WT. OF DRY SOIL | Z17: =Z15-Z13 -> 62.166 | AC17: Gs | AG17: =PP!J24 -> 2.6497359
E18: Tipe Tanah / Soil Type | G18: : | H18: =Details!B14 -> silty CLAY with sand | X18: WT. WATER (Ww) IN g | Z18: =Z14-Z15 -> 4.611 | AC18: Angka pori tanah semula | AF18: eo | AG18: =PP!J42 -> 1.2742617 | AH18: -
E19: Warna / Colour | G19: : | H19: =Details!B15 -> Abu-abu / Gray | AC19: Derajat kejenuhan air Semula | AF19: So | AG19: =(AG12*AG17)/AG18 -> 160.28501 | AH19: %
E20: Jenis Sampel / Type of Sample | G20: : | H20: =Details!B16 -> Undisturbed Sample / UDS | Y20: Cc | Z20: =AC52-AC53 -> 0.13033086 | AA20: =Z20/Z21 -> 0.43294973 | AC20: Solid Height | AF20: Hs | AG20: =AG9/AG17/AG4 -> 0.88390427 | AH20: cm-1
E21: Disclaimer : | F21: ="The samples were received as "&H20&" and the validity of the sampling process was not verified by the laboratory." -> The samples were received as Undisturbed Sample / UDS and the validity of the sampling process was not verified by the laboratory. | Z21: =LOG10(Y53)-LOG10(Y52) -> 0.30103
E22: Parameter Tanah / Soil Parameters
E23: Koeff. Permebilitas ( Permeability coeff ) k | I23: : | J23: =AI57 -> 3.0572215e-09 | K23: cm/s
E24: Indeks Kompresibilitas ( Compressibilty Index ) Cc | I24: : | J24: =AA20 -> 0.43294973 | K24: - | Y24: e max | Z24: =MAX(AC48:AC55) -> 1.2701888
E25: Koefisien Konsolidasi ( Coeff. of Consolidation ) Cv | I25: : | J25: =AI56 -> 0.00018185268 | K25: cm2/s | Y25: e min | Z25: =MIN(AC48:AC55) -> 0.94108078 | AB25: Elapsed | AC25: COMPRESSION DIAL (mm)
E26: Koef.Kompresibilitas ( Coeff.of Compressibilty ) mv | I26: : | J26: =AI55 -> 0.016811528 | K26: cm2/kg | AB26: Time | AD26: 0,25 kg/cm2 | AE26: 0,50 kg/cm2 | AF26: 1,00 kg/cm2 | AG26: 2,00 kg/cm2 | AH26: 4,00 kg/cm2 | AI26: 8,00 kg/cm2 | AJ26: 2,00 kg/cm2 | AK26: 0,25 kg/cm2
E27: Angka pori awal ( Initial Void Ratio ) e0 | I27: : | J27: =AG18 -> 1.2742617 | K27: - | AB27: (minute) | AC27: t
Y28: garis e0 | AB28: 0 | AC28: =AB28^0.5 -> 0 | AD28: =Data!I2 -> 0.9945 | AE28: =Data!J2 -> 0.9909 | AF28: =Data!K2 -> 0.98 | AG28: =Data!L2 -> 0.954 | AH28: =Data!M2 -> 0.896 | AI28: =Data!N2 -> 0.8152 | AJ28: =Data!O2 -> 0.7 | AK28: =Data!P2 -> 0.7182
Y29: 0.1 | Z29: =J27 -> 1.2742617 | AB29: 0.25 | AC29: =AB29^0.5 -> 0.5 | AD29: =Data!I3 -> 0.9923 | AE29: =Data!J3 -> 0.9873 | AF29: =Data!K3 -> 0.9716 | AG29: =Data!L3 -> 0.94 | AH29: =Data!M3 -> 0.8814 | AI29: =Data!N3 -> 0.8012
Y30: 10 | Z30: =Z29 -> 1.2742617 | AB30: 0.5 | AC30: =AB30^0.5 -> 0.70710678 | AD30: =Data!I4 -> 0.992 | AE30: =Data!J4 -> 0.9868 | AF30: =Data!K4 -> 0.9702 | AG30: =Data!L4 -> 0.9378 | AH30: =Data!M4 -> 0.8792 | AI30: =Data!N4 -> 0.7967
