Workbook
Name TTD_: 'Summary CMP_CBR'!$F$22
Name TTD_1ATB: INDIRECT('[1]WS-ATB'!$T$9)
Name TTD_1CBRS: INDIRECT('[1]WS-CBRSoaked'!$T$9)
Name TTD_1CBRU: INDIRECT('[1]WS-CBR unsoaked'!$T$9)
Name TTD_1CDR: INDIRECT('[1]WS_CD Residual '!$T$9)
Name TTD_1CMPM: INDIRECT('[1]WS-modified proctor'!$T$9)
Name TTD_1CMPS: INDIRECT('[1]WS-standard Proctor'!$T$9)
Name TTD_1CON: INDIRECT('[1]WS-Konsolidasi'!$T$9)
Name TTD_1DSCD: INDIRECT('[1]WS_DS-CD'!$T$9)
Name TTD_1DSUU: INDIRECT('[1]WS_DS-UU'!$T$9)
Name TTD_1PP: INDIRECT('[1]WS-PP'!$T$9)
Name TTD_1SH: INDIRECT('[1]WS-Sieve dan hidrometer'!$T$9)
Name TTD_1TCUM: INDIRECT('[1]WS-TRX-CU Multi'!$T$9)
Name TTD_1TCUN: INDIRECT('[1]WS-TRX-CU Normal'!$T$9)
Name TTD_1TUU: INDIRECT('[1]WS-TRX-UU'!$T$9)
Name TTD_1UCT: INDIRECT('[1]WS-UCT'!$T$9)
Name TTD_2ATB: INDIRECT('[1]WS-ATB'!$T$10)
Name TTD_2CBRS: INDIRECT('[1]WS-CBRSoaked'!$T$10)
Name TTD_2CBRU: INDIRECT('[1]WS-CBR unsoaked'!$T$10)
Name TTD_2CDR: INDIRECT('[1]WS_CD Residual '!$T$10)
Name TTD_2CMPM: INDIRECT('[1]WS-modified proctor'!$T$10)
Name TTD_2CMPS: INDIRECT('[1]WS-standard Proctor'!$T$10)
Name TTD_2CON: INDIRECT('[1]WS-Konsolidasi'!$T$10)
Name TTD_2DSCD: INDIRECT('[1]WS_DS-CD'!$T$10)
Name TTD_2DSUU: INDIRECT('[1]WS_DS-UU'!$T$10)
Name TTD_2PP: INDIRECT('[1]WS-PP'!$T$10)
Name TTD_2SH: INDIRECT('[1]WS-Sieve dan hidrometer'!$T$10)
Name TTD_2TCUM: INDIRECT('[1]WS-TRX-CU Multi'!$T$10)
Name TTD_2TCUN: INDIRECT('[1]WS-TRX-CU Normal'!$T$10)
Name TTD_2TUU: INDIRECT('[1]WS-TRX-UU'!$T$10)
Name TTD_2UCT: INDIRECT('[1]WS-UCT'!$T$10)
Name TTD_3ATB: INDIRECT('[1]WS-ATB'!$T$11)
Name TTD_3CBRS: INDIRECT('[1]WS-CBRSoaked'!$T$11)
Name TTD_3CBRU: INDIRECT('[1]WS-CBR unsoaked'!$T$11)
Name TTD_3CDR: INDIRECT('[1]WS_CD Residual '!$T$11)
Name TTD_3CMPM: INDIRECT('[1]WS-modified proctor'!$T$11)
Name TTD_3CON: INDIRECT('[1]WS-Konsolidasi'!$T$11)
Name TTD_3DSCD: INDIRECT('[1]WS_DS-CD'!$T$11)
Name TTD_3DSUU: INDIRECT('[1]WS_DS-UU'!$T$11)
Name TTD_3PP: INDIRECT('[1]WS-PP'!$T$11)
Name TTD_3SH: INDIRECT('[1]WS-Sieve dan hidrometer'!$T$11)
Name TTD_3TCUM: INDIRECT('[1]WS-TRX-CU Multi'!$T$11)
Name TTD_3TCUN: INDIRECT('[1]WS-TRX-CU Normal'!$T$11)
Name TTD_3TUU: INDIRECT('[1]WS-TRX-UU'!$T$11)
Name TTD_3UCT: INDIRECT('[1]WS-UCT'!$T$11)
Name TTD_CMPS: INDIRECT('[1]WS-standard Proctor'!$T$11)
Name X_UCS_Remoulded: OFFSET(#REF!,0,0,COUNT(#REF!),1)
Name X_UCS_Undisturbed: OFFSET(#REF!,0,0,COUNT(#REF!),1)
Name X_UU: OFFSET(#REF!,0,0,COUNT(#REF!),1)
Name X_UU_1kg: OFFSET(#REF!,0,0,COUNT(#REF!),1)
Name X_UU_2kg: OFFSET(#REF!,0,0,COUNT(#REF!),1)
Name Y_UCS_Remoulded: OFFSET(#REF!,0,0,COUNT(#REF!),1)
Name Y_UCS_Undisturbed: OFFSET(#REF!,0,0,COUNT(#REF!),1)
Name Y_UU: OFFSET(#REF!,0,0,COUNT(#REF!),1)
Name Y_UU_1kg: OFFSET(#REF!,0,0,COUNT(#REF!),1)
Name Y_UU_2kg: OFFSET(#REF!,0,0,COUNT(#REF!),1)

Sheet Rekapitulasi
C3: LABORATORIUM MEKANIKA TANAH PT. MINEARTH GEO SOLUTION REKAPITULASI HASIL PENGUJIAN / TEST RESULT SUMMARY
A8: Identitas | E8: Physical Properties | H8: Classification | P8: Compaction | R8: Perm. & Consolidation | U8: UCT | V8: Direct Shear | AB8: Triaxial | AH8: CBR Lab.
A9: No. | B9: Lab. ID | C9: Sample Code | D9: Depth (m) | E9: w (%) | F9: Gs | G9: γ (t/m³) | H9: LL | I9: PL | J9: PI | K9: USCS | L9: Clay | M9: Silt | N9: Sand | O9: Gravel | P9: γd max | Q9: OMC | R9: k | S9: Cc | T9: Cv | U9: qu | V9: φUU | W9: cUU | X9: φCD | Y9: cCD | Z9: φres | AA9: cres | AB9: φUU | AC9: cUU | AD9: φCU | AE9: cCU | AF9: φCD | AG9: cCD | AH9: CBR Unsoaked | AI9: CBR Soaked | AJ9: Swelling
A42: REKAPITULASI CONTOH / SAMPLE RECAPITULATION
A43: Jumlah contoh diterima / Total samples received
A44: Jumlah contoh komposit / Total composite samples
A45: Jumlah contoh diuji / Total samples tested
A46: Jumlah LHU diterbitkan / Reports issued
A47: Jumlah LHU internal / Internal reports
A49: Catatan/Note: 1. NP = Non Plastic 2. ND = Not Determined 3. Jumlah contoh yang diuji dapat berbeda dengan jumlah contoh yang diterima karena adanya preparasi contoh komposit.

Sheet DATA INDUK
B2: NAMA PROYEK / PROJECT ID | H2: BSI Candrian Waste Dump Extension Study
B3: LOKASI PROYEK | H3: Banyuwangi - JAWA TIMUR
B4: PEMILIK/KLIEN | H4: PT. GEOLAND QUATRO TECHNOLAB
B5: ALAMAT | F5: JL.
F6: KOTA-PROVINSI | H6: Kab. Bandung - JAWA BARAT
B7: PIC
B8: TLP
B9: NOMOR PO | H9: PO-GQT-001
B10: TGL PO
B11: NO. URUT PO | H11: 1
B12: TAHUN | H12: 2026
B13: TGL KEDATANGAN SAMPEL | H13: 46027
B14: NO. BA PENERIMAAN SAMPEL
B16: PELAPORAN HASIL UJI | J16: PELAPORAN SUMMARY HASIL UJI
B17: NOMOR LAPORAN | H17: 23/MGS/53/II/2026 | J17: NOMOR LAPORAN | P17: QMS/SUM-001/VI/2026
B18: REVISI | H18: R0 | J18: REVISI | P18: R0
J19: TGL REVISI | P19: -
B20: TGL LAPORAN | H20: 46051 | J20: TGL LAPORAN | P20: 46193 | AL20: SUMMARY PP | AM20: SUMMARY OF SHEAR STRENGTH | AN20: SUMMARY OF COMPRESSION | AO20: SUMMARY OF COMPACTION & CBR | AQ20: SUMMARY PP | AR20: SUMMARY OF SHEAR STRENGTH | AS20: SUMMARY OF CONSOLIDATION & PERMEABILTY | AT20: SUMMARY OF COMPACTION & CBR | AX20: QC INCLUDED
B22: JENIS PENGUJIAN /TEST PERFORMED
B23: NO. | C23: SAMPLE ID | D23: JENIS SAMPLE | E23: KODE SAMPEL | F23: HOLE ID | G23: SAMPEL No. | H23: LAB ID | I23: DEPTH (m) | L23: Composit group | M23: SPESIFIC GRAVITY | N23: MOISTURE CONTENT | O23: UNIT WEIGHT | P23: ATTENBERG LIMIT | Q23: SIEVE ANALYSIS | R23: SIEVE &HIDROMETER | S23: COMPACTION | U23: PERMEABILTY | V23: CONSOLIDATION | W23: UCT | X23: DIRECT SHEAR | AC23: TRIAXIAL | AG23: CBR LAB. | AI23: SHRINGKAGE LIMIT | AJ23: SWELLING PRESSURE
I24: INTERVAL | J24: Depth fr. | K24: Depth to | S24: STD. PROCTOR | T24: MODIF. PROCTOR | X24: DS-UU | Y24: DS-CU | Z24: DS - CD | AA24: DS - RESIDUAL | AB24: DS CD-RESIDUAL | AC24: TRIAXIAL UU | AD24: TRIAXIAL CU-M | AE24: TRIAXIAL CU-N | AF24: TRIAXIAL CD | AG24: CBR UNSOAKED | AH24: CBR-SOAKED
BA25: evaluation Depth | BC25: Interval Depth
AA26: DS - RESIDUAL | AL26: 0 | AM26: 0 | AN26: 0 | AO26: 0 | BS26: No | BT26: J | BU26: SNI
A28: DS | B28: 1 | C28: =CONCATENATE(F28,"-",G28) -> BH-04R1-SPT 15 | D28: =IF(E28="DS","Disturbed Sample", IF(E28="UDS","Undisturbed Sample", IF(E28="BS","Bulk Sample", IF(E28="CS","Composite Sample","")))) -> Disturbed Sample | E28: DS | F28: BH-04R1 | G28: SPT 15 | H28: =IF(OR($H$12="",$H$11="",E28="",B28=""),"",RIGHT($H$12,2)&"-"&TEXT($H$11,"000")&"-"&E28&"-"&TEXT(B28,"000")) -> 26-001-DS-001 | I28: =IF(AND(J28=0,K28=0), "-", TEXT(J28,"0.00")&" - "&TEXT(K28,"0.00")&" m") -> 22.50 - 22.95 m | J28: 22.5 | K28: 22.95 | M28: 1 | N28: 1 | O28: 1 | AD28: 1 | AL28: =IF(OR(M28=1,N28=1,O28=1,P28=1,Q28=1,R28=1,AI28=1),MAX($AL$26:AL26)+1,"") -> 1 | AM28: =IF(OR(W28=1,X28=1,Y28=1,Z28=1,AA28=1,AB28=1,AC28=1,AD28=1,AE28=1,AF28=1),MAX($AM$26:AM26)+1,"") -> 1 | AN28: =IF(OR(V28=1,AJ28=1,U28=1),MAX($AN$26:AN26)+1,"") | AO28: =IF(OR(S28=1,T28=1,AG28=1,AH28=1),MAX($AO$26:AO26)+1,"") | AQ28: =IF(SUM(M28,N28,O28,P28,Q28,R28,AI28)>0,1,0) -> 1 | AR28: =IF(SUM(W28,X28,Y28,Z28,AA28,AB28,AC28,AD28,AE28,AF28)>0,1,0) -> 1 | AS28: =IF(SUM(U28,V28,AJ28)>0,1,0) -> 0 | AT28: =IF(SUM(S28,T28,AG28,AH28)>0,1,0) -> 0 | AX28: =IF(COUNTIF(M28:AJ28,1)>0,H28,"") -> 26-001-DS-001 | BA28: =IF(OR(E28="CS",J28="",K28="",AND(J28=0,K28=0)),"",ROUND((J28+K28)/2,2)) -> 22.73 | BC28: =IF(OR(E28="CS",J28="",K28="",AND(J28=0,K28=0)),"",I28) -> 22.50 - 22.95 m | BF28: =IF(COUNTIF(M28:AJ28,1)>0,C28,"") -> BH-04R1-SPT 15 | BS28: 1 | BT28: Sieve analysis & Hydrometer | BU28: 3423:2008
A29: UDS | B29: =B28+1 -> 2 | C29: =CONCATENATE(F29,"-",G29) -> BH-03-R-SPT 01 | D29: =IF(E29="DS","Disturbed Sample", IF(E29="UDS","Undisturbed Sample", IF(E29="BS","Bulk Sample", IF(E29="CS","Composite Sample","")))) -> Disturbed Sample | E29: DS | F29: BH-03-R | G29: SPT 01 | H29: =IF(OR($H$12="",$H$11="",E29="",B29=""),"",RIGHT($H$12,2)&"-"&TEXT($H$11,"000")&"-"&E29&"-"&TEXT(B29,"000")) -> 26-001-DS-002 | I29: =IF(AND(J29=0,K29=0), "-", TEXT(J29,"0.00")&" - "&TEXT(K29,"0.00")&" m") -> 1.50 - 1.95 m | J29: 1.5 | K29: 1.95 | M29: 1 | N29: 1 | O29: 1 | AD29: 1 | AL29: =IF(OR(M29=1,N29=1,O29=1,P29=1,Q29=1,R29=1,AI29=1),MAX($AL$27:AL28)+1,"") -> 2 | AM29: =IF(OR(W29=1,X29=1,Y29=1,Z29=1,AA29=1,AB29=1,AC29=1,AD29=1,AE29=1,AF29=1),MAX($AM$27:AM28)+1,"") -> 2 | AN29: =IF(OR(V29=1,AJ29=1),MAX($AN$26:AN27)+1,"") | AO29: =IF(OR(S29=1,T29=1,AG29=1,AH29=1),MAX($AO$27:AO28)+1,"") | AQ29: =IF(SUM(M29,N29,O29,P29,Q29,R29,AI29)>0,1,0) -> 1 | AR29: =IF(SUM(W29,X29,Y29,Z29,AA29,AB29,AC29,AD29,AE29,AF29)>0,1,0) -> 1 | AS29: =IF(SUM(U29,V29,AJ29)>0,1,0) -> 0 | AT29: =IF(SUM(S29,T29,AG29,AH29)>0,1,0) -> 0 | AX29: =IF(COUNTIF(M29:AJ29,1)>0,H29,"") -> 26-001-DS-002 | BA29: =IF(OR(E29="CS",J29="",K29="",AND(J29=0,K29=0)),"",ROUND((J29+K29)/2,2)) -> 1.73 | BC29: =IF(OR(E29="CS",J29="",K29="",AND(J29=0,K29=0)),"",I29) -> 1.50 - 1.95 m | BF29: =IF(COUNTIF(M29:AJ29,1)>0,C29,"") -> BH-03-R-SPT 01 | BS29: 2 | BT29: Analisi Ayakan | BU29: 3423:2008
A30: BS | B30: =B29+1 -> 3 | C30: =CONCATENATE(F30,"-",G30) -> BH-07-R-SPT-01 | D30: =IF(E30="DS","Disturbed Sample", IF(E30="UDS","Undisturbed Sample", IF(E30="BS","Bulk Sample", IF(E30="CS","Composite Sample","")))) -> Disturbed Sample | E30: DS | F30: BH-07-R | G30: SPT-01 | H30: =IF(OR($H$12="",$H$11="",E30="",B30=""),"",RIGHT($H$12,2)&"-"&TEXT($H$11,"000")&"-"&E30&"-"&TEXT(B30,"000")) -> 26-001-DS-003 | I30: =IF(AND(J30=0,K30=0), "-", TEXT(J30,"0.00")&" - "&TEXT(K30,"0.00")&" m") -> 1.50 - 1.95 m | J30: 1.5 | K30: 1.95 | M30: 1 | N30: 1 | O30: 1 | AD30: 1 | AL30: =IF(OR(M30=1,N30=1,O30=1,P30=1,Q30=1,R30=1,AI30=1),MAX($AL$27:AL29)+1,"") -> 3 | AM30: =IF(OR(W30=1,X30=1,Y30=1,Z30=1,AA30=1,AB30=1,AC30=1,AD30=1,AE30=1,AF30=1),MAX($AM$27:AM29)+1,"") -> 3 | AN30: =IF(OR(V30=1,AJ30=1),MAX($AN$26:AN28)+1,"") | AO30: =IF(OR(S30=1,T30=1,AG30=1,AH30=1),MAX($AO$27:AO29)+1,"") | AQ30: =IF(SUM(M30,N30,O30,P30,Q30,R30,AI30)>0,1,0) -> 1 | AR30: =IF(SUM(W30,X30,Y30,Z30,AA30,AB30,AC30,AD30,AE30,AF30)>0,1,0) -> 1 | AS30: =IF(SUM(U30,V30,AJ30)>0,1,0) -> 0 | AT30: =IF(SUM(S30,T30,AG30,AH30)>0,1,0) -> 0 | AX30: =IF(COUNTIF(M30:AJ30,1)>0,H30,"") -> 26-001-DS-003 | BA30: =IF(OR(E30="CS",J30="",K30="",AND(J30=0,K30=0)),"",ROUND((J30+K30)/2,2)) -> 1.73 | BC30: =IF(OR(E30="CS",J30="",K30="",AND(J30=0,K30=0)),"",I30) -> 1.50 - 1.95 m | BF30: =IF(COUNTIF(M30:AJ30,1)>0,C30,"") -> BH-07-R-SPT-01 | BS30: 3 | BT30: Hidrometer | BU30: 3423:2008
A31: CS | B31: =B30+1 -> 4 | C31: =CONCATENATE(F31,"-",G31) -> BH-07-R-SPT 03 | D31: =IF(E31="DS","Disturbed Sample", IF(E31="UDS","Undisturbed Sample", IF(E31="BS","Bulk Sample", IF(E31="CS","Composite Sample","")))) -> Disturbed Sample | E31: DS | F31: BH-07-R | G31: SPT 03 | H31: =IF(OR($H$12="",$H$11="",E31="",B31=""),"",RIGHT($H$12,2)&"-"&TEXT($H$11,"000")&"-"&E31&"-"&TEXT(B31,"000")) -> 26-001-DS-004 | I31: =IF(AND(J31=0,K31=0), "-", TEXT(J31,"0.00")&" - "&TEXT(K31,"0.00")&" m") -> 4.50 - 4.95 m | J31: 4.5 | K31: 4.95 | M31: 1 | N31: 1 | O31: 1 | AD31: 1 | AL31: =IF(OR(M31=1,N31=1,O31=1,P31=1,Q31=1,R31=1,AI31=1),MAX($AL$27:AL30)+1,"") -> 4 | AM31: =IF(OR(W31=1,X31=1,Y31=1,Z31=1,AA31=1,AB31=1,AC31=1,AD31=1,AE31=1,AF31=1),MAX($AM$27:AM30)+1,"") -> 4 | AN31: =IF(OR(V31=1,AJ31=1),MAX($AN$26:AN29)+1,"") | AO31: =IF(OR(S31=1,T31=1,AG31=1,AH31=1),MAX($AO$27:AO30)+1,"") | AQ31: =IF(SUM(M31,N31,O31,P31,Q31,R31,AI31)>0,1,0) -> 1 | AR31: =IF(SUM(W31,X31,Y31,Z31,AA31,AB31,AC31,AD31,AE31,AF31)>0,1,0) -> 1 | AS31: =IF(SUM(U31,V31,AJ31)>0,1,0) -> 0 | AT31: =IF(SUM(S31,T31,AG31,AH31)>0,1,0) -> 0 | AX31: =IF(COUNTIF(M31:AJ31,1)>0,H31,"") -> 26-001-DS-004 | BA31: =IF(OR(E31="CS",J31="",K31="",AND(J31=0,K31=0)),"",ROUND((J31+K31)/2,2)) -> 4.73 | BC31: =IF(OR(E31="CS",J31="",K31="",AND(J31=0,K31=0)),"",I31) -> 4.50 - 4.95 m | BF31: =IF(COUNTIF(M31:AJ31,1)>0,C31,"") -> BH-07-R-SPT 03 | BS31: 4 | BT31: Spesific gravity/Uji berat Jenis | BU31: 1964:2008
B32: =B31+1 -> 5 | C32: =CONCATENATE(F32,"-",G32) -> BH-06-R2-SPT 01 | D32: =IF(E32="DS","Disturbed Sample", IF(E32="UDS","Undisturbed Sample", IF(E32="BS","Bulk Sample", IF(E32="CS","Composite Sample","")))) -> Disturbed Sample | E32: DS | F32: BH-06-R2 | G32: SPT 01 | H32: =IF(OR($H$12="",$H$11="",E32="",B32=""),"",RIGHT($H$12,2)&"-"&TEXT($H$11,"000")&"-"&E32&"-"&TEXT(B32,"000")) -> 26-001-DS-005 | I32: =IF(AND(J32=0,K32=0), "-", TEXT(J32,"0.00")&" - "&TEXT(K32,"0.00")&" m") -> 1.50 - 1.95 m | J32: 1.5 | K32: 1.95 | M32: 1 | N32: 1 | O32: 1 | AD32: 1 | AL32: =IF(OR(M32=1,N32=1,O32=1,P32=1,Q32=1,R32=1,AI32=1),MAX($AL$27:AL31)+1,"") -> 5 | AM32: =IF(OR(W32=1,X32=1,Y32=1,Z32=1,AA32=1,AB32=1,AC32=1,AD32=1,AE32=1,AF32=1),MAX($AM$27:AM31)+1,"") -> 5 | AN32: =IF(OR(V32=1,AJ32=1),MAX($AN$26:AN30)+1,"") | AO32: =IF(OR(S32=1,T32=1,AG32=1,AH32=1),MAX($AO$27:AO31)+1,"") | AQ32: =IF(SUM(M32,N32,O32,P32,Q32,R32,AI32)>0,1,0) -> 1 | AR32: =IF(SUM(W32,X32,Y32,Z32,AA32,AB32,AC32,AD32,AE32,AF32)>0,1,0) -> 1 | AS32: =IF(SUM(U32,V32,AJ32)>0,1,0) -> 0 | AT32: =IF(SUM(S32,T32,AG32,AH32)>0,1,0) -> 0 | AX32: =IF(COUNTIF(M32:AJ32,1)>0,H32,"") -> 26-001-DS-005 | BA32: =IF(OR(E32="CS",J32="",K32="",AND(J32=0,K32=0)),"",ROUND((J32+K32)/2,2)) -> 1.73 | BC32: =IF(OR(E32="CS",J32="",K32="",AND(J32=0,K32=0)),"",I32) -> 1.50 - 1.95 m | BF32: =IF(COUNTIF(M32:AJ32,1)>0,C32,"") -> BH-06-R2-SPT 01 | BS32: 5 | BT32: Moisture Content/Uji kadar air | BU32: 1965:2008
B33: =B32+1 -> 6 | C33: =CONCATENATE(F33,"-",G33) -> BH-06-R2-SPT 03 | D33: =IF(E33="DS","Disturbed Sample", IF(E33="UDS","Undisturbed Sample", IF(E33="BS","Bulk Sample", IF(E33="CS","Composite Sample","")))) -> Disturbed Sample | E33: DS | F33: BH-06-R2 | G33: SPT 03 | H33: =IF(OR($H$12="",$H$11="",E33="",B33=""),"",RIGHT($H$12,2)&"-"&TEXT($H$11,"000")&"-"&E33&"-"&TEXT(B33,"000")) -> 26-001-DS-006 | I33: =IF(AND(J33=0,K33=0), "-", TEXT(J33,"0.00")&" - "&TEXT(K33,"0.00")&" m") -> 4.50 - 4.95 m | J33: 4.5 | K33: 4.95 | M33: 1 | N33: 1 | O33: 1 | P33: 1 | Q33: 1 | R33: 1 | V33: 1 | AD33: 1 | AL33: =IF(OR(M33=1,N33=1,O33=1,P33=1,Q33=1,R33=1,AI33=1),MAX($AL$27:AL32)+1,"") -> 6 | AM33: =IF(OR(W33=1,X33=1,Y33=1,Z33=1,AA33=1,AB33=1,AC33=1,AD33=1,AE33=1,AF33=1),MAX($AM$27:AM32)+1,"") -> 6 | AN33: =IF(OR(V33=1,AJ33=1),MAX($AN$26:AN31)+1,"") -> 1 | AO33: =IF(OR(S33=1,T33=1,AG33=1,AH33=1),MAX($AO$27:AO32)+1,"") | AQ33: =IF(SUM(M33,N33,O33,P33,Q33,R33,AI33)>0,1,0) -> 1 | AR33: =IF(SUM(W33,X33,Y33,Z33,AA33,AB33,AC33,AD33,AE33,AF33)>0,1,0) -> 1 | AS33: =IF(SUM(U33,V33,AJ33)>0,1,0) -> 1 | AT33: =IF(SUM(S33,T33,AG33,AH33)>0,1,0) -> 0 | AX33: =IF(COUNTIF(M33:AJ33,1)>0,H33,"") -> 26-001-DS-006 | BA33: =IF(OR(E33="CS",J33="",K33="",AND(J33=0,K33=0)),"",ROUND((J33+K33)/2,2)) -> 4.73 | BC33: =IF(OR(E33="CS",J33="",K33="",AND(J33=0,K33=0)),"",I33) -> 4.50 - 4.95 m | BF33: =IF(COUNTIF(M33:AJ33,1)>0,C33,"") -> BH-06-R2-SPT 03 | BS33: 6 | BT33: Atterberg Limit
B34: =B33+1 -> 7 | C34: =CONCATENATE(F34,"-",G34) -> BH-04R1-UDS 01 | D34: =IF(E34="DS","Disturbed Sample", IF(E34="UDS","Undisturbed Sample", IF(E34="BS","Bulk Sample", IF(E34="CS","Composite Sample","")))) -> Undisturbed Sample | E34: UDS | F34: BH-04R1 | G34: UDS 01 | H34: =IF(OR($H$12="",$H$11="",E34="",B34=""),"",RIGHT($H$12,2)&"-"&TEXT($H$11,"000")&"-"&E34&"-"&TEXT(B34,"000")) -> 26-001-UDS-007 | I34: =IF(AND(J34=0,K34=0), "-", TEXT(J34,"0.00")&" - "&TEXT(K34,"0.00")&" m") -> 10.00 - 10.15 m | J34: 10 | K34: 10.15 | M34: 1 | N34: 1 | O34: 1 | AD34: 1 | AL34: =IF(OR(M34=1,N34=1,O34=1,P34=1,Q34=1,R34=1,AI34=1),MAX($AL$27:AL33)+1,"") -> 7 | AM34: =IF(OR(W34=1,X34=1,Y34=1,Z34=1,AA34=1,AB34=1,AC34=1,AD34=1,AE34=1,AF34=1),MAX($AM$27:AM33)+1,"") -> 7 | AN34: =IF(OR(V34=1,AJ34=1),MAX($AN$26:AN32)+1,"") | AO34: =IF(OR(S34=1,T34=1,AG34=1,AH34=1),MAX($AO$27:AO33)+1,"") | AQ34: =IF(SUM(M34,N34,O34,P34,Q34,R34,AI34)>0,1,0) -> 1 | AR34: =IF(SUM(W34,X34,Y34,Z34,AA34,AB34,AC34,AD34,AE34,AF34)>0,1,0) -> 1 | AS34: =IF(SUM(U34,V34,AJ34)>0,1,0) -> 0 | AT34: =IF(SUM(S34,T34,AG34,AH34)>0,1,0) -> 0 | AX34: =IF(COUNTIF(M34:AJ34,1)>0,H34,"") -> 26-001-UDS-007 | BA34: =IF(OR(E34="CS",J34="",K34="",AND(J34=0,K34=0)),"",ROUND((J34+K34)/2,2)) -> 10.08 | BC34: =IF(OR(E34="CS",J34="",K34="",AND(J34=0,K34=0)),"",I34) -> 10.00 - 10.15 m | BF34: =IF(COUNTIF(M34:AJ34,1)>0,C34,"") -> BH-04R1-UDS 01 | BT34: - Uji Batas Plastis dan Indeks Plastisitas | BU34: 1966:2008
B35: =B34+1 -> 8 | C35: =CONCATENATE(F35,"-",G35) -> BH-05-R-UDS 01 | D35: =IF(E35="DS","Disturbed Sample", IF(E35="UDS","Undisturbed Sample", IF(E35="BS","Bulk Sample", IF(E35="CS","Composite Sample","")))) -> Undisturbed Sample | E35: UDS | F35: BH-05-R | G35: UDS 01 | H35: =IF(OR($H$12="",$H$11="",E35="",B35=""),"",RIGHT($H$12,2)&"-"&TEXT($H$11,"000")&"-"&E35&"-"&TEXT(B35,"000")) -> 26-001-UDS-008 | I35: =IF(AND(J35=0,K35=0), "-", TEXT(J35,"0.00")&" - "&TEXT(K35,"0.00")&" m") -> 0.50 - 0.75 m | J35: 0.5 | K35: 0.75 | M35: 1 | N35: 1 | O35: 1 | R35: 1 | V35: 1 | AD35: 1 | AL35: =IF(OR(M35=1,N35=1,O35=1,P35=1,Q35=1,R35=1,AI35=1),MAX($AL$27:AL34)+1,"") -> 8 | AM35: =IF(OR(W35=1,X35=1,Y35=1,Z35=1,AA35=1,AB35=1,AC35=1,AD35=1,AE35=1,AF35=1),MAX($AM$27:AM34)+1,"") -> 8 | AN35: =IF(OR(V35=1,AJ35=1),MAX($AN$26:AN33)+1,"") -> 2 | AO35: =IF(OR(S35=1,T35=1,AG35=1,AH35=1),MAX($AO$27:AO34)+1,"") | AQ35: =IF(SUM(M35,N35,O35,P35,Q35,R35,AI35)>0,1,0) -> 1 | AR35: =IF(SUM(W35,X35,Y35,Z35,AA35,AB35,AC35,AD35,AE35,AF35)>0,1,0) -> 1 | AS35: =IF(SUM(U35,V35,AJ35)>0,1,0) -> 1 | AT35: =IF(SUM(S35,T35,AG35,AH35)>0,1,0) -> 0 | AX35: =IF(COUNTIF(M35:AJ35,1)>0,H35,"") -> 26-001-UDS-008 | BA35: =IF(OR(E35="CS",J35="",K35="",AND(J35=0,K35=0)),"",ROUND((J35+K35)/2,2)) -> 0.63 | BC35: =IF(OR(E35="CS",J35="",K35="",AND(J35=0,K35=0)),"",I35) -> 0.50 - 0.75 m | BF35: =IF(COUNTIF(M35:AJ35,1)>0,C35,"") -> BH-05-R-UDS 01 | BT35: - Uji Batas Batas Cair | BU35: 1967:2008
B36: =B35+1 -> 9 | C36: =CONCATENATE(F36,"-",G36) -> BH-03-R-UDS 01 | D36: =IF(E36="DS","Disturbed Sample", IF(E36="UDS","Undisturbed Sample", IF(E36="BS","Bulk Sample", IF(E36="CS","Composite Sample","")))) -> Undisturbed Sample | E36: UDS | F36: BH-03-R | G36: UDS 01 | H36: =IF(OR($H$12="",$H$11="",E36="",B36=""),"",RIGHT($H$12,2)&"-"&TEXT($H$11,"000")&"-"&E36&"-"&TEXT(B36,"000")) -> 26-001-UDS-009 | I36: =IF(AND(J36=0,K36=0), "-", TEXT(J36,"0.00")&" - "&TEXT(K36,"0.00")&" m") -> 4.00 - 4.34 m | J36: 4 | K36: 4.34 | M36: 1 | N36: 1 | O36: 1 | AD36: 1 | AL36: =IF(OR(M36=1,N36=1,O36=1,P36=1,Q36=1,R36=1,AI36=1),MAX($AL$27:AL35)+1,"") -> 9 | AM36: =IF(OR(W36=1,X36=1,Y36=1,Z36=1,AA36=1,AB36=1,AC36=1,AD36=1,AE36=1,AF36=1),MAX($AM$27:AM35)+1,"") -> 9 | AN36: =IF(OR(V36=1,AJ36=1),MAX($AN$26:AN34)+1,"") | AO36: =IF(OR(S36=1,T36=1,AG36=1,AH36=1),MAX($AO$27:AO35)+1,"") | AQ36: =IF(SUM(M36,N36,O36,P36,Q36,R36,AI36)>0,1,0) -> 1 | AR36: =IF(SUM(W36,X36,Y36,Z36,AA36,AB36,AC36,AD36,AE36,AF36)>0,1,0) -> 1 | AS36: =IF(SUM(U36,V36,AJ36)>0,1,0) -> 0 | AT36: =IF(SUM(S36,T36,AG36,AH36)>0,1,0) -> 0 | AX36: =IF(COUNTIF(M36:AJ36,1)>0,H36,"") -> 26-001-UDS-009 | BA36: =IF(OR(E36="CS",J36="",K36="",AND(J36=0,K36=0)),"",ROUND((J36+K36)/2,2)) -> 4.17 | BC36: =IF(OR(E36="CS",J36="",K36="",AND(J36=0,K36=0)),"",I36) -> 4.00 - 4.34 m | BF36: =IF(COUNTIF(M36:AJ36,1)>0,C36,"") -> BH-03-R-UDS 01 | BS36: 7 | BT36: Unit Weight/Uji berat isi tanah | BU36: 03-3637-1994
B37: =B36+1 -> 10 | C37: =CONCATENATE(F37,"-",G37) -> BH-03-R-UDS 04 | D37: =IF(E37="DS","Disturbed Sample", IF(E37="UDS","Undisturbed Sample", IF(E37="BS","Bulk Sample", IF(E37="CS","Composite Sample","")))) -> Undisturbed Sample | E37: UDS | F37: BH-03-R | G37: UDS 04 | H37: =IF(OR($H$12="",$H$11="",E37="",B37=""),"",RIGHT($H$12,2)&"-"&TEXT($H$11,"000")&"-"&E37&"-"&TEXT(B37,"000")) -> 26-001-UDS-010 | I37: =IF(AND(J37=0,K37=0), "-", TEXT(J37,"0.00")&" - "&TEXT(K37,"0.00")&" m") -> 8.50 - 9.00 m | J37: 8.5 | K37: 9 | M37: 1 | N37: 1 | O37: 1 | AD37: 1 | AL37: =IF(OR(M37=1,N37=1,O37=1,P37=1,Q37=1,R37=1,AI37=1),MAX($AL$27:AL36)+1,"") -> 10 | AM37: =IF(OR(W37=1,X37=1,Y37=1,Z37=1,AA37=1,AB37=1,AC37=1,AD37=1,AE37=1,AF37=1),MAX($AM$27:AM36)+1,"") -> 10 | AN37: =IF(OR(V37=1,AJ37=1),MAX($AN$26:AN35)+1,"") | AO37: =IF(OR(S37=1,T37=1,AG37=1,AH37=1),MAX($AO$27:AO36)+1,"") | AQ37: =IF(SUM(M37,N37,O37,P37,Q37,R37,AI37)>0,1,0) -> 1 | AR37: =IF(SUM(W37,X37,Y37,Z37,AA37,AB37,AC37,AD37,AE37,AF37)>0,1,0) -> 1 | AS37: =IF(SUM(U37,V37,AJ37)>0,1,0) -> 0 | AT37: =IF(SUM(S37,T37,AG37,AH37)>0,1,0) -> 0 | AX37: =IF(COUNTIF(M37:AJ37,1)>0,H37,"") -> 26-001-UDS-010 | BA37: =IF(OR(E37="CS",J37="",K37="",AND(J37=0,K37=0)),"",ROUND((J37+K37)/2,2)) -> 8.75 | BC37: =IF(OR(E37="CS",J37="",K37="",AND(J37=0,K37=0)),"",I37) -> 8.50 - 9.00 m | BF37: =IF(COUNTIF(M37:AJ37,1)>0,C37,"") -> BH-03-R-UDS 04 | BS37: 8 | BT37: Uji Triaxial
B38: =B37+1 -> 11 | C38: =CONCATENATE(F38,"-",G38) -> BH-07-R-UDS 01 | D38: =IF(E38="DS","Disturbed Sample", IF(E38="UDS","Undisturbed Sample", IF(E38="BS","Bulk Sample", IF(E38="CS","Composite Sample","")))) -> Undisturbed Sample | E38: UDS | F38: BH-07-R | G38: UDS 01 | H38: =IF(OR($H$12="",$H$11="",E38="",B38=""),"",RIGHT($H$12,2)&"-"&TEXT($H$11,"000")&"-"&E38&"-"&TEXT(B38,"000")) -> 26-001-UDS-011 | I38: =IF(AND(J38=0,K38=0), "-", TEXT(J38,"0.00")&" - "&TEXT(K38,"0.00")&" m") -> 1.00 - 1.50 m | J38: 1 | K38: 1.5 | M38: 1 | N38: 1 | O38: 1 | AD38: 1 | AL38: =IF(OR(M38=1,N38=1,O38=1,P38=1,Q38=1,R38=1,AI38=1),MAX($AL$27:AL37)+1,"") -> 11 | AM38: =IF(OR(W38=1,X38=1,Y38=1,Z38=1,AA38=1,AB38=1,AC38=1,AD38=1,AE38=1,AF38=1),MAX($AM$27:AM37)+1,"") -> 11 | AN38: =IF(OR(V38=1,AJ38=1),MAX($AN$26:AN36)+1,"") | AO38: =IF(OR(S38=1,T38=1,AG38=1,AH38=1),MAX($AO$27:AO37)+1,"") | AQ38: =IF(SUM(M38,N38,O38,P38,Q38,R38,AI38)>0,1,0) -> 1 | AR38: =IF(SUM(W38,X38,Y38,Z38,AA38,AB38,AC38,AD38,AE38,AF38)>0,1,0) -> 1 | AS38: =IF(SUM(U38,V38,AJ38)>0,1,0) -> 0 | AT38: =IF(SUM(S38,T38,AG38,AH38)>0,1,0) -> 0 | AX38: =IF(COUNTIF(M38:AJ38,1)>0,H38,"") -> 26-001-UDS-011 | BA38: =IF(OR(E38="CS",J38="",K38="",AND(J38=0,K38=0)),"",ROUND((J38+K38)/2,2)) -> 1.25 | BC38: =IF(OR(E38="CS",J38="",K38="",AND(J38=0,K38=0)),"",I38) -> 1.00 - 1.50 m | BF38: =IF(COUNTIF(M38:AJ38,1)>0,C38,"") -> BH-07-R-UDS 01 | BT38: - Triaxial UU | BU38: 4813:2015
B39: =B38+1 -> 12 | C39: =CONCATENATE(F39,"-",G39) -> BH-06-R2-UDS 01 | D39: =IF(E39="DS","Disturbed Sample", IF(E39="UDS","Undisturbed Sample", IF(E39="BS","Bulk Sample", IF(E39="CS","Composite Sample","")))) -> Undisturbed Sample | E39: UDS | F39: BH-06-R2 | G39: UDS 01 | H39: =IF(OR($H$12="",$H$11="",E39="",B39=""),"",RIGHT($H$12,2)&"-"&TEXT($H$11,"000")&"-"&E39&"-"&TEXT(B39,"000")) -> 26-001-UDS-012 | I39: =IF(AND(J39=0,K39=0), "-", TEXT(J39,"0.00")&" - "&TEXT(K39,"0.00")&" m") -> 2.50 - 3.00 m | J39: 2.5 | K39: 3 | M39: 1 | N39: 1 | O39: 1 | P39: 1 | R39: 1 | V39: 1 | AD39: 1 | AL39: =IF(OR(M39=1,N39=1,O39=1,P39=1,Q39=1,R39=1,AI39=1),MAX($AL$27:AL38)+1,"") -> 12 | AM39: =IF(OR(W39=1,X39=1,Y39=1,Z39=1,AA39=1,AB39=1,AC39=1,AD39=1,AE39=1,AF39=1),MAX($AM$27:AM38)+1,"") -> 12 | AN39: =IF(OR(V39=1,AJ39=1),MAX($AN$26:AN37)+1,"") -> 3 | AO39: =IF(OR(S39=1,T39=1,AG39=1,AH39=1),MAX($AO$27:AO38)+1,"") | AQ39: =IF(SUM(M39,N39,O39,P39,Q39,R39,AI39)>0,1,0) -> 1 | AR39: =IF(SUM(W39,X39,Y39,Z39,AA39,AB39,AC39,AD39,AE39,AF39)>0,1,0) -> 1 | AS39: =IF(SUM(U39,V39,AJ39)>0,1,0) -> 1 | AT39: =IF(SUM(S39,T39,AG39,AH39)>0,1,0) -> 0 | AX39: =IF(COUNTIF(M39:AJ39,1)>0,H39,"") -> 26-001-UDS-012 | BA39: =IF(OR(E39="CS",J39="",K39="",AND(J39=0,K39=0)),"",ROUND((J39+K39)/2,2)) -> 2.75 | BC39: =IF(OR(E39="CS",J39="",K39="",AND(J39=0,K39=0)),"",I39) -> 2.50 - 3.00 m | BF39: =IF(COUNTIF(M39:AJ39,1)>0,C39,"") -> BH-06-R2-UDS 01 | BT39: - Triaxial CU | BU39: 2455 : 2015
B40: =B39+1 -> 13 | C40: =CONCATENATE(F40,"-",G40) -> BH-06-R2-UDS 02 | D40: =IF(E40="DS","Disturbed Sample", IF(E40="UDS","Undisturbed Sample", IF(E40="BS","Bulk Sample", IF(E40="CS","Composite Sample","")))) -> Undisturbed Sample | E40: UDS | F40: BH-06-R2 | G40: UDS 02 | H40: =IF(OR($H$12="",$H$11="",E40="",B40=""),"",RIGHT($H$12,2)&"-"&TEXT($H$11,"000")&"-"&E40&"-"&TEXT(B40,"000")) -> 26-001-UDS-013 | I40: =IF(AND(J40=0,K40=0), "-", TEXT(J40,"0.00")&" - "&TEXT(K40,"0.00")&" m") -> 4.00 - 4.50 m | J40: 4 | K40: 4.5 | M40: 1 | N40: 1 | O40: 1 | AD40: 1 | AL40: =IF(OR(M40=1,N40=1,O40=1,P40=1,Q40=1,R40=1,AI40=1),MAX($AL$27:AL39)+1,"") -> 13 | AM40: =IF(OR(W40=1,X40=1,Y40=1,Z40=1,AA40=1,AB40=1,AC40=1,AD40=1,AE40=1,AF40=1),MAX($AM$27:AM39)+1,"") -> 13 | AN40: =IF(OR(V40=1,AJ40=1),MAX($AN$26:AN38)+1,"") | AO40: =IF(OR(S40=1,T40=1,AG40=1,AH40=1),MAX($AO$27:AO39)+1,"") | AQ40: =IF(SUM(M40,N40,O40,P40,Q40,R40,AI40)>0,1,0) -> 1 | AR40: =IF(SUM(W40,X40,Y40,Z40,AA40,AB40,AC40,AD40,AE40,AF40)>0,1,0) -> 1 | AS40: =IF(SUM(U40,V40,AJ40)>0,1,0) -> 0 | AT40: =IF(SUM(S40,T40,AG40,AH40)>0,1,0) -> 0 | AX40: =IF(COUNTIF(M40:AJ40,1)>0,H40,"") -> 26-001-UDS-013 | BA40: =IF(OR(E40="CS",J40="",K40="",AND(J40=0,K40=0)),"",ROUND((J40+K40)/2,2)) -> 4.25 | BC40: =IF(OR(E40="CS",J40="",K40="",AND(J40=0,K40=0)),"",I40) -> 4.00 - 4.50 m | BF40: =IF(COUNTIF(M40:AJ40,1)>0,C40,"") -> BH-06-R2-UDS 02 | BT40: - Triaxial CD | BU40: 2455 : 2015
B41: =B40+1 -> 14 | C41: =CONCATENATE(F41,"-",G41) -> BH-04R1-DS 01 | D41: =IF(E41="DS","Disturbed Sample", IF(E41="UDS","Undisturbed Sample", IF(E41="BS","Bulk Sample", IF(E41="CS","Composite Sample","")))) -> Disturbed Sample | E41: DS | F41: BH-04R1 | G41: DS 01 | H41: =IF(OR($H$12="",$H$11="",E41="",B41=""),"",RIGHT($H$12,2)&"-"&TEXT($H$11,"000")&"-"&E41&"-"&TEXT(B41,"000")) -> 26-001-DS-014 | I41: =IF(AND(J41=0,K41=0), "-", TEXT(J41,"0.00")&" - "&TEXT(K41,"0.00")&" m") -> 19.95 - 20.30 m | J41: 19.95 | K41: 20.3 | M41: 1 | N41: 1 | O41: 1 | AD41: 1 | AL41: =IF(OR(M41=1,N41=1,O41=1,P41=1,Q41=1,R41=1,AI41=1),MAX($AL$27:AL40)+1,"") -> 14 | AM41: =IF(OR(W41=1,X41=1,Y41=1,Z41=1,AA41=1,AB41=1,AC41=1,AD41=1,AE41=1,AF41=1),MAX($AM$27:AM40)+1,"") -> 14 | AN41: =IF(OR(V41=1,AJ41=1),MAX($AN$26:AN39)+1,"") | AO41: =IF(OR(S41=1,T41=1,AG41=1,AH41=1),MAX($AO$27:AO40)+1,"") | AQ41: =IF(SUM(M41,N41,O41,P41,Q41,R41,AI41)>0,1,0) -> 1 | AR41: =IF(SUM(W41,X41,Y41,Z41,AA41,AB41,AC41,AD41,AE41,AF41)>0,1,0) -> 1 | AS41: =IF(SUM(U41,V41,AJ41)>0,1,0) -> 0 | AT41: =IF(SUM(S41,T41,AG41,AH41)>0,1,0) -> 0 | AX41: =IF(COUNTIF(M41:AJ41,1)>0,H41,"") -> 26-001-DS-014 | BA41: =IF(OR(E41="CS",J41="",K41="",AND(J41=0,K41=0)),"",ROUND((J41+K41)/2,2)) -> 20.13 | BC41: =IF(OR(E41="CS",J41="",K41="",AND(J41=0,K41=0)),"",I41) -> 19.95 - 20.30 m | BF41: =IF(COUNTIF(M41:AJ41,1)>0,C41,"") -> BH-04R1-DS 01 | BS41: 9 | BT41: Unconfined CompressionTest (UCS)/Uji Kuat Tekan Bebas | BU41: 3638:2012
B42: =B41+1 -> 15 | C42: =CONCATENATE(F42,"-",G42) -> BH-04R1-DS 04 | D42: =IF(E42="DS","Disturbed Sample", IF(E42="UDS","Undisturbed Sample", IF(E42="BS","Bulk Sample", IF(E42="CS","Composite Sample","")))) -> Disturbed Sample | E42: DS | F42: BH-04R1 | G42: DS 04 | H42: =IF(OR($H$12="",$H$11="",E42="",B42=""),"",RIGHT($H$12,2)&"-"&TEXT($H$11,"000")&"-"&E42&"-"&TEXT(B42,"000")) -> 26-001-DS-015 | I42: =IF(AND(J42=0,K42=0), "-", TEXT(J42,"0.00")&" - "&TEXT(K42,"0.00")&" m") -> 25.23 - 25.43 m | J42: 25.23 | K42: 25.43 | M42: 1 | N42: 1 | O42: 1 | W42: 1 | AD42: 1 | AL42: =IF(OR(M42=1,N42=1,O42=1,P42=1,Q42=1,R42=1,AI42=1),MAX($AL$27:AL41)+1,"") -> 15 | AM42: =IF(OR(W42=1,X42=1,Y42=1,Z42=1,AA42=1,AB42=1,AC42=1,AD42=1,AE42=1,AF42=1),MAX($AM$27:AM41)+1,"") -> 15 | AN42: =IF(OR(V42=1,AJ42=1),MAX($AN$26:AN40)+1,"") | AO42: =IF(OR(S42=1,T42=1,AG42=1,AH42=1),MAX($AO$27:AO41)+1,"") | AQ42: =IF(SUM(M42,N42,O42,P42,Q42,R42,AI42)>0,1,0) -> 1 | AR42: =IF(SUM(W42,X42,Y42,Z42,AA42,AB42,AC42,AD42,AE42,AF42)>0,1,0) -> 1 | AS42: =IF(SUM(U42,V42,AJ42)>0,1,0) -> 0 | AT42: =IF(SUM(S42,T42,AG42,AH42)>0,1,0) -> 0 | AX42: =IF(COUNTIF(M42:AJ42,1)>0,H42,"") -> 26-001-DS-015 | BA42: =IF(OR(E42="CS",J42="",K42="",AND(J42=0,K42=0)),"",ROUND((J42+K42)/2,2)) -> 25.33 | BC42: =IF(OR(E42="CS",J42="",K42="",AND(J42=0,K42=0)),"",I42) -> 25.23 - 25.43 m | BF42: =IF(COUNTIF(M42:AJ42,1)>0,C42,"") -> BH-04R1-DS 04 | BS42: 10 | BT42: Direct shear/Uji Kuat Geser Langsung
B43: =B42+1 -> 16 | C43: =CONCATENATE(F43,"-",G43) -> BH-05-R-DS 01 | D43: =IF(E43="DS","Disturbed Sample", IF(E43="UDS","Undisturbed Sample", IF(E43="BS","Bulk Sample", IF(E43="CS","Composite Sample","")))) -> Disturbed Sample | E43: DS | F43: BH-05-R | G43: DS 01 | H43: =IF(OR($H$12="",$H$11="",E43="",B43=""),"",RIGHT($H$12,2)&"-"&TEXT($H$11,"000")&"-"&E43&"-"&TEXT(B43,"000")) -> 26-001-DS-016 | I43: =IF(AND(J43=0,K43=0), "-", TEXT(J43,"0.00")&" - "&TEXT(K43,"0.00")&" m") -> 3.92 - 4.15 m | J43: 3.92 | K43: 4.15 | M43: 1 | N43: 1 | O43: 1 | P43: 1 | R43: 1 | W43: 1 | AD43: 1 | AL43: =IF(OR(M43=1,N43=1,O43=1,P43=1,Q43=1,R43=1,AI43=1),MAX($AL$27:AL42)+1,"") -> 16 | AM43: =IF(OR(W43=1,X43=1,Y43=1,Z43=1,AA43=1,AB43=1,AC43=1,AD43=1,AE43=1,AF43=1),MAX($AM$27:AM42)+1,"") -> 16 | AN43: =IF(OR(V43=1,AJ43=1),MAX($AN$26:AN41)+1,"") | AO43: =IF(OR(S43=1,T43=1,AG43=1,AH43=1),MAX($AO$27:AO42)+1,"") | AQ43: =IF(SUM(M43,N43,O43,P43,Q43,R43,AI43)>0,1,0) -> 1 | AR43: =IF(SUM(W43,X43,Y43,Z43,AA43,AB43,AC43,AD43,AE43,AF43)>0,1,0) -> 1 | AS43: =IF(SUM(U43,V43,AJ43)>0,1,0) -> 0 | AT43: =IF(SUM(S43,T43,AG43,AH43)>0,1,0) -> 0 | AX43: =IF(COUNTIF(M43:AJ43,1)>0,H43,"") -> 26-001-DS-016 | BA43: =IF(OR(E43="CS",J43="",K43="",AND(J43=0,K43=0)),"",ROUND((J43+K43)/2,2)) -> 4.04 | BC43: =IF(OR(E43="CS",J43="",K43="",AND(J43=0,K43=0)),"",I43) -> 3.92 - 4.15 m | BF43: =IF(COUNTIF(M43:AJ43,1)>0,C43,"") -> BH-05-R-DS 01 | BT43: Direct shear UU | BU43: 3420:2016
B44: =B43+1 -> 17 | C44: =CONCATENATE(F44,"-",G44) -> BH-03-R-DS 01 | D44: =IF(E44="DS","Disturbed Sample", IF(E44="UDS","Undisturbed Sample", IF(E44="BS","Bulk Sample", IF(E44="CS","Composite Sample","")))) -> Disturbed Sample | E44: DS | F44: BH-03-R | G44: DS 01 | H44: =IF(OR($H$12="",$H$11="",E44="",B44=""),"",RIGHT($H$12,2)&"-"&TEXT($H$11,"000")&"-"&E44&"-"&TEXT(B44,"000")) -> 26-001-DS-017 | I44: =IF(AND(J44=0,K44=0), "-", TEXT(J44,"0.00")&" - "&TEXT(K44,"0.00")&" m") -> 2.50 - 3.00 m | J44: 2.5 | K44: 3 | M44: 1 | N44: 1 | O44: 1 | P44: 1 | R44: 1 | W44: 1 | AL44: =IF(OR(M44=1,N44=1,O44=1,P44=1,Q44=1,R44=1,AI44=1),MAX($AL$27:AL43)+1,"") -> 17 | AM44: =IF(OR(W44=1,X44=1,Y44=1,Z44=1,AA44=1,AB44=1,AC44=1,AD44=1,AE44=1,AF44=1),MAX($AM$27:AM43)+1,"") -> 17 | AN44: =IF(OR(V44=1,AJ44=1),MAX($AN$26:AN42)+1,"") | AO44: =IF(OR(S44=1,T44=1,AG44=1,AH44=1),MAX($AO$27:AO43)+1,"") | AQ44: =IF(SUM(M44,N44,O44,P44,Q44,R44,AI44)>0,1,0) -> 1 | AR44: =IF(SUM(W44,X44,Y44,Z44,AA44,AB44,AC44,AD44,AE44,AF44)>0,1,0) -> 1 | AS44: =IF(SUM(U44,V44,AJ44)>0,1,0) -> 0 | AT44: =IF(SUM(S44,T44,AG44,AH44)>0,1,0) -> 0 | AX44: =IF(COUNTIF(M44:AJ44,1)>0,H44,"") -> 26-001-DS-017 | BA44: =IF(OR(E44="CS",J44="",K44="",AND(J44=0,K44=0)),"",ROUND((J44+K44)/2,2)) -> 2.75 | BC44: =IF(OR(E44="CS",J44="",K44="",AND(J44=0,K44=0)),"",I44) -> 2.50 - 3.00 m | BF44: =IF(COUNTIF(M44:AJ44,1)>0,C44,"") -> BH-03-R-DS 01 | BT44: Direct shear CU | BU44: 2813 : 2008
...

Sheet Excecutive Summary
D2: LABORATORIUM MEKANIKA TANAH DAN BATUAN | V2: RINGKASAN LAPORAN HASIL UJI
D3: PT. TERRAFORMA GEOTEKNIK INDONESIA | V3: TEST RESULT SUMMARY
A7: Nomor Laporan / Report Number
A8: Revisi / Revision
A9: Tgl Revisi / Revision date | M9: Tgl Laporan / Report Date | X9: Halaman /Pages | AA9: =": 1 dari X" -> : 1 dari X
D23: RINGKASAN EKSEKUTIF / EXECUTIVE SUMMARY
D29: INFORMASI PROYEK/PROJECT INFORMATION | Q29: RINGKASAN SAMPEL / SAMPLE SUMMARY
D31: Nama Proyek / Project Name | Q31: Ringkasan Sampel | X31: Jumlah
Q33: Sampel Diterima / Samples Received | X33: 25
D34: Lokasi Proyek / Project Location | Q34: Sampel Individual Diuji / Individual Samples Tested | X34: 25
D35: No. PO / PO Number | Q35: Sampel Komposit Diuji / Composite Samples Tested | X35: 0
Q36: Total Sampel Diuji / Total Samples Tested | X36: =X34+X35 -> 25
Q37: Sampel Tidak Diuji / Samples Not Tested | X37: 0
D39: IDENTITAS KLIEN / CLIENT INFORMATION | Q39: =IF(OR(X35>0,X37>0),"Catatan / Notes: ","") & IF(X35>0, X35& " sampel komposit diuji sebagai sampel representatif hasil penggabungan beberapa sampel / "& X35& " composite samples were tested as representative samples prepared from multiple samples", "") & IF(AND(X35>0,X37>0),"; ","") & IF(X37>0, X37& " sampel tidak dilakukan pengujian / "& X37& " samples were not tested", "")
D41: Klien / Client
D42: Alamat / Address
H43: =": "&IF('[4]DATA INDUK'!$H$6="","",'[4]DATA INDUK'!L26) -> :
Q44: RINGKASAN KELOMPOK PENGUJIAN / TEST GROUP SUMMARY
Q46: Kelompok Pengujian / Test Group | W46: Jumlah Sampel Diuji / Number of SamplesTested
Q48: Physical Properties | W48: =SUM('DATA INDUK'!$AQ$28:AQ328) -> 25 | AD48: ='DATA INDUK'!$H$9 -> PO-GQT-001
Q49: Shear Strength | W49: =SUM('DATA INDUK'!$AR$28:AR328) -> 24 | AD49: ='DATA INDUK'!$P$17 -> QMS/SUM-001/VI/2026
Q50: Compaction & CBR | W50: =SUM('DATA INDUK'!$AS$28:AS328) -> 3 | AD50: EXEC
Q51: Consolidation & Permeability | W51: =SUM('DATA INDUK'!$AT$28:AT328) -> 5
A68: KETERANGAN / REMARK | E68: Summary ini merupakan ringkasan hasil pengujian yang disusun berdasarkan Laporan Hasil Uji (LHU) terkait. Apabila terdapat perbedaan interpretasi, maka data dan informasi yang tercantum dalam LHU yang bersangkutan menjadi acuan utama./ This summary presents a compilation of test results derived from the corresponding Test Reports (LHU). In the event of any discrepancy in interpretation, the data and information stated in the respective Test Report shall prevail. | N68: DIPERSIAPKAN OLEH / PREPARED BY | S68: DISETUJUI OLEH / APPROVED BY
N74: KOORDINATOR MUTU | S74: KA. LABORATORIUM
N75: Tgl / Date | S75: Tgl / Date

Sheet summary PP
C2: PT. TERRAFORMA GEOTEKNIK INDONESIA | P2: RINGKASAN LAPORAN HASIL UJI
C3: " GROUND TRUTH THROUGH TESTING" | P3: TEST REPORT SUMMARY
A7: Nomor Laporan / Report Number | E7: =": "& IF('DATA INDUK'!$P$17="","",'DATA INDUK'!$P$17) -> : QMS/SUM-001/VI/2026
A8: Revisi / Revision | E8: =": "& IF('DATA INDUK'!$P$18="","",'DATA INDUK'!$P$18) -> : R0
A9: Tgl Revisi / Revision date | E9: =": "& IF('DATA INDUK'!$P$19="","",'DATA INDUK'!$P$19) -> : - | I9: Tgl Laporan / Report Date | L9: =": "& IF('DATA INDUK'!$P$20="","",TEXT('DATA INDUK'!$P$20,"dd mmmm yyyy")) -> : 20 June 2026 | S9: Halaman /Pages | T9: =": 1 dari X" -> : 1 dari X
A12: RINGKASAN KELOMPOK SIFAT FISIK DAN KLASIFIKASI
A13: SUMMARY OF PHYSICAL PROPERTIES AND CLASSIFICATION TEST GROUP | P13: Jumlah Sampel Diuji / Number of Samples Tested | T13: ='Excecutive Summary'!$W$48 -> 25
A16: No | B16: Lab. ID | C16: Sample ID | E16: SAMPLE TYPE | F16: INTERVAL DEPTH | G16: SPESIFIC GRAVITY | H16: MOISTURE CONTENT | I16: UNIT WEIGHT | K16: ATTENBERG LIMIT | O16: GRAIN SIZE ANALYSIS | T16: SHRINKAGE LIMIT | W16: Spesial Request Note | X16: 1
G18: Gs | H18: w (%) | I18: γw (g/cm³) | J18: γd (g/cm³) | K18: LL (%) | L18: PL (%) | M18: PI (%) | N18: USCS | O18: Clay (%) | P18: Silt (%) | Q18: Sand (%) | R18: Gravel (%) | S18: Material Description | T18: SL (%)
A20: =IFERROR(SMALL('DATA INDUK'!$AL$28:$AL$1151,ROWS($A$20:A20)),"") -> 1 | B20: =IF($A20="","",INDEX('DATA INDUK'!$H$28:$H$151,MATCH($A20,'DATA INDUK'!$AL$28:$AL$151,0))) -> 26-001-DS-001 | C20: {=IF($A20="","", _xlfn.LET( _xlpm.Grp,INDEX('DATA INDUK'!$L$28:$L$151, MATCH($A20,'DATA INDUK'!$AL$28:$AL$151,0)), _xlpm.SID,INDEX('DATA INDUK'!$C$28:$C$151, MATCH($A20,'DATA INDUK'!$AL$28:$AL$151,0)), IF( _xlpm.Grp="", _xlpm.SID, _xlfn.TEXTJOIN(CHAR(10),TRUE, _xlfn._xlws.FILTER('DATA INDUK'!$C$28:$C$151, 'DATA INDUK'!$L$28:$L$151=_xlpm.Grp)) ) ))} -> BH-04R1-SPT 15 | E20: =IF($A20="","",INDEX('DATA INDUK'!$D$28:$D$151,MATCH($A20,'DATA INDUK'!$AL$28:$AL$151,0))) -> Disturbed Sample | F20: {=IF($A20="","", _xlfn.LET( _xlpm.Grp,INDEX('DATA INDUK'!$L$28:$L$151, MATCH($A20,'DATA INDUK'!$AL$28:$AL$151,0)), IF( _xlpm.Grp="", INDEX('DATA INDUK'!$I$28:$I$151, MATCH($A20,'DATA INDUK'!$AL$28:$AL$151,0)), _xlfn.TEXTJOIN(CHAR(10),TRUE, _xlfn._xlws.FILTER('DATA INDUK'!$I$28:$I$151, 'DATA INDUK'!$L$28:$L$151=_xlpm.Grp)) ) ))} -> 22.50 - 22.95 m | G20: ='[3]WS-PP'!$C$86 -> 2.6824373 | H20: ='[3]WS-PP'!$C$88 -> 33.378096 | I20: ='[3]WS-PP'!$C$90 -> 1.6970833 | J20: ='[3]WS-PP'!$C$92 -> 1.2723853 | K20: - | L20: - | M20: - | N20: =IF($A20="","", IF(OR($K20="",$M20=""),"", IF($K20="-","-", IF($K20="NP","NP - Non Plastic", IF(AND($K20<50,$M20>=0.73*($K20-20)),"CL - Lean Clay", IF(AND($K20>=50,$M20>=0.73*($K20-20)),"CH - Fat Clay", IF(AND($K20<50,$M20<0.73*($K20-20)),"ML - Silt", IF(AND($K20>=50,$M20<0.73*($K20-20)),"MH - Elastic Silt","")))))))) -> - | O20: - | P20: - | Q20: - | R20: - | T20: -
A21: =IFERROR(SMALL('DATA INDUK'!$AL$28:$AL$1151,ROWS($A$20:A21)),"") -> 2 | B21: =IF($A21="","",INDEX('DATA INDUK'!$H$28:$H$151,MATCH($A21,'DATA INDUK'!$AL$28:$AL$151,0))) -> 26-001-DS-002 | C21: {=IF($A21="","", _xlfn.LET( _xlpm.Grp,INDEX('DATA INDUK'!$L$28:$L$151, MATCH($A21,'DATA INDUK'!$AL$28:$AL$151,0)), _xlpm.SID,INDEX('DATA INDUK'!$C$28:$C$151, MATCH($A21,'DATA INDUK'!$AL$28:$AL$151,0)), IF( _xlpm.Grp="", _xlpm.SID, _xlfn.TEXTJOIN(CHAR(10),TRUE, _xlfn._xlws.FILTER('DATA INDUK'!$C$28:$C$151, 'DATA INDUK'!$L$28:$L$151=_xlpm.Grp)) ) ))} -> BH-03-R-SPT 01 | E21: =IF($A21="","",INDEX('DATA INDUK'!$D$28:$D$151,MATCH($A21,'DATA INDUK'!$AL$28:$AL$151,0))) -> Disturbed Sample | F21: {=IF($A21="","", _xlfn.LET( _xlpm.Grp,INDEX('DATA INDUK'!$L$28:$L$151, MATCH($A21,'DATA INDUK'!$AL$28:$AL$151,0)), IF( _xlpm.Grp="", INDEX('DATA INDUK'!$I$28:$I$151, MATCH($A21,'DATA INDUK'!$AL$28:$AL$151,0)), _xlfn.TEXTJOIN(CHAR(10),TRUE, _xlfn._xlws.FILTER('DATA INDUK'!$I$28:$I$151, 'DATA INDUK'!$L$28:$L$151=_xlpm.Grp)) ) ))} -> 1.50 - 1.95 m | G21: =[4]LHU_PP!$O$36 -> 2.6721216 | H21: =[4]LHU_PP!$O$37 -> 34.854043 | I21: =[4]LHU_PP!$O$38 -> 1.6942878 | J21: =[4]LHU_PP!$O$39 -> 1.2563864 | K21: - | L21: - | M21: - | N21: =IF($A21="","", IF(OR($K21="",$M21=""),"", IF($K21="-","-", IF($K21="NP","NP - Non Plastic", IF(AND($K21<50,$M21>=0.73*($K21-20)),"CL - Lean Clay", IF(AND($K21>=50,$M21>=0.73*($K21-20)),"CH - Fat Clay", IF(AND($K21<50,$M21<0.73*($K21-20)),"ML - Silt", IF(AND($K21>=50,$M21<0.73*($K21-20)),"MH - Elastic Silt","")))))))) -> - | O21: - | P21: - | Q21: - | R21: - | T21: -
A22: =IFERROR(SMALL('DATA INDUK'!$AL$28:$AL$1151,ROWS($A$20:A22)),"") -> 3 | B22: =IF($A22="","",INDEX('DATA INDUK'!$H$28:$H$151,MATCH($A22,'DATA INDUK'!$AL$28:$AL$151,0))) -> 26-001-DS-003 | C22: {=IF($A22="","", _xlfn.LET( _xlpm.Grp,INDEX('DATA INDUK'!$L$28:$L$151, MATCH($A22,'DATA INDUK'!$AL$28:$AL$151,0)), _xlpm.SID,INDEX('DATA INDUK'!$C$28:$C$151, MATCH($A22,'DATA INDUK'!$AL$28:$AL$151,0)), IF( _xlpm.Grp="", _xlpm.SID, _xlfn.TEXTJOIN(CHAR(10),TRUE, _xlfn._xlws.FILTER('DATA INDUK'!$C$28:$C$151, 'DATA INDUK'!$L$28:$L$151=_xlpm.Grp)) ) ))} -> BH-07-R-SPT-01 | E22: =IF($A22="","",INDEX('DATA INDUK'!$D$28:$D$151,MATCH($A22,'DATA INDUK'!$AL$28:$AL$151,0))) -> Disturbed Sample | F22: {=IF($A22="","", _xlfn.LET( _xlpm.Grp,INDEX('DATA INDUK'!$L$28:$L$151, MATCH($A22,'DATA INDUK'!$AL$28:$AL$151,0)), IF( _xlpm.Grp="", INDEX('DATA INDUK'!$I$28:$I$151, MATCH($A22,'DATA INDUK'!$AL$28:$AL$151,0)), _xlfn.TEXTJOIN(CHAR(10),TRUE, _xlfn._xlws.FILTER('DATA INDUK'!$I$28:$I$151, 'DATA INDUK'!$L$28:$L$151=_xlpm.Grp)) ) ))} -> 1.50 - 1.95 m | G22: ='[5]WS-PP'!$C$86 -> 2.6573968 | H22: ='[5]WS-PP'!$C$88 -> 38.942112 | I22: ='[5]WS-PP'!$C$90 -> 1.6873065 | J22: ='[5]WS-PP'!$C$92 -> 1.2143953 | K22: - | L22: - | M22: - | N22: =IF($A22="","", IF(OR($K22="",$M22=""),"", IF($K22="-","-", IF($K22="NP","NP - Non Plastic", IF(AND($K22<50,$M22>=0.73*($K22-20)),"CL - Lean Clay", IF(AND($K22>=50,$M22>=0.73*($K22-20)),"CH - Fat Clay", IF(AND($K22<50,$M22<0.73*($K22-20)),"ML - Silt", IF(AND($K22>=50,$M22<0.73*($K22-20)),"MH - Elastic Silt","")))))))) -> - | O22: - | P22: - | Q22: - | R22: - | T22: -
A23: =IFERROR(SMALL('DATA INDUK'!$AL$28:$AL$1151,ROWS($A$20:A23)),"") -> 4 | B23: =IF($A23="","",INDEX('DATA INDUK'!$H$28:$H$151,MATCH($A23,'DATA INDUK'!$AL$28:$AL$151,0))) -> 26-001-DS-004 | C23: {=IF($A23="","", _xlfn.LET( _xlpm.Grp,INDEX('DATA INDUK'!$L$28:$L$151, MATCH($A23,'DATA INDUK'!$AL$28:$AL$151,0)), _xlpm.SID,INDEX('DATA INDUK'!$C$28:$C$151, MATCH($A23,'DATA INDUK'!$AL$28:$AL$151,0)), IF( _xlpm.Grp="", _xlpm.SID, _xlfn.TEXTJOIN(CHAR(10),TRUE, _xlfn._xlws.FILTER('DATA INDUK'!$C$28:$C$151, 'DATA INDUK'!$L$28:$L$151=_xlpm.Grp)) ) ))} -> BH-07-R-SPT 03 | E23: =IF($A23="","",INDEX('DATA INDUK'!$D$28:$D$151,MATCH($A23,'DATA INDUK'!$AL$28:$AL$151,0))) -> Disturbed Sample | F23: {=IF($A23="","", _xlfn.LET( _xlpm.Grp,INDEX('DATA INDUK'!$L$28:$L$151, MATCH($A23,'DATA INDUK'!$AL$28:$AL$151,0)), IF( _xlpm.Grp="", INDEX('DATA INDUK'!$I$28:$I$151, MATCH($A23,'DATA INDUK'!$AL$28:$AL$151,0)), _xlfn.TEXTJOIN(CHAR(10),TRUE, _xlfn._xlws.FILTER('DATA INDUK'!$I$28:$I$151, 'DATA INDUK'!$L$28:$L$151=_xlpm.Grp)) ) ))} -> 4.50 - 4.95 m | G23: ='[2]WS-PP'!$H$66 -> 2.6645329 | H23: ='[2]WS-PP'!$H$67 -> 24.673539 | I23: ='[2]WS-PP'!$H$68 -> 1.6775585 | J23: ='[2]WS-PP'!$H$69 -> 1.3455609 | K23: - | L23: - | M23: - | N23: =IF($A23="","", IF(OR($K23="",$M23=""),"", IF($K23="-","-", IF($K23="NP","NP - Non Plastic", IF(AND($K23<50,$M23>=0.73*($K23-20)),"CL - Lean Clay", IF(AND($K23>=50,$M23>=0.73*($K23-20)),"CH - Fat Clay", IF(AND($K23<50,$M23<0.73*($K23-20)),"ML - Silt", IF(AND($K23>=50,$M23<0.73*($K23-20)),"MH - Elastic Silt","")))))))) -> - | O23: - | P23: - | Q23: - | R23: - | T23: -
A24: =IFERROR(SMALL('DATA INDUK'!$AL$28:$AL$1151,ROWS($A$20:A24)),"") -> 5 | B24: =IF($A24="","",INDEX('DATA INDUK'!$H$28:$H$151,MATCH($A24,'DATA INDUK'!$AL$28:$AL$151,0))) -> 26-001-DS-005 | C24: {=IF($A24="","", _xlfn.LET( _xlpm.Grp,INDEX('DATA INDUK'!$L$28:$L$151, MATCH($A24,'DATA INDUK'!$AL$28:$AL$151,0)), _xlpm.SID,INDEX('DATA INDUK'!$C$28:$C$151, MATCH($A24,'DATA INDUK'!$AL$28:$AL$151,0)), IF( _xlpm.Grp="", _xlpm.SID, _xlfn.TEXTJOIN(CHAR(10),TRUE, _xlfn._xlws.FILTER('DATA INDUK'!$C$28:$C$151, 'DATA INDUK'!$L$28:$L$151=_xlpm.Grp)) ) ))} -> BH-06-R2-SPT 01 | E24: =IF($A24="","",INDEX('DATA INDUK'!$D$28:$D$151,MATCH($A24,'DATA INDUK'!$AL$28:$AL$151,0))) -> Disturbed Sample | F24: {=IF($A24="","", _xlfn.LET( _xlpm.Grp,INDEX('DATA INDUK'!$L$28:$L$151, MATCH($A24,'DATA INDUK'!$AL$28:$AL$151,0)), IF( _xlpm.Grp="", INDEX('DATA INDUK'!$I$28:$I$151, MATCH($A24,'DATA INDUK'!$AL$28:$AL$151,0)), _xlfn.TEXTJOIN(CHAR(10),TRUE, _xlfn._xlws.FILTER('DATA INDUK'!$I$28:$I$151, 'DATA INDUK'!$L$28:$L$151=_xlpm.Grp)) ) ))} -> 1.50 - 1.95 m | G24: ='[6]WS-PP'!$C$86 -> 2.6746347 | H24: ='[6]WS-PP'!$C$88 -> 33.207683 | I24: ='[6]WS-PP'!$C$90 -> 1.692069 | J24: ='[6]WS-PP'!$C$92 -> 1.2702488 | K24: - | L24: - | M24: - | N24: =IF($A24="","", IF(OR($K24="",$M24=""),"", IF($K24="-","-", IF($K24="NP","NP - Non Plastic", IF(AND($K24<50,$M24>=0.73*($K24-20)),"CL - Lean Clay", IF(AND($K24>=50,$M24>=0.73*($K24-20)),"CH - Fat Clay", IF(AND($K24<50,$M24<0.73*($K24-20)),"ML - Silt", IF(AND($K24>=50,$M24<0.73*($K24-20)),"MH - Elastic Silt","")))))))) -> - | O24: - | P24: - | Q24: - | R24: - | T24: -
A25: =IFERROR(SMALL('DATA INDUK'!$AL$28:$AL$1151,ROWS($A$20:A25)),"") -> 6 | B25: =IF($A25="","",INDEX('DATA INDUK'!$H$28:$H$151,MATCH($A25,'DATA INDUK'!$AL$28:$AL$151,0))) -> 26-001-DS-006 | C25: {=IF($A25="","", _xlfn.LET( _xlpm.Grp,INDEX('DATA INDUK'!$L$28:$L$151, MATCH($A25,'DATA INDUK'!$AL$28:$AL$151,0)), _xlpm.SID,INDEX('DATA INDUK'!$C$28:$C$151, MATCH($A25,'DATA INDUK'!$AL$28:$AL$151,0)), IF( _xlpm.Grp="", _xlpm.SID, _xlfn.TEXTJOIN(CHAR(10),TRUE, _xlfn._xlws.FILTER('DATA INDUK'!$C$28:$C$151, 'DATA INDUK'!$L$28:$L$151=_xlpm.Grp)) ) ))} -> BH-06-R2-SPT 03 | E25: =IF($A25="","",INDEX('DATA INDUK'!$D$28:$D$151,MATCH($A25,'DATA INDUK'!$AL$28:$AL$151,0))) -> Disturbed Sample | F25: {=IF($A25="","", _xlfn.LET( _xlpm.Grp,INDEX('DATA INDUK'!$L$28:$L$151, MATCH($A25,'DATA INDUK'!$AL$28:$AL$151,0)), IF( _xlpm.Grp="", INDEX('DATA INDUK'!$I$28:$I$151, MATCH($A25,'DATA INDUK'!$AL$28:$AL$151,0)), _xlfn.TEXTJOIN(CHAR(10),TRUE, _xlfn._xlws.FILTER('DATA INDUK'!$I$28:$I$151, 'DATA INDUK'!$L$28:$L$151=_xlpm.Grp)) ) ))} -> 4.50 - 4.95 m | G25: ='[7]WS-PP'!$C$86 -> 2.6776332 | H25: ='[7]WS-PP'!$C$88 -> 26.28117 | I25: ='[7]WS-PP'!$C$90 -> 1.6647356 | J25: ='[7]WS-PP'!$C$92 -> 1.318277 | K25: ='[7]WS-ATB'!$C$163 -> 46.879858 | L25: ='[7]WS-ATB'!$C$165 -> 22.721893 | M25: ='[7]WS-ATB'!$C$167 -> 24.157965 | N25: =IF($A25="","", IF(OR($K25="",$M25=""),"", IF($K25="-","-", IF($K25="NP","NP - Non Plastic", IF(AND($K25<50,$M25>=0.73*($K25-20)),"CL - Lean Clay", IF(AND($K25>=50,$M25>=0.73*($K25-20)),"CH - Fat Clay", IF(AND($K25<50,$M25<0.73*($K25-20)),"ML - Silt", IF(AND($K25>=50,$M25<0.73*($K25-20)),"MH - Elastic Silt","")))))))) -> CL - Lean Clay | O25: ='[7]WS-Sieve dan hidrometer'!$C$136 -> 4.7990147 | P25: ='[7]WS-Sieve dan hidrometer'!$C$135 -> 26.394581 | Q25: ='[7]WS-Sieve dan hidrometer'!$C$134 -> 68.806404 | R25: ='[7]WS-Sieve dan hidrometer'!$C$133 -> 0 | T25: -
A26: =IFERROR(SMALL('DATA INDUK'!$AL$28:$AL$1151,ROWS($A$20:A26)),"") -> 7 | B26: =IF($A26="","",INDEX('DATA INDUK'!$H$28:$H$151,MATCH($A26,'DATA INDUK'!$AL$28:$AL$151,0))) -> 26-001-UDS-007 | C26: {=IF($A26="","", _xlfn.LET( _xlpm.Grp,INDEX('DATA INDUK'!$L$28:$L$151, MATCH($A26,'DATA INDUK'!$AL$28:$AL$151,0)), _xlpm.SID,INDEX('DATA INDUK'!$C$28:$C$151, MATCH($A26,'DATA INDUK'!$AL$28:$AL$151,0)), IF( _xlpm.Grp="", _xlpm.SID, _xlfn.TEXTJOIN(CHAR(10),TRUE, _xlfn._xlws.FILTER('DATA INDUK'!$C$28:$C$151, 'DATA INDUK'!$L$28:$L$151=_xlpm.Grp)) ) ))} -> BH-04R1-UDS 01 | E26: =IF($A26="","",INDEX('DATA INDUK'!$D$28:$D$151,MATCH($A26,'DATA INDUK'!$AL$28:$AL$151,0))) -> Undisturbed Sample | F26: {=IF($A26="","", _xlfn.LET( _xlpm.Grp,INDEX('DATA INDUK'!$L$28:$L$151, MATCH($A26,'DATA INDUK'!$AL$28:$AL$151,0)), IF( _xlpm.Grp="", INDEX('DATA INDUK'!$I$28:$I$151, MATCH($A26,'DATA INDUK'!$AL$28:$AL$151,0)), _xlfn.TEXTJOIN(CHAR(10),TRUE, _xlfn._xlws.FILTER('DATA INDUK'!$I$28:$I$151, 'DATA INDUK'!$L$28:$L$151=_xlpm.Grp)) ) ))} -> 10.00 - 10.15 m | G26: =[8]LHU_PP!$O$36 -> 2.6607959 | H26: =[8]LHU_PP!$O$37 -> 29.075334 | I26: =[8]LHU_PP!$O$38 -> 1.6829772 | J26: =[8]LHU_PP!$O$39 -> 1.3038721 | K26: - | L26: - | M26: - | N26: =IF($A26="","", IF(OR($K26="",$M26=""),"", IF($K26="-","-", IF($K26="NP","NP - Non Plastic", IF(AND($K26<50,$M26>=0.73*($K26-20)),"CL - Lean Clay", IF(AND($K26>=50,$M26>=0.73*($K26-20)),"CH - Fat Clay", IF(AND($K26<50,$M26<0.73*($K26-20)),"ML - Silt", IF(AND($K26>=50,$M26<0.73*($K26-20)),"MH - Elastic Silt","")))))))) -> - | O26: - | P26: - | Q26: - | R26: - | T26: -
A27: =IFERROR(SMALL('DATA INDUK'!$AL$28:$AL$1151,ROWS($A$20:A27)),"") -> 8 | B27: =IF($A27="","",INDEX('DATA INDUK'!$H$28:$H$151,MATCH($A27,'DATA INDUK'!$AL$28:$AL$151,0))) -> 26-001-UDS-008 | C27: {=IF($A27="","", _xlfn.LET( _xlpm.Grp,INDEX('DATA INDUK'!$L$28:$L$151, MATCH($A27,'DATA INDUK'!$AL$28:$AL$151,0)), _xlpm.SID,INDEX('DATA INDUK'!$C$28:$C$151, MATCH($A27,'DATA INDUK'!$AL$28:$AL$151,0)), IF( _xlpm.Grp="", _xlpm.SID, _xlfn.TEXTJOIN(CHAR(10),TRUE, _xlfn._xlws.FILTER('DATA INDUK'!$C$28:$C$151, 'DATA INDUK'!$L$28:$L$151=_xlpm.Grp)) ) ))} -> BH-05-R-UDS 01 | E27: =IF($A27="","",INDEX('DATA INDUK'!$D$28:$D$151,MATCH($A27,'DATA INDUK'!$AL$28:$AL$151,0))) -> Undisturbed Sample | F27: {=IF($A27="","", _xlfn.LET( _xlpm.Grp,INDEX('DATA INDUK'!$L$28:$L$151, MATCH($A27,'DATA INDUK'!$AL$28:$AL$151,0)), IF( _xlpm.Grp="", INDEX('DATA INDUK'!$I$28:$I$151, MATCH($A27,'DATA INDUK'!$AL$28:$AL$151,0)), _xlfn.TEXTJOIN(CHAR(10),TRUE, _xlfn._xlws.FILTER('DATA INDUK'!$I$28:$I$151, 'DATA INDUK'!$L$28:$L$151=_xlpm.Grp)) ) ))} -> 0.50 - 0.75 m | G27: - | H27: - | I27: - | J27: - | K27: - | L27: - | M27: - | N27: =IF($A27="","", IF(OR($K27="",$M27=""),"", IF($K27="-","-", IF($K27="NP","NP - Non Plastic", IF(AND($K27<50,$M27>=0.73*($K27-20)),"CL - Lean Clay", IF(AND($K27>=50,$M27>=0.73*($K27-20)),"CH - Fat Clay", IF(AND($K27<50,$M27<0.73*($K27-20)),"ML - Silt", IF(AND($K27>=50,$M27<0.73*($K27-20)),"MH - Elastic Silt","")))))))) -> - | O27: - | P27: - | Q27: - | R27: - | T27: -
A28: =IFERROR(SMALL('DATA INDUK'!$AL$28:$AL$1151,ROWS($A$20:A28)),"") -> 9 | B28: =IF($A28="","",INDEX('DATA INDUK'!$H$28:$H$151,MATCH($A28,'DATA INDUK'!$AL$28:$AL$151,0))) -> 26-001-UDS-009 | C28: {=IF($A28="","", _xlfn.LET( _xlpm.Grp,INDEX('DATA INDUK'!$L$28:$L$151, MATCH($A28,'DATA INDUK'!$AL$28:$AL$151,0)), _xlpm.SID,INDEX('DATA INDUK'!$C$28:$C$151, MATCH($A28,'DATA INDUK'!$AL$28:$AL$151,0)), IF( _xlpm.Grp="", _xlpm.SID, _xlfn.TEXTJOIN(CHAR(10),TRUE, _xlfn._xlws.FILTER('DATA INDUK'!$C$28:$C$151, 'DATA INDUK'!$L$28:$L$151=_xlpm.Grp)) ) ))} -> BH-03-R-UDS 01 | E28: =IF($A28="","",INDEX('DATA INDUK'!$D$28:$D$151,MATCH($A28,'DATA INDUK'!$AL$28:$AL$151,0))) -> Undisturbed Sample | F28: {=IF($A28="","", _xlfn.LET( _xlpm.Grp,INDEX('DATA INDUK'!$L$28:$L$151, MATCH($A28,'DATA INDUK'!$AL$28:$AL$151,0)), IF( _xlpm.Grp="", INDEX('DATA INDUK'!$I$28:$I$151, MATCH($A28,'DATA INDUK'!$AL$28:$AL$151,0)), _xlfn.TEXTJOIN(CHAR(10),TRUE, _xlfn._xlws.FILTER('DATA INDUK'!$I$28:$I$151, 'DATA INDUK'!$L$28:$L$151=_xlpm.Grp)) ) ))} -> 4.00 - 4.34 m | G28: - | H28: - | I28: - | J28: - | K28: - | L28: - | M28: - | N28: =IF($A28="","", IF(OR($K28="",$M28=""),"", IF($K28="-","-", IF($K28="NP","NP - Non Plastic", IF(AND($K28<50,$M28>=0.73*($K28-20)),"CL - Lean Clay", IF(AND($K28>=50,$M28>=0.73*($K28-20)),"CH - Fat Clay", IF(AND($K28<50,$M28<0.73*($K28-20)),"ML - Silt", IF(AND($K28>=50,$M28<0.73*($K28-20)),"MH - Elastic Silt","")))))))) -> - | O28: - | P28: - | Q28: - | R28: - | T28: -
A29: =IFERROR(SMALL('DATA INDUK'!$AL$28:$AL$1151,ROWS($A$20:A29)),"") -> 10 | B29: =IF($A29="","",INDEX('DATA INDUK'!$H$28:$H$151,MATCH($A29,'DATA INDUK'!$AL$28:$AL$151,0))) -> 26-001-UDS-010 | C29: {=IF($A29="","", _xlfn.LET( _xlpm.Grp,INDEX('DATA INDUK'!$L$28:$L$151, MATCH($A29,'DATA INDUK'!$AL$28:$AL$151,0)), _xlpm.SID,INDEX('DATA INDUK'!$C$28:$C$151, MATCH($A29,'DATA INDUK'!$AL$28:$AL$151,0)), IF( _xlpm.Grp="", _xlpm.SID, _xlfn.TEXTJOIN(CHAR(10),TRUE, _xlfn._xlws.FILTER('DATA INDUK'!$C$28:$C$151, 'DATA INDUK'!$L$28:$L$151=_xlpm.Grp)) ) ))} -> BH-03-R-UDS 04 | E29: =IF($A29="","",INDEX('DATA INDUK'!$D$28:$D$151,MATCH($A29,'DATA INDUK'!$AL$28:$AL$151,0))) -> Undisturbed Sample | F29: {=IF($A29="","", _xlfn.LET( _xlpm.Grp,INDEX('DATA INDUK'!$L$28:$L$151, MATCH($A29,'DATA INDUK'!$AL$28:$AL$151,0)), IF( _xlpm.Grp="", INDEX('DATA INDUK'!$I$28:$I$151, MATCH($A29,'DATA INDUK'!$AL$28:$AL$151,0)), _xlfn.TEXTJOIN(CHAR(10),TRUE, _xlfn._xlws.FILTER('DATA INDUK'!$I$28:$I$151, 'DATA INDUK'!$L$28:$L$151=_xlpm.Grp)) ) ))} -> 8.50 - 9.00 m | G29: - | H29: - | I29: - | J29: - | K29: - | L29: - | M29: - | N29: =IF($A29="","", IF(OR($K29="",$M29=""),"", IF($K29="-","-", IF($K29="NP","NP - Non Plastic", IF(AND($K29<50,$M29>=0.73*($K29-20)),"CL - Lean Clay", IF(AND($K29>=50,$M29>=0.73*($K29-20)),"CH - Fat Clay", IF(AND($K29<50,$M29<0.73*($K29-20)),"ML - Silt", IF(AND($K29>=50,$M29<0.73*($K29-20)),"MH - Elastic Silt","")))))))) -> - | O29: - | P29: - | Q29: - | R29: - | T29: -
A30: =IFERROR(SMALL('DATA INDUK'!$AL$28:$AL$1151,ROWS($A$20:A30)),"") -> 11 | B30: =IF($A30="","",INDEX('DATA INDUK'!$H$28:$H$151,MATCH($A30,'DATA INDUK'!$AL$28:$AL$151,0))) -> 26-001-UDS-011 | C30: {=IF($A30="","", _xlfn.LET( _xlpm.Grp,INDEX('DATA INDUK'!$L$28:$L$151, MATCH($A30,'DATA INDUK'!$AL$28:$AL$151,0)), _xlpm.SID,INDEX('DATA INDUK'!$C$28:$C$151, MATCH($A30,'DATA INDUK'!$AL$28:$AL$151,0)), IF( _xlpm.Grp="", _xlpm.SID, _xlfn.TEXTJOIN(CHAR(10),TRUE, _xlfn._xlws.FILTER('DATA INDUK'!$C$28:$C$151, 'DATA INDUK'!$L$28:$L$151=_xlpm.Grp)) ) ))} -> BH-07-R-UDS 01 | E30: =IF($A30="","",INDEX('DATA INDUK'!$D$28:$D$151,MATCH($A30,'DATA INDUK'!$AL$28:$AL$151,0))) -> Undisturbed Sample | F30: {=IF($A30="","", _xlfn.LET( _xlpm.Grp,INDEX('DATA INDUK'!$L$28:$L$151, MATCH($A30,'DATA INDUK'!$AL$28:$AL$151,0)), IF( _xlpm.Grp="", INDEX('DATA INDUK'!$I$28:$I$151, MATCH($A30,'DATA INDUK'!$AL$28:$AL$151,0)), _xlfn.TEXTJOIN(CHAR(10),TRUE, _xlfn._xlws.FILTER('DATA INDUK'!$I$28:$I$151, 'DATA INDUK'!$L$28:$L$151=_xlpm.Grp)) ) ))} -> 1.00 - 1.50 m | G30: - | H30: - | I30: - | J30: - | K30: - | L30: - | M30: - | N30: =IF($A30="","", IF(OR($K30="",$M30=""),"", IF($K30="-","-", IF($K30="NP","NP - Non Plastic", IF(AND($K30<50,$M30>=0.73*($K30-20)),"CL - Lean Clay", IF(AND($K30>=50,$M30>=0.73*($K30-20)),"CH - Fat Clay", IF(AND($K30<50,$M30<0.73*($K30-20)),"ML - Silt", IF(AND($K30>=50,$M30<0.73*($K30-20)),"MH - Elastic Silt","")))))))) -> - | O30: - | P30: - | Q30: - | R30: - | T30: -
A31: =IFERROR(SMALL('DATA INDUK'!$AL$28:$AL$1151,ROWS($A$20:A31)),"") -> 12 | B31: =IF($A31="","",INDEX('DATA INDUK'!$H$28:$H$151,MATCH($A31,'DATA INDUK'!$AL$28:$AL$151,0))) -> 26-001-UDS-012 | C31: {=IF($A31="","", _xlfn.LET( _xlpm.Grp,INDEX('DATA INDUK'!$L$28:$L$151, MATCH($A31,'DATA INDUK'!$AL$28:$AL$151,0)), _xlpm.SID,INDEX('DATA INDUK'!$C$28:$C$151, MATCH($A31,'DATA INDUK'!$AL$28:$AL$151,0)), IF( _xlpm.Grp="", _xlpm.SID, _xlfn.TEXTJOIN(CHAR(10),TRUE, _xlfn._xlws.FILTER('DATA INDUK'!$C$28:$C$151, 'DATA INDUK'!$L$28:$L$151=_xlpm.Grp)) ) ))} -> BH-06-R2-UDS 01 | E31: =IF($A31="","",INDEX('DATA INDUK'!$D$28:$D$151,MATCH($A31,'DATA INDUK'!$AL$28:$AL$151,0))) -> Undisturbed Sample | F31: {=IF($A31="","", _xlfn.LET( _xlpm.Grp,INDEX('DATA INDUK'!$L$28:$L$151, MATCH($A31,'DATA INDUK'!$AL$28:$AL$151,0)), IF( _xlpm.Grp="", INDEX('DATA INDUK'!$I$28:$I$151, MATCH($A31,'DATA INDUK'!$AL$28:$AL$151,0)), _xlfn.TEXTJOIN(CHAR(10),TRUE, _xlfn._xlws.FILTER('DATA INDUK'!$I$28:$I$151, 'DATA INDUK'!$L$28:$L$151=_xlpm.Grp)) ) ))} -> 2.50 - 3.00 m | G31: - | H31: - | I31: - | J31: - | K31: - | L31: - | M31: - | N31: =IF($A31="","", IF(OR($K31="",$M31=""),"", IF($K31="-","-", IF($K31="NP","NP - Non Plastic", IF(AND($K31<50,$M31>=0.73*($K31-20)),"CL - Lean Clay", IF(AND($K31>=50,$M31>=0.73*($K31-20)),"CH - Fat Clay", IF(AND($K31<50,$M31<0.73*($K31-20)),"ML - Silt", IF(AND($K31>=50,$M31<0.73*($K31-20)),"MH - Elastic Silt","")))))))) -> - | O31: - | P31: - | Q31: - | R31: - | T31: -
A32: =IFERROR(SMALL('DATA INDUK'!$AL$28:$AL$1151,ROWS($A$20:A32)),"") -> 13 | B32: =IF($A32="","",INDEX('DATA INDUK'!$H$28:$H$151,MATCH($A32,'DATA INDUK'!$AL$28:$AL$151,0))) -> 26-001-UDS-013 | C32: {=IF($A32="","", _xlfn.LET( _xlpm.Grp,INDEX('DATA INDUK'!$L$28:$L$151, MATCH($A32,'DATA INDUK'!$AL$28:$AL$151,0)), _xlpm.SID,INDEX('DATA INDUK'!$C$28:$C$151, MATCH($A32,'DATA INDUK'!$AL$28:$AL$151,0)), IF( _xlpm.Grp="", _xlpm.SID, _xlfn.TEXTJOIN(CHAR(10),TRUE, _xlfn._xlws.FILTER('DATA INDUK'!$C$28:$C$151, 'DATA INDUK'!$L$28:$L$151=_xlpm.Grp)) ) ))} -> BH-06-R2-UDS 02 | E32: =IF($A32="","",INDEX('DATA INDUK'!$D$28:$D$151,MATCH($A32,'DATA INDUK'!$AL$28:$AL$151,0))) -> Undisturbed Sample | F32: {=IF($A32="","", _xlfn.LET( _xlpm.Grp,INDEX('DATA INDUK'!$L$28:$L$151, MATCH($A32,'DATA INDUK'!$AL$28:$AL$151,0)), IF( _xlpm.Grp="", INDEX('DATA INDUK'!$I$28:$I$151, MATCH($A32,'DATA INDUK'!$AL$28:$AL$151,0)), _xlfn.TEXTJOIN(CHAR(10),TRUE, _xlfn._xlws.FILTER('DATA INDUK'!$I$28:$I$151, 'DATA INDUK'!$L$28:$L$151=_xlpm.Grp)) ) ))} -> 4.00 - 4.50 m | G32: - | H32: - | I32: - | J32: - | K32: - | L32: - | M32: - | N32: =IF($A32="","", IF(OR($K32="",$M32=""),"", IF($K32="-","-", IF($K32="NP","NP - Non Plastic", IF(AND($K32<50,$M32>=0.73*($K32-20)),"CL - Lean Clay", IF(AND($K32>=50,$M32>=0.73*($K32-20)),"CH - Fat Clay", IF(AND($K32<50,$M32<0.73*($K32-20)),"ML - Silt", IF(AND($K32>=50,$M32<0.73*($K32-20)),"MH - Elastic Silt","")))))))) -> - | O32: - | P32: - | Q32: - | R32: - | T32: -
A33: =IFERROR(SMALL('DATA INDUK'!$AL$28:$AL$1151,ROWS($A$20:A33)),"") -> 14 | B33: =IF($A33="","",INDEX('DATA INDUK'!$H$28:$H$151,MATCH($A33,'DATA INDUK'!$AL$28:$AL$151,0))) -> 26-001-DS-014 | C33: {=IF($A33="","", _xlfn.LET( _xlpm.Grp,INDEX('DATA INDUK'!$L$28:$L$151, MATCH($A33,'DATA INDUK'!$AL$28:$AL$151,0)), _xlpm.SID,INDEX('DATA INDUK'!$C$28:$C$151, MATCH($A33,'DATA INDUK'!$AL$28:$AL$151,0)), IF( _xlpm.Grp="", _xlpm.SID, _xlfn.TEXTJOIN(CHAR(10),TRUE, _xlfn._xlws.FILTER('DATA INDUK'!$C$28:$C$151, 'DATA INDUK'!$L$28:$L$151=_xlpm.Grp)) ) ))} -> BH-04R1-DS 01 | E33: =IF($A33="","",INDEX('DATA INDUK'!$D$28:$D$151,MATCH($A33,'DATA INDUK'!$AL$28:$AL$151,0))) -> Disturbed Sample | F33: {=IF($A33="","", _xlfn.LET( _xlpm.Grp,INDEX('DATA INDUK'!$L$28:$L$151, MATCH($A33,'DATA INDUK'!$AL$28:$AL$151,0)), IF( _xlpm.Grp="", INDEX('DATA INDUK'!$I$28:$I$151, MATCH($A33,'DATA INDUK'!$AL$28:$AL$151,0)), _xlfn.TEXTJOIN(CHAR(10),TRUE, _xlfn._xlws.FILTER('DATA INDUK'!$I$28:$I$151, 'DATA INDUK'!$L$28:$L$151=_xlpm.Grp)) ) ))} -> 19.95 - 20.30 m | G33: - | H33: - | I33: - | J33: - | K33: - | L33: - | M33: - | N33: =IF($A33="","", IF(OR($K33="",$M33=""),"", IF($K33="-","-", IF($K33="NP","NP - Non Plastic", IF(AND($K33<50,$M33>=0.73*($K33-20)),"CL - Lean Clay", IF(AND($K33>=50,$M33>=0.73*($K33-20)),"CH - Fat Clay", IF(AND($K33<50,$M33<0.73*($K33-20)),"ML - Silt", IF(AND($K33>=50,$M33<0.73*($K33-20)),"MH - Elastic Silt","")))))))) -> - | O33: - | P33: - | Q33: - | R33: - | T33: -
A34: =IFERROR(SMALL('DATA INDUK'!$AL$28:$AL$1151,ROWS($A$20:A34)),"") -> 15 | B34: =IF($A34="","",INDEX('DATA INDUK'!$H$28:$H$151,MATCH($A34,'DATA INDUK'!$AL$28:$AL$151,0))) -> 26-001-DS-015 | C34: {=IF($A34="","", _xlfn.LET( _xlpm.Grp,INDEX('DATA INDUK'!$L$28:$L$151, MATCH($A34,'DATA INDUK'!$AL$28:$AL$151,0)), _xlpm.SID,INDEX('DATA INDUK'!$C$28:$C$151, MATCH($A34,'DATA INDUK'!$AL$28:$AL$151,0)), IF( _xlpm.Grp="", _xlpm.SID, _xlfn.TEXTJOIN(CHAR(10),TRUE, _xlfn._xlws.FILTER('DATA INDUK'!$C$28:$C$151, 'DATA INDUK'!$L$28:$L$151=_xlpm.Grp)) ) ))} -> BH-04R1-DS 04 | E34: =IF($A34="","",INDEX('DATA INDUK'!$D$28:$D$151,MATCH($A34,'DATA INDUK'!$AL$28:$AL$151,0))) -> Disturbed Sample | F34: {=IF($A34="","", _xlfn.LET( _xlpm.Grp,INDEX('DATA INDUK'!$L$28:$L$151, MATCH($A34,'DATA INDUK'!$AL$28:$AL$151,0)), IF( _xlpm.Grp="", INDEX('DATA INDUK'!$I$28:$I$151, MATCH($A34,'DATA INDUK'!$AL$28:$AL$151,0)), _xlfn.TEXTJOIN(CHAR(10),TRUE, _xlfn._xlws.FILTER('DATA INDUK'!$I$28:$I$151, 'DATA INDUK'!$L$28:$L$151=_xlpm.Grp)) ) ))} -> 25.23 - 25.43 m | G34: - | H34: - | I34: - | J34: - | K34: - | L34: - | M34: - | N34: =IF($A34="","", IF(OR($K34="",$M34=""),"", IF($K34="-","-", IF($K34="NP","NP - Non Plastic", IF(AND($K34<50,$M34>=0.73*($K34-20)),"CL - Lean Clay", IF(AND($K34>=50,$M34>=0.73*($K34-20)),"CH - Fat Clay", IF(AND($K34<50,$M34<0.73*($K34-20)),"ML - Silt", IF(AND($K34>=50,$M34<0.73*($K34-20)),"MH - Elastic Silt","")))))))) -> - | O34: - | P34: - | Q34: - | R34: - | T34: -
A35: =IFERROR(SMALL('DATA INDUK'!$AL$28:$AL$1151,ROWS($A$20:A35)),"") -> 16 | B35: =IF($A35="","",INDEX('DATA INDUK'!$H$28:$H$151,MATCH($A35,'DATA INDUK'!$AL$28:$AL$151,0))) -> 26-001-DS-016 | C35: {=IF($A35="","", _xlfn.LET( _xlpm.Grp,INDEX('DATA INDUK'!$L$28:$L$151, MATCH($A35,'DATA INDUK'!$AL$28:$AL$151,0)), _xlpm.SID,INDEX('DATA INDUK'!$C$28:$C$151, MATCH($A35,'DATA INDUK'!$AL$28:$AL$151,0)), IF( _xlpm.Grp="", _xlpm.SID, _xlfn.TEXTJOIN(CHAR(10),TRUE, _xlfn._xlws.FILTER('DATA INDUK'!$C$28:$C$151, 'DATA INDUK'!$L$28:$L$151=_xlpm.Grp)) ) ))} -> BH-05-R-DS 01 | E35: =IF($A35="","",INDEX('DATA INDUK'!$D$28:$D$151,MATCH($A35,'DATA INDUK'!$AL$28:$AL$151,0))) -> Disturbed Sample | F35: {=IF($A35="","", _xlfn.LET( _xlpm.Grp,INDEX('DATA INDUK'!$L$28:$L$151, MATCH($A35,'DATA INDUK'!$AL$28:$AL$151,0)), IF( _xlpm.Grp="", INDEX('DATA INDUK'!$I$28:$I$151, MATCH($A35,'DATA INDUK'!$AL$28:$AL$151,0)), _xlfn.TEXTJOIN(CHAR(10),TRUE, _xlfn._xlws.FILTER('DATA INDUK'!$I$28:$I$151, 'DATA INDUK'!$L$28:$L$151=_xlpm.Grp)) ) ))} -> 3.92 - 4.15 m | G35: - | H35: - | I35: - | J35: - | K35: - | L35: - | M35: - | N35: =IF($A35="","", IF(OR($K35="",$M35=""),"", IF($K35="-","-", IF($K35="NP","NP - Non Plastic", IF(AND($K35<50,$M35>=0.73*($K35-20)),"CL - Lean Clay", IF(AND($K35>=50,$M35>=0.73*($K35-20)),"CH - Fat Clay", IF(AND($K35<50,$M35<0.73*($K35-20)),"ML - Silt", IF(AND($K35>=50,$M35<0.73*($K35-20)),"MH - Elastic Silt","")))))))) -> - | O35: - | P35: - | Q35: - | R35: - | T35: -
