Workbook
Name TTD_: TTD!$B$3:$C$8
Name TTD_1ATB: INDIRECT('WS-ATB'!$T$9)
Name TTD_1CBRS: INDIRECT('WS-CBRSoaked'!$T$9)
Name TTD_1CBRU: INDIRECT('WS-CBR unsoaked'!$T$9)
Name TTD_1CDR: INDIRECT('WS_CD Residual '!$T$9)
Name TTD_1CMPM: INDIRECT('WS-modified proctor'!$T$9)
Name TTD_1CMPS: INDIRECT('WS-standard Proctor'!$T$9)
Name TTD_1CON: INDIRECT('WS-Konsolidasi'!$T$9)
Name TTD_1DSCD: INDIRECT('WS_DS-CD'!$T$9)
Name TTD_1DSUU: INDIRECT('WS_DS-UU'!$T$9)
Name TTD_1PP: INDIRECT('WS-PP'!$Y$9)
Name TTD_1SH: INDIRECT('WS-Sieve dan hidrometer'!$T$9)
Name TTD_1TCUM: INDIRECT('WS-TRX-CU Multi'!$T$9)
Name TTD_1TCUN: INDIRECT('WS-TRX-CD'!$T$9)
Name TTD_1TCUN: INDIRECT('WS-TRX-CU Normal'!$T$9)
Name TTD_1TUU: INDIRECT('WS-TRX-UU'!$T$9)
Name TTD_1UCT: INDIRECT('WS-UCT'!$T$9)
Name TTD_2ATB: INDIRECT('WS-ATB'!$T$10)
Name TTD_2CBRS: INDIRECT('WS-CBRSoaked'!$T$10)
Name TTD_2CBRU: INDIRECT('WS-CBR unsoaked'!$T$10)
Name TTD_2CDR: INDIRECT('WS_CD Residual '!$T$10)
Name TTD_2CMPM: INDIRECT('WS-modified proctor'!$T$10)
Name TTD_2CMPS: INDIRECT('WS-standard Proctor'!$T$10)
Name TTD_2CON: INDIRECT('WS-Konsolidasi'!$T$10)
Name TTD_2DSCD: INDIRECT('WS_DS-CD'!$T$10)
Name TTD_2DSUU: INDIRECT('WS_DS-UU'!$T$10)
Name TTD_2PP: INDIRECT('WS-PP'!$Y$10)
Name TTD_2SH: INDIRECT('WS-Sieve dan hidrometer'!$T$10)
Name TTD_2TCUM: INDIRECT('WS-TRX-CU Multi'!$T$10)
Name TTD_2TCUN: INDIRECT('WS-TRX-CD'!$T$10)
Name TTD_2TCUN: INDIRECT('WS-TRX-CU Normal'!$T$10)
Name TTD_2TUU: INDIRECT('WS-TRX-UU'!$T$10)
Name TTD_2UCT: INDIRECT('WS-UCT'!$T$10)
Name TTD_3ATB: INDIRECT('WS-ATB'!$T$11)
Name TTD_3CBRS: INDIRECT('WS-CBRSoaked'!$T$11)
Name TTD_3CBRU: INDIRECT('WS-CBR unsoaked'!$T$11)
Name TTD_3CDR: INDIRECT('WS_CD Residual '!$T$11)
Name TTD_3CMPM: INDIRECT('WS-modified proctor'!$T$11)
Name TTD_3CON: INDIRECT('WS-Konsolidasi'!$T$11)
Name TTD_3DSCD: INDIRECT('WS_DS-CD'!$T$11)
Name TTD_3DSUU: INDIRECT('WS_DS-UU'!$T$11)
Name TTD_3PP: INDIRECT('WS-PP'!$Y$11)
Name TTD_3SH: INDIRECT('WS-Sieve dan hidrometer'!$T$11)
Name TTD_3TCUM: INDIRECT('WS-TRX-CU Multi'!$T$11)
Name TTD_3TCUN: INDIRECT('WS-TRX-CD'!$T$11)
Name TTD_3TCUN: INDIRECT('WS-TRX-CU Normal'!$T$11)
Name TTD_3TUU: INDIRECT('WS-TRX-UU'!$T$11)
Name TTD_3UCT: INDIRECT('WS-UCT'!$T$11)
Name TTD_A.SUMARTADJI: TTD!$B$12:$E$18
Name TTD_CMPS: INDIRECT('WS-standard Proctor'!$T$11)
Name TTD_NOUFAL: TTD!$B$19:$D$25
Name TTD_RAFLY: TTD!$B$28:$D$33
Name TTD_RIZKI: TTD!$B$36:$D$42
Name X_UCS_Remoulded: OFFSET(#REF!,0,0,COUNT(#REF!),1)
Name X_UCS_Undisturbed: OFFSET(#REF!,0,0,COUNT(#REF!),1)
Name X_UU: OFFSET(#REF!,0,0,COUNT(#REF!),1)
Name X_UU_1kg: OFFSET(#REF!,0,0,COUNT(#REF!),1)
Name X_UU_2kg: OFFSET(#REF!,0,0,COUNT(#REF!),1)
Name Y_UCS_Remoulded: OFFSET(#REF!,0,0,COUNT(#REF!),1)
Name Y_UCS_Undisturbed: OFFSET(#REF!,0,0,COUNT(#REF!),1)

Sheet TTD
G14: A.SUMARTADJI
G20: M.NOUFAL
G30: RAFLY R.
G37: RIZKI W.

Sheet Template LHU
F1: LABORATORIUM MEKANIKA TANAH
F2: PT. MINEARTH GEO SOLUTION
F3: LABORATORY TEST REPORT
A6: No. Laporan / Report No. | E6: =": " & IF('DATA INDUK'!$H$17="","",'DATA INDUK'!$H$17) -> : 23/MGS/53/II/2026
A7: Revisi / Revision | E7: =": "&IF('DATA INDUK'!$H$18="","",'DATA INDUK'!$H$18) -> : R0 | J7: Tgl. Laporan / Report Date | M7: =": "&IF('DATA INDUK'!$H$19="","",TEXT('DATA INDUK'!$H$19,"dd mmmm yyyy")) -> : 29 January 2026 | T7: Halaman/Pages | W7: =": 1 dari x" -> : 1 dari x
A9: INFORMASI PROYEK /PROJECT INFORMATION | N9: INFORMASI CONTOH / SAMPLE INFORMATION
A11: Nama Proyek / Project Name | N11: Kode Laboratorium / Laboratory Id.
A12: =IF('DATA INDUK'!$H$2="","",'DATA INDUK'!$H$2) -> BSI Candrian Waste Dump Extension Study | N12: =IF('WS-PP'!D7="","",'WS-PP'!D7) -> 26-001-DS-001
A13: Lokasi Proyek / Location | E13: =": "&IF('DATA INDUK'!$H$3="","",'DATA INDUK'!$H$3) -> : Banyuwangi - JAWA TIMUR | N13: No. Contoh / Sample Id. | S13: =": "&IF('WS-PP'!D9="","",'WS-PP'!D9) -> #N/A
A14: No. PO / PO Number | E14: =": "&IF('DATA INDUK'!$H$9="","",'DATA INDUK'!$H$9) -> : PO-GQT-001 | N14: Kedalaman / Depth (m) | S14: =": "&IF('WS-PP'!D10="","",'WS-PP'!D10) -> #N/A
N15: Jenis Contoh / Sample Type | S15: =": "&IF('WS-PP'!D11="","",'WS-PP'!D11) -> : Disturbed Sample
A17: IDENTITAS KLIEN / CLIENT INFORMATION | N17: Deskripsi Tanah / Soil Description | S17: =": "&IF('WS-PP'!D12="","",'WS-PP'!D12) -> : Lempung / Clay
N18: Warna Tanah / Soil Color | S18: =": "&IF('WS-PP'!D13="","",'WS-PP'!D13) -> : Coklat Kekuningan / Yellowish Brown
A19: Klien / Client | E19: =": "&IF('DATA INDUK'!$H$4="","",'DATA INDUK'!$H$4) -> : PT. GEOLAND QUATRO TECHNOLAB
N20: Tgl.Diterima / Date Received | S20: =": "&IF('DATA INDUK'!H13="","",TEXT('DATA INDUK'!H13,"dd mmmm yyyy")) -> : 05 January 2026
A21: Alamat / Address | E21: =": "&IF('DATA INDUK'!$H$6="","",'DATA INDUK'!H6) -> : Kab. Bandung - JAWA BARAT
N22: Tgl Pengujian / Date Tested | S22: =": "&IF('WS-PP'!T12="","",TEXT('WS-PP'!T12,"dd mmmm yyyy")) -> : 05 January 2026
A26: ='WS-PP'!A2 -> UJI SIFAT FISIK TANAH | U26: SNI
A27: ='WS-PP'!A3 -> SOIL PHYSICAL PROPERTIES TEST
C60: DIUJI OLEH / | H60: DIPERIKSA OLEH / | M60: DISETUJUI OLEH /
C61: TESTED BY | H61: CHECKED BY | M61: APPROVED BY
C66: Teknisi/Analis | H66: Koordinator Teknis | M66: Kepala Laboratorium
C67: Tgl./Date : | E67: =IF($M$7="","",$M$7-1) -> #VALUE! | H67: Tgl./Date : | J67: =IF($M$7="","",$M$7-1) -> #VALUE! | M67: Tgl./Date : | P67: =IF($M$7="","",$M$7-1) -> #VALUE!
A69: KETERANGAN / NOTES | D69: - Laporan hasil Uji ini hanya berlaku untuk contoh yang diuji | M69: - | N69: This test report applies only to the tested sample.
D70: - Dilarang memperbanyak laporan tanpa ijin tertulis dari Laboratorium | M70: - | N70: This report shall not be reproduced except in full without written approval from
D71: Mekanika Tanah PT. MINEARTH GEO SOLUTION. | N71: PT. MINEARTH GEO SOLUTION Soil Mechanics Laboratory.
D72: - Laboratorium tidak bertanggung jawab atas kegiatan pengambilan | M72: - | N72: The laboratory is not responsible for sampling,handling and sample transportation
D73: dan transportasi contoh yang dilakukan oleh pihak lain. | N73: conducted by others.
T74: ='DATA INDUK'!$BT$44 -> 23-MINEARTH-RM-LHU-DS-CD-R0
A75: Jl. Leuwisari VII No.23, Kota Bandung | K75: Telp : 022-4572503,08112183223 | S75: Email : Soil_test@minearth.co.id
A76: Jawa Barat-40235 | K76: Mobile : 0811-2183-223 | S76: Website : www.minearth.co.id
F79: LABORATORIUM MEKANIKA TANAH
F80: PT. MINEARTH GEO SOLUTION
F81: LABORATORY TEST REPORT
A84: No. Laporan / Report No. | E84: =": " & IF('DATA INDUK'!$H$17="","",'DATA INDUK'!$H$17) -> : 23/MGS/53/II/2026
A85: Revisi / Revision | E85: =": "&IF('DATA INDUK'!$H$18="","",'DATA INDUK'!$H$18) -> : R0 | J85: Tgl. Laporan / Report Date | M85: =": "&IF('DATA INDUK'!$H$19="","",TEXT('DATA INDUK'!$H$19,"dd mmmm yyyy")) -> : 29 January 2026 | T85: Halaman/Pages | W85: =": 1 dari 2" -> : 1 dari 2
A87: LAMPIRAN / APPENDIX
A140: CATATAN /NOTES : | H140: DIUJI OLEH / | L140: DIPERIKSA OLEH / | P140: DISETUJUI OLEH /
H141: TESTED BY | L141: CHECKED BY | P141: APPROVED BY
H142: =C65 -> 0
...

Sheet DATA INDUK
B2: NAMA PROYEK / PROJECT ID | H2: BSI Candrian Waste Dump Extension Study
B3: LOKASI PROYEK | H3: Banyuwangi - JAWA TIMUR
B4: PEMILIK/KLIEN | H4: PT. GEOLAND QUATRO TECHNOLAB
B5: ALAMAT | F5: JL.
F6: KOTA-PROVINSI | H6: Kab. Bandung - JAWA BARAT
B7: PIC
B8: TLP
B9: NOMOR PO | H9: PO-GQT-001
B10: TGL PO
B11: NO. URUT PO | H11: 1
B12: TAHUN | H12: 2026
B13: TGL KEDATANGAN SAMPEL | H13: 46027
B14: NO. BA PENERIMAAN SAMPEL
B16: PELAPORAN
B17: NOMOR LAPORAN | H17: 23/MGS/53/II/2026
B18: REVISI | H18: R0
B19: TGL LAPORAN | H19: 46051
B21: JENIS PENGUJIAN /TEST PERFORMED
B22: NO. | C22: SAMPLE ID | D22: JENIS SAMPLE | E22: KODE SAMPEL | F22: HOLE ID | G22: SAMPEL No. | H22: LAB ID | I22: Group Composit | J22: DEPTH (m) | M22: FILE ID | N22: SPESIFIC GRAVITY | O22: MOISTURE CONTENT | P22: UNIT WEIGHT | Q22: ATTENBERG LIMIT | R22: SIEVE ANALYSIS | S22: SIEVE &HIDROMETER | T22: COMPACTION | V22: PERMEABILTY | W22: CONSOLIDATION | X22: UCT | Y22: DIRECT SHEAR | AD22: TRIAXIAL | AH22: CBR LAB. | AJ22: SHRINGKAGE LIMIT | AK22: SWELLING PRESSURE | AN22: SPESIFIC GRAVITY | AO22: MOISTURE CONTENT | AP22: UNIT WEIGHT | AQ22: ATTENBERG LIMIT | AR22: SIEVE ANALYSIS | AS22: SIEVE &HIDROMETER | AT22: COMPACTION | AV22: PERMEABILTY | AW22: CONSOLIDATION | AX22: UCT | AY22: DIRECT SHEAR | BD22: TRIAXIAL | BH22: CBR LAB. | BJ22: SHRINGKAGE LIMIT | BK22: SWELLING PRESSURE
J23: INTERVAL | K23: Depth fr. | L23: Depth to | T23: STD. PROCTOR | U23: MODIF. PROCTOR | Y23: DS-UU | Z23: DS-CU | AA23: DS - CD | AB23: DS - RESIDUAL | AC23: DS CD-RESIDUAL | AD23: TRIAXIAL UU | AE23: TRIAXIAL CU-M | AF23: TRIAXIAL CU-N | AG23: TRIAXIAL CD | AH23: CBR UNSOAKED | AI23: CBR-SOAKED | AT23: STD. PROCTOR | AU23: MODIF. PROCTOR | AY23: DS-UU | AZ23: DS-CU | BA23: DS - CD | BB23: DS - RESIDUAL | BC23: DS CD-RESIDUAL | BD23: TRIAXIAL UU | BE23: TRIAXIAL CU-M | BF23: TRIAXIAL CU-N | BG23: TRIAXIAL CD | BH23: CBR UNSOAKED | BI23: CBR-SOAKED
AB25: DS - RESIDUAL | BB25: DS - RESIDUAL | BQ25: No | BR25: J | BS25: SNI | BT25: KODE DOKUMEN
A27: DS | B27: 1 | C27: =CONCATENATE(F27,"-",G27) -> BH-04R1-SPT 15 | D27: =IF(E27="DS","Disturbed Sample", IF(E27="UDS","Undisturbed Sample", IF(E27="BS","Bulk Sample", IF(E27="CS","Composite Sample","")))) -> Disturbed Sample | E27: DS | F27: BH-04R1 | G27: SPT 15 | H27: =IF(OR($H$12="",$H$11="",E27="",B27=""),"",RIGHT($H$12,2)&"-"&TEXT($H$11,"000")&"-"&E27&"-"&TEXT(B27,"000")) -> 26-001-DS-001 | J27: =IF(AND(K27=0,L27=0), "-", TEXT(K27,"0.00")&" - "&TEXT(L27,"0.00")&" m") -> 22.50 - 22.95 m | K27: 22.5 | L27: 22.95 | M27: =TEXT(B27,"000")&"-"&C27&"-"&TEXT(K27,"0.00")&"-"&TEXT(L27,"0.00")&"m" -> 001-BH-04R1-SPT 15-22.50-22.95m | N27: 1 | O27: 1 | P27: 1 | Q27: 1 | R27: 1 | S27: 1 | T27: 1 | U27: 1 | V27: 1 | W27: 1 | X27: 1 | Y27: 1 | Z27: 1 | AA27: 1 | AB27: 1 | AC27: 1 | AD27: 1 | AE27: 1 | AF27: 1 | AG27: 1 | AH27: 1 | AI27: 1 | AJ27: 1 | AK27: 1 | AN27: =IF(N27=1,COUNTIF($N$27:N27,1),"") -> 1 | AO27: =IF(O27=1,COUNTIF($O$27:O27,1),"") -> 1 | AP27: =IF(P27=1,COUNTIF($P$27:P27,1),"") -> 1 | AQ27: =IF(Q27=1,COUNTIF($Q$27:Q27,1),"") -> 1 | AR27: =IF(R27=1,COUNTIF($R$27:R27,1),"") -> 1 | AS27: =IF(S27=1,COUNTIF($S$27:S27,1),"") -> 1 | AT27: =IF(T27=1,COUNTIF($T$27:T27,1),"") -> 1 | AU27: =IF(U27=1,COUNTIF($U$27:U27,1),"") -> 1 | AV27: =IF(V27=1,COUNTIF($V$27:V27,1),"") -> 1 | AW27: =IF(W27=1,COUNTIF($W$27:W27,1),"") -> 1 | AX27: =IF(X27=1,COUNTIF($X$27:X27,1),"") -> 1 | AY27: =IF(Y27=1,COUNTIF($Y$27:Y27,1),"") -> 1 | AZ27: =IF(Z27=1,COUNTIF($Z$27:Z27,1),"") -> 1 | BA27: =IF(AA27=1,COUNTIF($AA$27:AA27,1),"") -> 1 | BB27: =IF(AB27=1,COUNTIF($AB$27:AB27,1),"") -> 1 | BC27: =IF(AC27=1,COUNTIF($AC$27:AC27,1),"") -> 1 | BD27: =IF(AD27=1,COUNTIF($AD$27:AD27,1),"") -> 1 | BE27: =IF(AE27=1,COUNTIF($AE$27:AE27,1),"") -> 1 | BF27: =IF(AF27=1,COUNTIF($AF$27:AF27,1),"") -> 1 | BG27: =IF(AG27=1,COUNTIF($AG$27:AG27,1),"") -> 1 | BH27: =IF(AH27=1,COUNTIF($AH$27:AH27,1),"") -> 1 | BI27: =IF(AI27=1,COUNTIF($AI$27:AI27,1),"") -> 1 | BJ27: =IF(AJ27=1,COUNTIF($AJ$27:AJ27,1),"") -> 1 | BK27: =IF(AK27=1,COUNTIF($AK$27:AK27,1),"") -> 1 | BQ27: 1 | BR27: Sieve analysis & Hydrometer | BS27: 3423:2008 | BT27: 23-MINEARTH-RM-LHU-SH-R0
A28: UDS | B28: =B27+1 -> 2 | C28: =CONCATENATE(F28,"-",G28) -> BH-03-R-SPT 01 | D28: =IF(E28="DS","Disturbed Sample", IF(E28="UDS","Undisturbed Sample", IF(E28="BS","Bulk Sample", IF(E28="CS","Composite Sample","")))) -> Disturbed Sample | E28: DS | F28: BH-03-R | G28: SPT 01 | H28: =IF(OR($H$12="",$H$11="",E28="",B28=""),"",RIGHT($H$12,2)&"-"&TEXT($H$11,"000")&"-"&E28&"-"&TEXT(B28,"000")) -> 26-001-DS-002 | J28: =IF(AND(K28=0,L28=0), "-", TEXT(K28,"0.00")&" - "&TEXT(L28,"0.00")&" m") -> 1.50 - 1.95 m | K28: 1.5 | L28: 1.95 | M28: =TEXT(B28,"000")&"-"&C28&"-"&TEXT(K28,"0.00")&"-"&TEXT(L28,"0.00")&"m" -> 002-BH-03-R-SPT 01-1.50-1.95m | AN28: =IF(N28=1,COUNTIF($N$27:N28,1),"") | AO28: =IF(O28=1,COUNTIF($O$27:O28,1),"") | AP28: =IF(P28=1,COUNTIF($P$27:P28,1),"") | AQ28: =IF(Q28=1,COUNTIF($Q$27:Q28,1),"") | AR28: =IF(R28=1,COUNTIF($R$27:R28,1),"") | AS28: =IF(S28=1,COUNTIF($S$27:S28,1),"") | AT28: =IF(T28=1,COUNTIF($T$27:T28,1),"") | AU28: =IF(U28=1,COUNTIF($U$27:U28,1),"") | AV28: =IF(V28=1,COUNTIF($V$27:V28,1),"") | AW28: =IF(W28=1,COUNTIF($W$27:W28,1),"") | AX28: =IF(X28=1,COUNTIF($X$27:X28,1),"") | AY28: =IF(Y28=1,COUNTIF($Y$27:Y28,1),"") | AZ28: =IF(Z28=1,COUNTIF($Z$27:Z28,1),"") | BA28: =IF(AA28=1,COUNTIF($AA$27:AA28,1),"") | BB28: =IF(AB28=1,COUNTIF($AB$27:AB28,1),"") | BC28: =IF(AC28=1,COUNTIF($AC$27:AC28,1),"") | BD28: =IF(AD28=1,COUNTIF($AD$27:AD28,1),"") | BE28: =IF(AE28=1,COUNTIF($AE$27:AE28,1),"") | BF28: =IF(AF28=1,COUNTIF($AF$27:AF28,1),"") | BG28: =IF(AG28=1,COUNTIF($AG$27:AG28,1),"") | BH28: =IF(AH28=1,COUNTIF($AH$27:AH28,1),"") | BI28: =IF(AI28=1,COUNTIF($AI$27:AI28,1),"") | BJ28: =IF(AJ28=1,COUNTIF($AJ$27:AJ28,1),"") | BK28: =IF(AK28=1,COUNTIF($AK$27:AK28,1),"") | BQ28: 2 | BR28: Analisi Ayakan | BS28: 3423:2008 | BT28: 23-MINEARTH-RM-LHU-AS-R0
A29: BS | B29: =B28+1 -> 3 | C29: =CONCATENATE(F29,"-",G29) -> BH-07-R-SPT-01 | D29: =IF(E29="DS","Disturbed Sample", IF(E29="UDS","Undisturbed Sample", IF(E29="BS","Bulk Sample", IF(E29="CS","Composite Sample","")))) -> Disturbed Sample | E29: DS | F29: BH-07-R | G29: SPT-01 | H29: =IF(OR($H$12="",$H$11="",E29="",B29=""),"",RIGHT($H$12,2)&"-"&TEXT($H$11,"000")&"-"&E29&"-"&TEXT(B29,"000")) -> 26-001-DS-003 | J29: =IF(AND(K29=0,L29=0), "-", TEXT(K29,"0.00")&" - "&TEXT(L29,"0.00")&" m") -> 1.50 - 1.95 m | K29: 1.5 | L29: 1.95 | M29: =TEXT(B29,"000")&"-"&C29&"-"&TEXT(K29,"0.00")&"-"&TEXT(L29,"0.00")&"m" -> 003-BH-07-R-SPT-01-1.50-1.95m | AN29: =IF(N29=1,COUNTIF($N$27:N29,1),"") | AO29: =IF(O29=1,COUNTIF($O$27:O29,1),"") | AP29: =IF(P29=1,COUNTIF($P$27:P29,1),"") | AQ29: =IF(Q29=1,COUNTIF($Q$27:Q29,1),"") | AR29: =IF(R29=1,COUNTIF($R$27:R29,1),"") | AS29: =IF(S29=1,COUNTIF($S$27:S29,1),"") | AT29: =IF(T29=1,COUNTIF($T$27:T29,1),"") | AU29: =IF(U29=1,COUNTIF($U$27:U29,1),"") | AV29: =IF(V29=1,COUNTIF($V$27:V29,1),"") | AW29: =IF(W29=1,COUNTIF($W$27:W29,1),"") | AX29: =IF(X29=1,COUNTIF($X$27:X29,1),"") | AY29: =IF(Y29=1,COUNTIF($Y$27:Y29,1),"") | AZ29: =IF(Z29=1,COUNTIF($Z$27:Z29,1),"") | BA29: =IF(AA29=1,COUNTIF($AA$27:AA29,1),"") | BB29: =IF(AB29=1,COUNTIF($AB$27:AB29,1),"") | BC29: =IF(AC29=1,COUNTIF($AC$27:AC29,1),"") | BD29: =IF(AD29=1,COUNTIF($AD$27:AD29,1),"") | BE29: =IF(AE29=1,COUNTIF($AE$27:AE29,1),"") | BF29: =IF(AF29=1,COUNTIF($AF$27:AF29,1),"") | BG29: =IF(AG29=1,COUNTIF($AG$27:AG29,1),"") | BH29: =IF(AH29=1,COUNTIF($AH$27:AH29,1),"") | BI29: =IF(AI29=1,COUNTIF($AI$27:AI29,1),"") | BJ29: =IF(AJ29=1,COUNTIF($AJ$27:AJ29,1),"") | BK29: =IF(AK29=1,COUNTIF($AK$27:AK29,1),"") | BQ29: 3 | BR29: Hidrometer | BS29: 3423:2008 | BT29: 23-MINEARTH-RM-LHU-HID-R0
A30: CS | B30: =B29+1 -> 4 | C30: =CONCATENATE(F30,"-",G30) -> BH-07-R-SPT 03 | D30: =IF(E30="DS","Disturbed Sample", IF(E30="UDS","Undisturbed Sample", IF(E30="BS","Bulk Sample", IF(E30="CS","Composite Sample","")))) -> Disturbed Sample | E30: DS | F30: BH-07-R | G30: SPT 03 | H30: =IF(OR($H$12="",$H$11="",E30="",B30=""),"",RIGHT($H$12,2)&"-"&TEXT($H$11,"000")&"-"&E30&"-"&TEXT(B30,"000")) -> 26-001-DS-004 | J30: =IF(AND(K30=0,L30=0), "-", TEXT(K30,"0.00")&" - "&TEXT(L30,"0.00")&" m") -> 4.50 - 4.95 m | K30: 4.5 | L30: 4.95 | M30: =TEXT(B30,"000")&"-"&C30&"-"&TEXT(K30,"0.00")&"-"&TEXT(L30,"0.00")&"m" -> 004-BH-07-R-SPT 03-4.50-4.95m | AN30: =IF(N30=1,COUNTIF($N$27:N30,1),"") | AO30: =IF(O30=1,COUNTIF($O$27:O30,1),"") | AP30: =IF(P30=1,COUNTIF($P$27:P30,1),"") | AQ30: =IF(Q30=1,COUNTIF($Q$27:Q30,1),"") | AR30: =IF(R30=1,COUNTIF($R$27:R30,1),"") | AS30: =IF(S30=1,COUNTIF($S$27:S30,1),"") | AT30: =IF(T30=1,COUNTIF($T$27:T30,1),"") | AU30: =IF(U30=1,COUNTIF($U$27:U30,1),"") | AV30: =IF(V30=1,COUNTIF($V$27:V30,1),"") | AW30: =IF(W30=1,COUNTIF($W$27:W30,1),"") | AX30: =IF(X30=1,COUNTIF($X$27:X30,1),"") | AY30: =IF(Y30=1,COUNTIF($Y$27:Y30,1),"") | AZ30: =IF(Z30=1,COUNTIF($Z$27:Z30,1),"") | BA30: =IF(AA30=1,COUNTIF($AA$27:AA30,1),"") | BB30: =IF(AB30=1,COUNTIF($AB$27:AB30,1),"") | BC30: =IF(AC30=1,COUNTIF($AC$27:AC30,1),"") | BD30: =IF(AD30=1,COUNTIF($AD$27:AD30,1),"") | BE30: =IF(AE30=1,COUNTIF($AE$27:AE30,1),"") | BF30: =IF(AF30=1,COUNTIF($AF$27:AF30,1),"") | BG30: =IF(AG30=1,COUNTIF($AG$27:AG30,1),"") | BH30: =IF(AH30=1,COUNTIF($AH$27:AH30,1),"") | BI30: =IF(AI30=1,COUNTIF($AI$27:AI30,1),"") | BJ30: =IF(AJ30=1,COUNTIF($AJ$27:AJ30,1),"") | BK30: =IF(AK30=1,COUNTIF($AK$27:AK30,1),"") | BQ30: 4 | BR30: Spesific gravity/Uji berat Jenis | BS30: 1964:2008 | BT30: 23-MINEARTH-RM-LHU-PP-R0
B31: =B30+1 -> 5 | C31: =CONCATENATE(F31,"-",G31) -> BH-06-R2-SPT 01 | D31: =IF(E31="DS","Disturbed Sample", IF(E31="UDS","Undisturbed Sample", IF(E31="BS","Bulk Sample", IF(E31="CS","Composite Sample","")))) -> Disturbed Sample | E31: DS | F31: BH-06-R2 | G31: SPT 01 | H31: =IF(OR($H$12="",$H$11="",E31="",B31=""),"",RIGHT($H$12,2)&"-"&TEXT($H$11,"000")&"-"&E31&"-"&TEXT(B31,"000")) -> 26-001-DS-005 | J31: =IF(AND(K31=0,L31=0), "-", TEXT(K31,"0.00")&" - "&TEXT(L31,"0.00")&" m") -> 1.50 - 1.95 m | K31: 1.5 | L31: 1.95 | M31: =TEXT(B31,"000")&"-"&C31&"-"&TEXT(K31,"0.00")&"-"&TEXT(L31,"0.00")&"m" -> 005-BH-06-R2-SPT 01-1.50-1.95m | AN31: =IF(N31=1,COUNTIF($N$27:N31,1),"") | AO31: =IF(O31=1,COUNTIF($O$27:O31,1),"") | AP31: =IF(P31=1,COUNTIF($P$27:P31,1),"") | AQ31: =IF(Q31=1,COUNTIF($Q$27:Q31,1),"") | AR31: =IF(R31=1,COUNTIF($R$27:R31,1),"") | AS31: =IF(S31=1,COUNTIF($S$27:S31,1),"") | AT31: =IF(T31=1,COUNTIF($T$27:T31,1),"") | AU31: =IF(U31=1,COUNTIF($U$27:U31,1),"") | AV31: =IF(V31=1,COUNTIF($V$27:V31,1),"") | AW31: =IF(W31=1,COUNTIF($W$27:W31,1),"") | AX31: =IF(X31=1,COUNTIF($X$27:X31,1),"") | AY31: =IF(Y31=1,COUNTIF($Y$27:Y31,1),"") | AZ31: =IF(Z31=1,COUNTIF($Z$27:Z31,1),"") | BA31: =IF(AA31=1,COUNTIF($AA$27:AA31,1),"") | BB31: =IF(AB31=1,COUNTIF($AB$27:AB31,1),"") | BC31: =IF(AC31=1,COUNTIF($AC$27:AC31,1),"") | BD31: =IF(AD31=1,COUNTIF($AD$27:AD31,1),"") | BE31: =IF(AE31=1,COUNTIF($AE$27:AE31,1),"") | BF31: =IF(AF31=1,COUNTIF($AF$27:AF31,1),"") | BG31: =IF(AG31=1,COUNTIF($AG$27:AG31,1),"") | BH31: =IF(AH31=1,COUNTIF($AH$27:AH31,1),"") | BI31: =IF(AI31=1,COUNTIF($AI$27:AI31,1),"") | BJ31: =IF(AJ31=1,COUNTIF($AJ$27:AJ31,1),"") | BK31: =IF(AK31=1,COUNTIF($AK$27:AK31,1),"") | BQ31: 5 | BR31: Moisture Content/Uji kadar air | BS31: 1965:2008
B32: =B31+1 -> 6 | C32: =CONCATENATE(F32,"-",G32) -> BH-06-R2-SPT 03 | D32: =IF(E32="DS","Disturbed Sample", IF(E32="UDS","Undisturbed Sample", IF(E32="BS","Bulk Sample", IF(E32="CS","Composite Sample","")))) -> Disturbed Sample | E32: DS | F32: BH-06-R2 | G32: SPT 03 | H32: =IF(OR($H$12="",$H$11="",E32="",B32=""),"",RIGHT($H$12,2)&"-"&TEXT($H$11,"000")&"-"&E32&"-"&TEXT(B32,"000")) -> 26-001-DS-006 | J32: =IF(AND(K32=0,L32=0), "-", TEXT(K32,"0.00")&" - "&TEXT(L32,"0.00")&" m") -> 4.50 - 4.95 m | K32: 4.5 | L32: 4.95 | M32: =TEXT(B32,"000")&"-"&C32&"-"&TEXT(K32,"0.00")&"-"&TEXT(L32,"0.00")&"m" -> 006-BH-06-R2-SPT 03-4.50-4.95m | AN32: =IF(N32=1,COUNTIF($N$27:N32,1),"") | AO32: =IF(O32=1,COUNTIF($O$27:O32,1),"") | AP32: =IF(P32=1,COUNTIF($P$27:P32,1),"") | AQ32: =IF(Q32=1,COUNTIF($Q$27:Q32,1),"") | AR32: =IF(R32=1,COUNTIF($R$27:R32,1),"") | AS32: =IF(S32=1,COUNTIF($S$27:S32,1),"") | AT32: =IF(T32=1,COUNTIF($T$27:T32,1),"") | AU32: =IF(U32=1,COUNTIF($U$27:U32,1),"") | AV32: =IF(V32=1,COUNTIF($V$27:V32,1),"") | AW32: =IF(W32=1,COUNTIF($W$27:W32,1),"") | AX32: =IF(X32=1,COUNTIF($X$27:X32,1),"") | AY32: =IF(Y32=1,COUNTIF($Y$27:Y32,1),"") | AZ32: =IF(Z32=1,COUNTIF($Z$27:Z32,1),"") | BA32: =IF(AA32=1,COUNTIF($AA$27:AA32,1),"") | BB32: =IF(AB32=1,COUNTIF($AB$27:AB32,1),"") | BC32: =IF(AC32=1,COUNTIF($AC$27:AC32,1),"") | BD32: =IF(AD32=1,COUNTIF($AD$27:AD32,1),"") | BE32: =IF(AE32=1,COUNTIF($AE$27:AE32,1),"") | BF32: =IF(AF32=1,COUNTIF($AF$27:AF32,1),"") | BG32: =IF(AG32=1,COUNTIF($AG$27:AG32,1),"") | BH32: =IF(AH32=1,COUNTIF($AH$27:AH32,1),"") | BI32: =IF(AI32=1,COUNTIF($AI$27:AI32,1),"") | BJ32: =IF(AJ32=1,COUNTIF($AJ$27:AJ32,1),"") | BK32: =IF(AK32=1,COUNTIF($AK$27:AK32,1),"") | BQ32: 6 | BR32: Atterberg Limit | BT32: 23-MINEARTH-RM-LHU-ATB-R0
B33: =B32+1 -> 7 | C33: =CONCATENATE(F33,"-",G33) -> BH-04R1-UDS 01 | D33: =IF(E33="DS","Disturbed Sample", IF(E33="UDS","Undisturbed Sample", IF(E33="BS","Bulk Sample", IF(E33="CS","Composite Sample","")))) -> Composite Sample | E33: CS | F33: BH-04R1 | G33: UDS 01 | H33: =IF(OR($H$12="",$H$11="",E33="",B33=""),"",RIGHT($H$12,2)&"-"&TEXT($H$11,"000")&"-"&E33&"-"&TEXT(B33,"000")) -> 26-001-CS-007 | I33: C-1 | J33: =IF(AND(K33=0,L33=0), "-", TEXT(K33,"0.00")&" - "&TEXT(L33,"0.00")&" m") -> 10.00 - 10.15 m | K33: 10 | L33: 10.15 | M33: =TEXT(B33,"000")&"-"&C33&"-"&TEXT(K33,"0.00")&"-"&TEXT(L33,"0.00")&"m" -> 007-BH-04R1-UDS 01-10.00-10.15m | AN33: =IF(N33=1,COUNTIF($N$27:N33,1),"") | AO33: =IF(O33=1,COUNTIF($O$27:O33,1),"") | AP33: =IF(P33=1,COUNTIF($P$27:P33,1),"") | AQ33: =IF(Q33=1,COUNTIF($Q$27:Q33,1),"") | AR33: =IF(R33=1,COUNTIF($R$27:R33,1),"") | AS33: =IF(S33=1,COUNTIF($S$27:S33,1),"") | AT33: =IF(T33=1,COUNTIF($T$27:T33,1),"") | AU33: =IF(U33=1,COUNTIF($U$27:U33,1),"") | AV33: =IF(V33=1,COUNTIF($V$27:V33,1),"") | AW33: =IF(W33=1,COUNTIF($W$27:W33,1),"") | AX33: =IF(X33=1,COUNTIF($X$27:X33,1),"") | AY33: =IF(Y33=1,COUNTIF($Y$27:Y33,1),"") | AZ33: =IF(Z33=1,COUNTIF($Z$27:Z33,1),"") | BA33: =IF(AA33=1,COUNTIF($AA$27:AA33,1),"") | BB33: =IF(AB33=1,COUNTIF($AB$27:AB33,1),"") | BC33: =IF(AC33=1,COUNTIF($AC$27:AC33,1),"") | BD33: =IF(AD33=1,COUNTIF($AD$27:AD33,1),"") | BE33: =IF(AE33=1,COUNTIF($AE$27:AE33,1),"") | BF33: =IF(AF33=1,COUNTIF($AF$27:AF33,1),"") | BG33: =IF(AG33=1,COUNTIF($AG$27:AG33,1),"") | BH33: =IF(AH33=1,COUNTIF($AH$27:AH33,1),"") | BI33: =IF(AI33=1,COUNTIF($AI$27:AI33,1),"") | BJ33: =IF(AJ33=1,COUNTIF($AJ$27:AJ33,1),"") | BK33: =IF(AK33=1,COUNTIF($AK$27:AK33,1),"") | BR33: - Uji Batas Plastis dan Indeks Plastisitas | BS33: 1966:2008
B34: =B33+1 -> 8 | C34: =CONCATENATE(F34,"-",G34) -> BH-05-R-UDS 01 | D34: =IF(E34="DS","Disturbed Sample", IF(E34="UDS","Undisturbed Sample", IF(E34="BS","Bulk Sample", IF(E34="CS","Composite Sample","")))) -> Composite Sample | E34: CS | F34: BH-05-R | G34: UDS 01 | H34: =IF(OR($H$12="",$H$11="",E34="",B34=""),"",RIGHT($H$12,2)&"-"&TEXT($H$11,"000")&"-"&E34&"-"&TEXT(B34,"000")) -> 26-001-CS-008 | I34: C-1 | J34: =IF(AND(K34=0,L34=0), "-", TEXT(K34,"0.00")&" - "&TEXT(L34,"0.00")&" m") -> 0.50 - 0.75 m | K34: 0.5 | L34: 0.75 | M34: =TEXT(B34,"000")&"-"&C34&"-"&TEXT(K34,"0.00")&"-"&TEXT(L34,"0.00")&"m" -> 008-BH-05-R-UDS 01-0.50-0.75m | AN34: =IF(N34=1,COUNTIF($N$27:N34,1),"") | AO34: =IF(O34=1,COUNTIF($O$27:O34,1),"") | AP34: =IF(P34=1,COUNTIF($P$27:P34,1),"") | AQ34: =IF(Q34=1,COUNTIF($Q$27:Q34,1),"") | AR34: =IF(R34=1,COUNTIF($R$27:R34,1),"") | AS34: =IF(S34=1,COUNTIF($S$27:S34,1),"") | AT34: =IF(T34=1,COUNTIF($T$27:T34,1),"") | AU34: =IF(U34=1,COUNTIF($U$27:U34,1),"") | AV34: =IF(V34=1,COUNTIF($V$27:V34,1),"") | AW34: =IF(W34=1,COUNTIF($W$27:W34,1),"") | AX34: =IF(X34=1,COUNTIF($X$27:X34,1),"") | AY34: =IF(Y34=1,COUNTIF($Y$27:Y34,1),"") | AZ34: =IF(Z34=1,COUNTIF($Z$27:Z34,1),"") | BA34: =IF(AA34=1,COUNTIF($AA$27:AA34,1),"") | BB34: =IF(AB34=1,COUNTIF($AB$27:AB34,1),"") | BC34: =IF(AC34=1,COUNTIF($AC$27:AC34,1),"") | BD34: =IF(AD34=1,COUNTIF($AD$27:AD34,1),"") | BE34: =IF(AE34=1,COUNTIF($AE$27:AE34,1),"") | BF34: =IF(AF34=1,COUNTIF($AF$27:AF34,1),"") | BG34: =IF(AG34=1,COUNTIF($AG$27:AG34,1),"") | BH34: =IF(AH34=1,COUNTIF($AH$27:AH34,1),"") | BI34: =IF(AI34=1,COUNTIF($AI$27:AI34,1),"") | BJ34: =IF(AJ34=1,COUNTIF($AJ$27:AJ34,1),"") | BK34: =IF(AK34=1,COUNTIF($AK$27:AK34,1),"") | BR34: - Uji Batas Batas Cair | BS34: 1967:2008
B35: =B34+1 -> 9 | C35: =CONCATENATE(F35,"-",G35) -> BH-03-R-UDS 01 | D35: =IF(E35="DS","Disturbed Sample", IF(E35="UDS","Undisturbed Sample", IF(E35="BS","Bulk Sample", IF(E35="CS","Composite Sample","")))) -> Composite Sample | E35: CS | F35: BH-03-R | G35: UDS 01 | H35: =IF(OR($H$12="",$H$11="",E35="",B35=""),"",RIGHT($H$12,2)&"-"&TEXT($H$11,"000")&"-"&E35&"-"&TEXT(B35,"000")) -> 26-001-CS-009 | I35: C-1 | J35: =IF(AND(K35=0,L35=0), "-", TEXT(K35,"0.00")&" - "&TEXT(L35,"0.00")&" m") -> 4.00 - 4.34 m | K35: 4 | L35: 4.34 | M35: =TEXT(B35,"000")&"-"&C35&"-"&TEXT(K35,"0.00")&"-"&TEXT(L35,"0.00")&"m" -> 009-BH-03-R-UDS 01-4.00-4.34m | AN35: =IF(N35=1,COUNTIF($N$27:N35,1),"") | AO35: =IF(O35=1,COUNTIF($O$27:O35,1),"") | AP35: =IF(P35=1,COUNTIF($P$27:P35,1),"") | AQ35: =IF(Q35=1,COUNTIF($Q$27:Q35,1),"") | AR35: =IF(R35=1,COUNTIF($R$27:R35,1),"") | AS35: =IF(S35=1,COUNTIF($S$27:S35,1),"") | AT35: =IF(T35=1,COUNTIF($T$27:T35,1),"") | AU35: =IF(U35=1,COUNTIF($U$27:U35,1),"") | AV35: =IF(V35=1,COUNTIF($V$27:V35,1),"") | AW35: =IF(W35=1,COUNTIF($W$27:W35,1),"") | AX35: =IF(X35=1,COUNTIF($X$27:X35,1),"") | AY35: =IF(Y35=1,COUNTIF($Y$27:Y35,1),"") | AZ35: =IF(Z35=1,COUNTIF($Z$27:Z35,1),"") | BA35: =IF(AA35=1,COUNTIF($AA$27:AA35,1),"") | BB35: =IF(AB35=1,COUNTIF($AB$27:AB35,1),"") | BC35: =IF(AC35=1,COUNTIF($AC$27:AC35,1),"") | BD35: =IF(AD35=1,COUNTIF($AD$27:AD35,1),"") | BE35: =IF(AE35=1,COUNTIF($AE$27:AE35,1),"") | BF35: =IF(AF35=1,COUNTIF($AF$27:AF35,1),"") | BG35: =IF(AG35=1,COUNTIF($AG$27:AG35,1),"") | BH35: =IF(AH35=1,COUNTIF($AH$27:AH35,1),"") | BI35: =IF(AI35=1,COUNTIF($AI$27:AI35,1),"") | BJ35: =IF(AJ35=1,COUNTIF($AJ$27:AJ35,1),"") | BK35: =IF(AK35=1,COUNTIF($AK$27:AK35,1),"") | BQ35: 7 | BR35: Unit Weight/Uji berat isi tanah | BS35: 03-3637-1994
B36: =B35+1 -> 10 | C36: =CONCATENATE(F36,"-",G36) -> BH-03-R-UDS 04 | D36: =IF(E36="DS","Disturbed Sample", IF(E36="UDS","Undisturbed Sample", IF(E36="BS","Bulk Sample", IF(E36="CS","Composite Sample","")))) -> Undisturbed Sample | E36: UDS | F36: BH-03-R | G36: UDS 04 | H36: =IF(OR($H$12="",$H$11="",E36="",B36=""),"",RIGHT($H$12,2)&"-"&TEXT($H$11,"000")&"-"&E36&"-"&TEXT(B36,"000")) -> 26-001-UDS-010 | J36: =IF(AND(K36=0,L36=0), "-", TEXT(K36,"0.00")&" - "&TEXT(L36,"0.00")&" m") -> 8.50 - 9.00 m | K36: 8.5 | L36: 9 | M36: =TEXT(B36,"000")&"-"&C36&"-"&TEXT(K36,"0.00")&"-"&TEXT(L36,"0.00")&"m" -> 010-BH-03-R-UDS 04-8.50-9.00m | AN36: =IF(N36=1,COUNTIF($N$27:N36,1),"") | AO36: =IF(O36=1,COUNTIF($O$27:O36,1),"") | AP36: =IF(P36=1,COUNTIF($P$27:P36,1),"") | AQ36: =IF(Q36=1,COUNTIF($Q$27:Q36,1),"") | AR36: =IF(R36=1,COUNTIF($R$27:R36,1),"") | AS36: =IF(S36=1,COUNTIF($S$27:S36,1),"") | AT36: =IF(T36=1,COUNTIF($T$27:T36,1),"") | AU36: =IF(U36=1,COUNTIF($U$27:U36,1),"") | AV36: =IF(V36=1,COUNTIF($V$27:V36,1),"") | AW36: =IF(W36=1,COUNTIF($W$27:W36,1),"") | AX36: =IF(X36=1,COUNTIF($X$27:X36,1),"") | AY36: =IF(Y36=1,COUNTIF($Y$27:Y36,1),"") | AZ36: =IF(Z36=1,COUNTIF($Z$27:Z36,1),"") | BA36: =IF(AA36=1,COUNTIF($AA$27:AA36,1),"") | BB36: =IF(AB36=1,COUNTIF($AB$27:AB36,1),"") | BC36: =IF(AC36=1,COUNTIF($AC$27:AC36,1),"") | BD36: =IF(AD36=1,COUNTIF($AD$27:AD36,1),"") | BE36: =IF(AE36=1,COUNTIF($AE$27:AE36,1),"") | BF36: =IF(AF36=1,COUNTIF($AF$27:AF36,1),"") | BG36: =IF(AG36=1,COUNTIF($AG$27:AG36,1),"") | BH36: =IF(AH36=1,COUNTIF($AH$27:AH36,1),"") | BI36: =IF(AI36=1,COUNTIF($AI$27:AI36,1),"") | BJ36: =IF(AJ36=1,COUNTIF($AJ$27:AJ36,1),"") | BK36: =IF(AK36=1,COUNTIF($AK$27:AK36,1),"") | BQ36: 8 | BR36: Uji Triaxial
B37: =B36+1 -> 11 | C37: =CONCATENATE(F37,"-",G37) -> BH-07-R-UDS 01 | D37: =IF(E37="DS","Disturbed Sample", IF(E37="UDS","Undisturbed Sample", IF(E37="BS","Bulk Sample", IF(E37="CS","Composite Sample","")))) -> Undisturbed Sample | E37: UDS | F37: BH-07-R | G37: UDS 01 | H37: =IF(OR($H$12="",$H$11="",E37="",B37=""),"",RIGHT($H$12,2)&"-"&TEXT($H$11,"000")&"-"&E37&"-"&TEXT(B37,"000")) -> 26-001-UDS-011 | J37: =IF(AND(K37=0,L37=0), "-", TEXT(K37,"0.00")&" - "&TEXT(L37,"0.00")&" m") -> 1.00 - 1.50 m | K37: 1 | L37: 1.5 | M37: =TEXT(B37,"000")&"-"&C37&"-"&TEXT(K37,"0.00")&"-"&TEXT(L37,"0.00")&"m" -> 011-BH-07-R-UDS 01-1.00-1.50m | AN37: =IF(N37=1,COUNTIF($N$27:N37,1),"") | AO37: =IF(O37=1,COUNTIF($O$27:O37,1),"") | AP37: =IF(P37=1,COUNTIF($P$27:P37,1),"") | AQ37: =IF(Q37=1,COUNTIF($Q$27:Q37,1),"") | AR37: =IF(R37=1,COUNTIF($R$27:R37,1),"") | AS37: =IF(S37=1,COUNTIF($S$27:S37,1),"") | AT37: =IF(T37=1,COUNTIF($T$27:T37,1),"") | AU37: =IF(U37=1,COUNTIF($U$27:U37,1),"") | AV37: =IF(V37=1,COUNTIF($V$27:V37,1),"") | AW37: =IF(W37=1,COUNTIF($W$27:W37,1),"") | AX37: =IF(X37=1,COUNTIF($X$27:X37,1),"") | AY37: =IF(Y37=1,COUNTIF($Y$27:Y37,1),"") | AZ37: =IF(Z37=1,COUNTIF($Z$27:Z37,1),"") | BA37: =IF(AA37=1,COUNTIF($AA$27:AA37,1),"") | BB37: =IF(AB37=1,COUNTIF($AB$27:AB37,1),"") | BC37: =IF(AC37=1,COUNTIF($AC$27:AC37,1),"") | BD37: =IF(AD37=1,COUNTIF($AD$27:AD37,1),"") | BE37: =IF(AE37=1,COUNTIF($AE$27:AE37,1),"") | BF37: =IF(AF37=1,COUNTIF($AF$27:AF37,1),"") | BG37: =IF(AG37=1,COUNTIF($AG$27:AG37,1),"") | BH37: =IF(AH37=1,COUNTIF($AH$27:AH37,1),"") | BI37: =IF(AI37=1,COUNTIF($AI$27:AI37,1),"") | BJ37: =IF(AJ37=1,COUNTIF($AJ$27:AJ37,1),"") | BK37: =IF(AK37=1,COUNTIF($AK$27:AK37,1),"") | BR37: - Triaxial UU | BS37: 4813:2015 | BT37: 23-MINEARTH-RM-LHU-TRX-UU-R0
B38: =B37+1 -> 12 | C38: =CONCATENATE(F38,"-",G38) -> BH-06-R2-UDS 01 | D38: =IF(E38="DS","Disturbed Sample", IF(E38="UDS","Undisturbed Sample", IF(E38="BS","Bulk Sample", IF(E38="CS","Composite Sample","")))) -> Undisturbed Sample | E38: UDS | F38: BH-06-R2 | G38: UDS 01 | H38: =IF(OR($H$12="",$H$11="",E38="",B38=""),"",RIGHT($H$12,2)&"-"&TEXT($H$11,"000")&"-"&E38&"-"&TEXT(B38,"000")) -> 26-001-UDS-012 | J38: =IF(AND(K38=0,L38=0), "-", TEXT(K38,"0.00")&" - "&TEXT(L38,"0.00")&" m") -> 2.50 - 3.00 m | K38: 2.5 | L38: 3 | M38: =TEXT(B38,"000")&"-"&C38&"-"&TEXT(K38,"0.00")&"-"&TEXT(L38,"0.00")&"m" -> 012-BH-06-R2-UDS 01-2.50-3.00m | AN38: =IF(N38=1,COUNTIF($N$27:N38,1),"") | AO38: =IF(O38=1,COUNTIF($O$27:O38,1),"") | AP38: =IF(P38=1,COUNTIF($P$27:P38,1),"") | AQ38: =IF(Q38=1,COUNTIF($Q$27:Q38,1),"") | AR38: =IF(R38=1,COUNTIF($R$27:R38,1),"") | AS38: =IF(S38=1,COUNTIF($S$27:S38,1),"") | AT38: =IF(T38=1,COUNTIF($T$27:T38,1),"") | AU38: =IF(U38=1,COUNTIF($U$27:U38,1),"") | AV38: =IF(V38=1,COUNTIF($V$27:V38,1),"") | AW38: =IF(W38=1,COUNTIF($W$27:W38,1),"") | AX38: =IF(X38=1,COUNTIF($X$27:X38,1),"") | AY38: =IF(Y38=1,COUNTIF($Y$27:Y38,1),"") | AZ38: =IF(Z38=1,COUNTIF($Z$27:Z38,1),"") | BA38: =IF(AA38=1,COUNTIF($AA$27:AA38,1),"") | BB38: =IF(AB38=1,COUNTIF($AB$27:AB38,1),"") | BC38: =IF(AC38=1,COUNTIF($AC$27:AC38,1),"") | BD38: =IF(AD38=1,COUNTIF($AD$27:AD38,1),"") | BE38: =IF(AE38=1,COUNTIF($AE$27:AE38,1),"") | BF38: =IF(AF38=1,COUNTIF($AF$27:AF38,1),"") | BG38: =IF(AG38=1,COUNTIF($AG$27:AG38,1),"") | BH38: =IF(AH38=1,COUNTIF($AH$27:AH38,1),"") | BI38: =IF(AI38=1,COUNTIF($AI$27:AI38,1),"") | BJ38: =IF(AJ38=1,COUNTIF($AJ$27:AJ38,1),"") | BK38: =IF(AK38=1,COUNTIF($AK$27:AK38,1),"") | BR38: - Triaxial CU | BS38: 2455 : 2015 | BT38: 23-MINEARTH-RM-LHU-TRX-CU-R0
B39: =B38+1 -> 13 | C39: =CONCATENATE(F39,"-",G39) -> BH-06-R2-UDS 02 | D39: =IF(E39="DS","Disturbed Sample", IF(E39="UDS","Undisturbed Sample", IF(E39="BS","Bulk Sample", IF(E39="CS","Composite Sample","")))) -> Undisturbed Sample | E39: UDS | F39: BH-06-R2 | G39: UDS 02 | H39: =IF(OR($H$12="",$H$11="",E39="",B39=""),"",RIGHT($H$12,2)&"-"&TEXT($H$11,"000")&"-"&E39&"-"&TEXT(B39,"000")) -> 26-001-UDS-013 | J39: =IF(AND(K39=0,L39=0), "-", TEXT(K39,"0.00")&" - "&TEXT(L39,"0.00")&" m") -> 4.00 - 0.50 m | K39: 4 | L39: 0.5 | M39: =TEXT(B39,"000")&"-"&C39&"-"&TEXT(K39,"0.00")&"-"&TEXT(L39,"0.00")&"m" -> 013-BH-06-R2-UDS 02-4.00-0.50m | AN39: =IF(N39=1,COUNTIF($N$27:N39,1),"") | AO39: =IF(O39=1,COUNTIF($O$27:O39,1),"") | AP39: =IF(P39=1,COUNTIF($P$27:P39,1),"") | AQ39: =IF(Q39=1,COUNTIF($Q$27:Q39,1),"") | AR39: =IF(R39=1,COUNTIF($R$27:R39,1),"") | AS39: =IF(S39=1,COUNTIF($S$27:S39,1),"") | AT39: =IF(T39=1,COUNTIF($T$27:T39,1),"") | AU39: =IF(U39=1,COUNTIF($U$27:U39,1),"") | AV39: =IF(V39=1,COUNTIF($V$27:V39,1),"") | AW39: =IF(W39=1,COUNTIF($W$27:W39,1),"") | AX39: =IF(X39=1,COUNTIF($X$27:X39,1),"") | AY39: =IF(Y39=1,COUNTIF($Y$27:Y39,1),"") | AZ39: =IF(Z39=1,COUNTIF($Z$27:Z39,1),"") | BA39: =IF(AA39=1,COUNTIF($AA$27:AA39,1),"") | BB39: =IF(AB39=1,COUNTIF($AB$27:AB39,1),"") | BC39: =IF(AC39=1,COUNTIF($AC$27:AC39,1),"") | BD39: =IF(AD39=1,COUNTIF($AD$27:AD39,1),"") | BE39: =IF(AE39=1,COUNTIF($AE$27:AE39,1),"") | BF39: =IF(AF39=1,COUNTIF($AF$27:AF39,1),"") | BG39: =IF(AG39=1,COUNTIF($AG$27:AG39,1),"") | BH39: =IF(AH39=1,COUNTIF($AH$27:AH39,1),"") | BI39: =IF(AI39=1,COUNTIF($AI$27:AI39,1),"") | BJ39: =IF(AJ39=1,COUNTIF($AJ$27:AJ39,1),"") | BK39: =IF(AK39=1,COUNTIF($AK$27:AK39,1),"") | BR39: - Triaxial CD | BS39: 2455 : 2015 | BT39: 23-MINEARTH-RM-LHU-CS-R0
B40: =B39+1 -> 14 | C40: =CONCATENATE(F40,"-",G40) -> BH-04R1-DS 01 | D40: =IF(E40="DS","Disturbed Sample", IF(E40="UDS","Undisturbed Sample", IF(E40="BS","Bulk Sample", IF(E40="CS","Composite Sample","")))) -> Disturbed Sample | E40: DS | F40: BH-04R1 | G40: DS 01 | H40: =IF(OR($H$12="",$H$11="",E40="",B40=""),"",RIGHT($H$12,2)&"-"&TEXT($H$11,"000")&"-"&E40&"-"&TEXT(B40,"000")) -> 26-001-DS-014 | J40: =IF(AND(K40=0,L40=0), "-", TEXT(K40,"0.00")&" - "&TEXT(L40,"0.00")&" m") -> 19.95 - 20.30 m | K40: 19.95 | L40: 20.3 | M40: =TEXT(B40,"000")&"-"&C40&"-"&TEXT(K40,"0.00")&"-"&TEXT(L40,"0.00")&"m" -> 014-BH-04R1-DS 01-19.95-20.30m | AN40: =IF(N40=1,COUNTIF($N$27:N40,1),"") | AO40: =IF(O40=1,COUNTIF($O$27:O40,1),"") | AP40: =IF(P40=1,COUNTIF($P$27:P40,1),"") | AQ40: =IF(Q40=1,COUNTIF($Q$27:Q40,1),"") | AR40: =IF(R40=1,COUNTIF($R$27:R40,1),"") | AS40: =IF(S40=1,COUNTIF($S$27:S40,1),"") | AT40: =IF(T40=1,COUNTIF($T$27:T40,1),"") | AU40: =IF(U40=1,COUNTIF($U$27:U40,1),"") | AV40: =IF(V40=1,COUNTIF($V$27:V40,1),"") | AW40: =IF(W40=1,COUNTIF($W$27:W40,1),"") | AX40: =IF(X40=1,COUNTIF($X$27:X40,1),"") | AY40: =IF(Y40=1,COUNTIF($Y$27:Y40,1),"") | AZ40: =IF(Z40=1,COUNTIF($Z$27:Z40,1),"") | BA40: =IF(AA40=1,COUNTIF($AA$27:AA40,1),"") | BB40: =IF(AB40=1,COUNTIF($AB$27:AB40,1),"") | BC40: =IF(AC40=1,COUNTIF($AC$27:AC40,1),"") | BD40: =IF(AD40=1,COUNTIF($AD$27:AD40,1),"") | BE40: =IF(AE40=1,COUNTIF($AE$27:AE40,1),"") | BF40: =IF(AF40=1,COUNTIF($AF$27:AF40,1),"") | BG40: =IF(AG40=1,COUNTIF($AG$27:AG40,1),"") | BH40: =IF(AH40=1,COUNTIF($AH$27:AH40,1),"") | BI40: =IF(AI40=1,COUNTIF($AI$27:AI40,1),"") | BJ40: =IF(AJ40=1,COUNTIF($AJ$27:AJ40,1),"") | BK40: =IF(AK40=1,COUNTIF($AK$27:AK40,1),"") | BQ40: 9 | BR40: Unconfined CompressionTest (UCS)/Uji Kuat Tekan Bebas | BS40: 3638:2012 | BT40: 23-MINEARTH-RM-LHU-UCT-R0
B41: =B40+1 -> 15 | C41: =CONCATENATE(F41,"-",G41) -> BH-04R1-DS 04 | D41: =IF(E41="DS","Disturbed Sample", IF(E41="UDS","Undisturbed Sample", IF(E41="BS","Bulk Sample", IF(E41="CS","Composite Sample","")))) -> Disturbed Sample | E41: DS | F41: BH-04R1 | G41: DS 04 | H41: =IF(OR($H$12="",$H$11="",E41="",B41=""),"",RIGHT($H$12,2)&"-"&TEXT($H$11,"000")&"-"&E41&"-"&TEXT(B41,"000")) -> 26-001-DS-015 | J41: =IF(AND(K41=0,L41=0), "-", TEXT(K41,"0.00")&" - "&TEXT(L41,"0.00")&" m") -> 25.23 - 25.43 m | K41: 25.23 | L41: 25.43 | M41: =TEXT(B41,"000")&"-"&C41&"-"&TEXT(K41,"0.00")&"-"&TEXT(L41,"0.00")&"m" -> 015-BH-04R1-DS 04-25.23-25.43m | AN41: =IF(N41=1,COUNTIF($N$27:N41,1),"") | AO41: =IF(O41=1,COUNTIF($O$27:O41,1),"") | AP41: =IF(P41=1,COUNTIF($P$27:P41,1),"") | AQ41: =IF(Q41=1,COUNTIF($Q$27:Q41,1),"") | AR41: =IF(R41=1,COUNTIF($R$27:R41,1),"") | AS41: =IF(S41=1,COUNTIF($S$27:S41,1),"") | AT41: =IF(T41=1,COUNTIF($T$27:T41,1),"") | AU41: =IF(U41=1,COUNTIF($U$27:U41,1),"") | AV41: =IF(V41=1,COUNTIF($V$27:V41,1),"") | AW41: =IF(W41=1,COUNTIF($W$27:W41,1),"") | AX41: =IF(X41=1,COUNTIF($X$27:X41,1),"") | AY41: =IF(Y41=1,COUNTIF($Y$27:Y41,1),"") | AZ41: =IF(Z41=1,COUNTIF($Z$27:Z41,1),"") | BA41: =IF(AA41=1,COUNTIF($AA$27:AA41,1),"") | BB41: =IF(AB41=1,COUNTIF($AB$27:AB41,1),"") | BC41: =IF(AC41=1,COUNTIF($AC$27:AC41,1),"") | BD41: =IF(AD41=1,COUNTIF($AD$27:AD41,1),"") | BE41: =IF(AE41=1,COUNTIF($AE$27:AE41,1),"") | BF41: =IF(AF41=1,COUNTIF($AF$27:AF41,1),"") | BG41: =IF(AG41=1,COUNTIF($AG$27:AG41,1),"") | BH41: =IF(AH41=1,COUNTIF($AH$27:AH41,1),"") | BI41: =IF(AI41=1,COUNTIF($AI$27:AI41,1),"") | BJ41: =IF(AJ41=1,COUNTIF($AJ$27:AJ41,1),"") | BK41: =IF(AK41=1,COUNTIF($AK$27:AK41,1),"") | BQ41: 10 | BR41: Direct shear/Uji Kuat Geser Langsung
B42: =B41+1 -> 16 | C42: =CONCATENATE(F42,"-",G42) -> BH-05-R-DS 01 | D42: =IF(E42="DS","Disturbed Sample", IF(E42="UDS","Undisturbed Sample", IF(E42="BS","Bulk Sample", IF(E42="CS","Composite Sample","")))) -> Disturbed Sample | E42: DS | F42: BH-05-R | G42: DS 01 | H42: =IF(OR($H$12="",$H$11="",E42="",B42=""),"",RIGHT($H$12,2)&"-"&TEXT($H$11,"000")&"-"&E42&"-"&TEXT(B42,"000")) -> 26-001-DS-016 | J42: =IF(AND(K42=0,L42=0), "-", TEXT(K42,"0.00")&" - "&TEXT(L42,"0.00")&" m") -> 3.92 - 4.15 m | K42: 3.92 | L42: 4.15 | M42: =TEXT(B42,"000")&"-"&C42&"-"&TEXT(K42,"0.00")&"-"&TEXT(L42,"0.00")&"m" -> 016-BH-05-R-DS 01-3.92-4.15m | AN42: =IF(N42=1,COUNTIF($N$27:N42,1),"") | AO42: =IF(O42=1,COUNTIF($O$27:O42,1),"") | AP42: =IF(P42=1,COUNTIF($P$27:P42,1),"") | AQ42: =IF(Q42=1,COUNTIF($Q$27:Q42,1),"") | AR42: =IF(R42=1,COUNTIF($R$27:R42,1),"") | AS42: =IF(S42=1,COUNTIF($S$27:S42,1),"") | AT42: =IF(T42=1,COUNTIF($T$27:T42,1),"") | AU42: =IF(U42=1,COUNTIF($U$27:U42,1),"") | AV42: =IF(V42=1,COUNTIF($V$27:V42,1),"") | AW42: =IF(W42=1,COUNTIF($W$27:W42,1),"") | AX42: =IF(X42=1,COUNTIF($X$27:X42,1),"") | AY42: =IF(Y42=1,COUNTIF($Y$27:Y42,1),"") | AZ42: =IF(Z42=1,COUNTIF($Z$27:Z42,1),"") | BA42: =IF(AA42=1,COUNTIF($AA$27:AA42,1),"") | BB42: =IF(AB42=1,COUNTIF($AB$27:AB42,1),"") | BC42: =IF(AC42=1,COUNTIF($AC$27:AC42,1),"") | BD42: =IF(AD42=1,COUNTIF($AD$27:AD42,1),"") | BE42: =IF(AE42=1,COUNTIF($AE$27:AE42,1),"") | BF42: =IF(AF42=1,COUNTIF($AF$27:AF42,1),"") | BG42: =IF(AG42=1,COUNTIF($AG$27:AG42,1),"") | BH42: =IF(AH42=1,COUNTIF($AH$27:AH42,1),"") | BI42: =IF(AI42=1,COUNTIF($AI$27:AI42,1),"") | BJ42: =IF(AJ42=1,COUNTIF($AJ$27:AJ42,1),"") | BK42: =IF(AK42=1,COUNTIF($AK$27:AK42,1),"") | BR42: Direct shear UU | BS42: 3420:2016 | BT42: 23-MINEARTH-RM-LHU-DS-UU-R0
B43: =B42+1 -> 17 | C43: =CONCATENATE(F43,"-",G43) -> BH-03-R-DS 01 | D43: =IF(E43="DS","Disturbed Sample", IF(E43="UDS","Undisturbed Sample", IF(E43="BS","Bulk Sample", IF(E43="CS","Composite Sample","")))) -> Disturbed Sample | E43: DS | F43: BH-03-R | G43: DS 01 | H43: =IF(OR($H$12="",$H$11="",E43="",B43=""),"",RIGHT($H$12,2)&"-"&TEXT($H$11,"000")&"-"&E43&"-"&TEXT(B43,"000")) -> 26-001-DS-017 | J43: =IF(AND(K43=0,L43=0), "-", TEXT(K43,"0.00")&" - "&TEXT(L43,"0.00")&" m") -> 2.50 - 3.00 m | K43: 2.5 | L43: 3 | M43: =TEXT(B43,"000")&"-"&C43&"-"&TEXT(K43,"0.00")&"-"&TEXT(L43,"0.00")&"m" -> 017-BH-03-R-DS 01-2.50-3.00m | AN43: =IF(N43=1,COUNTIF($N$27:N43,1),"") | AO43: =IF(O43=1,COUNTIF($O$27:O43,1),"") | AP43: =IF(P43=1,COUNTIF($P$27:P43,1),"") | AQ43: =IF(Q43=1,COUNTIF($Q$27:Q43,1),"") | AR43: =IF(R43=1,COUNTIF($R$27:R43,1),"") | AS43: =IF(S43=1,COUNTIF($S$27:S43,1),"") | AT43: =IF(T43=1,COUNTIF($T$27:T43,1),"") | AU43: =IF(U43=1,COUNTIF($U$27:U43,1),"") | AV43: =IF(V43=1,COUNTIF($V$27:V43,1),"") | AW43: =IF(W43=1,COUNTIF($W$27:W43,1),"") | AX43: =IF(X43=1,COUNTIF($X$27:X43,1),"") | AY43: =IF(Y43=1,COUNTIF($Y$27:Y43,1),"") | AZ43: =IF(Z43=1,COUNTIF($Z$27:Z43,1),"") | BA43: =IF(AA43=1,COUNTIF($AA$27:AA43,1),"") | BB43: =IF(AB43=1,COUNTIF($AB$27:AB43,1),"") | BC43: =IF(AC43=1,COUNTIF($AC$27:AC43,1),"") | BD43: =IF(AD43=1,COUNTIF($AD$27:AD43,1),"") | BE43: =IF(AE43=1,COUNTIF($AE$27:AE43,1),"") | BF43: =IF(AF43=1,COUNTIF($AF$27:AF43,1),"") | BG43: =IF(AG43=1,COUNTIF($AG$27:AG43,1),"") | BH43: =IF(AH43=1,COUNTIF($AH$27:AH43,1),"") | BI43: =IF(AI43=1,COUNTIF($AI$27:AI43,1),"") | BJ43: =IF(AJ43=1,COUNTIF($AJ$27:AJ43,1),"") | BK43: =IF(AK43=1,COUNTIF($AK$27:AK43,1),"") | BR43: Direct shear CU | BS43: 2813 : 2008 | BT43: 23-MINEARTH-RM-LHU-DS_CU-R0
B44: =B43+1 -> 18 | C44: =CONCATENATE(F44,"-",G44) -> BH-03-R-DS 02 | D44: =IF(E44="DS","Disturbed Sample", IF(E44="UDS","Undisturbed Sample", IF(E44="BS","Bulk Sample", IF(E44="CS","Composite Sample","")))) -> Disturbed Sample | E44: DS | F44: BH-03-R | G44: DS 02 | H44: =IF(OR($H$12="",$H$11="",E44="",B44=""),"",RIGHT($H$12,2)&"-"&TEXT($H$11,"000")&"-"&E44&"-"&TEXT(B44,"000")) -> 26-001-DS-018 | J44: =IF(AND(K44=0,L44=0), "-", TEXT(K44,"0.00")&" - "&TEXT(L44,"0.00")&" m") -> 6.45 - 6.96 m | K44: 6.45 | L44: 6.96 | M44: =TEXT(B44,"000")&"-"&C44&"-"&TEXT(K44,"0.00")&"-"&TEXT(L44,"0.00")&"m" -> 018-BH-03-R-DS 02-6.45-6.96m | AN44: =IF(N44=1,COUNTIF($N$27:N44,1),"") | AO44: =IF(O44=1,COUNTIF($O$27:O44,1),"") | AP44: =IF(P44=1,COUNTIF($P$27:P44,1),"") | AQ44: =IF(Q44=1,COUNTIF($Q$27:Q44,1),"") | AR44: =IF(R44=1,COUNTIF($R$27:R44,1),"") | AS44: =IF(S44=1,COUNTIF($S$27:S44,1),"") | AT44: =IF(T44=1,COUNTIF($T$27:T44,1),"") | AU44: =IF(U44=1,COUNTIF($U$27:U44,1),"") | AV44: =IF(V44=1,COUNTIF($V$27:V44,1),"") | AW44: =IF(W44=1,COUNTIF($W$27:W44,1),"") | AX44: =IF(X44=1,COUNTIF($X$27:X44,1),"") | AY44: =IF(Y44=1,COUNTIF($Y$27:Y44,1),"") | AZ44: =IF(Z44=1,COUNTIF($Z$27:Z44,1),"") | BA44: =IF(AA44=1,COUNTIF($AA$27:AA44,1),"") | BB44: =IF(AB44=1,COUNTIF($AB$27:AB44,1),"") | BC44: =IF(AC44=1,COUNTIF($AC$27:AC44,1),"") | BD44: =IF(AD44=1,COUNTIF($AD$27:AD44,1),"") | BE44: =IF(AE44=1,COUNTIF($AE$27:AE44,1),"") | BF44: =IF(AF44=1,COUNTIF($AF$27:AF44,1),"") | BG44: =IF(AG44=1,COUNTIF($AG$27:AG44,1),"") | BH44: =IF(AH44=1,COUNTIF($AH$27:AH44,1),"") | BI44: =IF(AI44=1,COUNTIF($AI$27:AI44,1),"") | BJ44: =IF(AJ44=1,COUNTIF($AJ$27:AJ44,1),"") | BK44: =IF(AK44=1,COUNTIF($AK$27:AK44,1),"") | BR44: Direct shear CD | BS44: 2813:2008 | BT44: 23-MINEARTH-RM-LHU-DS-CD-R0
B45: =B44+1 -> 19 | C45: =CONCATENATE(F45,"-",G45) -> BH-07-R-DS 01 | D45: =IF(E45="DS","Disturbed Sample", IF(E45="UDS","Undisturbed Sample", IF(E45="BS","Bulk Sample", IF(E45="CS","Composite Sample","")))) -> Disturbed Sample | E45: DS | F45: BH-07-R | G45: DS 01 | H45: =IF(OR($H$12="",$H$11="",E45="",B45=""),"",RIGHT($H$12,2)&"-"&TEXT($H$11,"000")&"-"&E45&"-"&TEXT(B45,"000")) -> 26-001-DS-019 | J45: =IF(AND(K45=0,L45=0), "-", TEXT(K45,"0.00")&" - "&TEXT(L45,"0.00")&" m") -> 10.95 - 11.17 m | K45: 10.95 | L45: 11.17 | M45: =TEXT(B45,"000")&"-"&C45&"-"&TEXT(K45,"0.00")&"-"&TEXT(L45,"0.00")&"m" -> 019-BH-07-R-DS 01-10.95-11.17m | AN45: =IF(N45=1,COUNTIF($N$27:N45,1),"") | AO45: =IF(O45=1,COUNTIF($O$27:O45,1),"") | AP45: =IF(P45=1,COUNTIF($P$27:P45,1),"") | AQ45: =IF(Q45=1,COUNTIF($Q$27:Q45,1),"") | AR45: =IF(R45=1,COUNTIF($R$27:R45,1),"") | AS45: =IF(S45=1,COUNTIF($S$27:S45,1),"") | AT45: =IF(T45=1,COUNTIF($T$27:T45,1),"") | AU45: =IF(U45=1,COUNTIF($U$27:U45,1),"") | AV45: =IF(V45=1,COUNTIF($V$27:V45,1),"") | AW45: =IF(W45=1,COUNTIF($W$27:W45,1),"") | AX45: =IF(X45=1,COUNTIF($X$27:X45,1),"") | AY45: =IF(Y45=1,COUNTIF($Y$27:Y45,1),"") | AZ45: =IF(Z45=1,COUNTIF($Z$27:Z45,1),"") | BA45: =IF(AA45=1,COUNTIF($AA$27:AA45,1),"") | BB45: =IF(AB45=1,COUNTIF($AB$27:AB45,1),"") | BC45: =IF(AC45=1,COUNTIF($AC$27:AC45,1),"") | BD45: =IF(AD45=1,COUNTIF($AD$27:AD45,1),"") | BE45: =IF(AE45=1,COUNTIF($AE$27:AE45,1),"") | BF45: =IF(AF45=1,COUNTIF($AF$27:AF45,1),"") | BG45: =IF(AG45=1,COUNTIF($AG$27:AG45,1),"") | BH45: =IF(AH45=1,COUNTIF($AH$27:AH45,1),"") | BI45: =IF(AI45=1,COUNTIF($AI$27:AI45,1),"") | BJ45: =IF(AJ45=1,COUNTIF($AJ$27:AJ45,1),"") | BK45: =IF(AK45=1,COUNTIF($AK$27:AK45,1),"") | BR45: Direct shear Residual | BS45: 2813:2008 | BT45: 23-MINEARTH-RM-LHU-DS-RES-R0
...

Sheet WS-PP
A1: LEMBAR PENGUJIAN / TESTING WORKSHEET
A2: UJI SIFAT FISIK TANAH
A3: SOIL PHYSICAL PROPERTIES TEST
A5: AL
A7: KODE LABORATORIUM / Laboratory Id. | D7: =IFERROR(INDEX('DATA INDUK'!$H$27:$H$152,MATCH(ROW(D1),'DATA INDUK'!$AN$27:$AN$152,0)),"") -> 26-001-DS-001
D8: =IFERROR(INDEX('DATA INDUK'!$H$27:$H$38,MATCH(ROW(D2),'DATA INDUK'!$Z$27:$Z$38,0)),"")
A9: NO. CONTOH / Sample Id. | D9: {=IF( INDEX('DATA INDUK'!$I$28:$I$151, MATCH($D$7,'DATA INDUK'!$H$28:$H$151,0))="", $D$7, _xlfn.TEXTJOIN(CHAR(10),TRUE, _xlfn._xlws.FILTER('DATA INDUK'!$C$28:$C$151, 'DATA INDUK'!$I$28:$I$151= INDEX('DATA INDUK'!$I$28:$I$151, MATCH($D$7,'DATA INDUK'!$H$28:$H$151,0)) )) )} -> #N/A | G9: =INDEX('DATA INDUK'!$I$28:$I$151, MATCH($D$7,'DATA INDUK'!$H$28:$H$151,0)) -> #N/A | Q9: DIUJI OLEH / Tested By | T9: =IF($D$7="","",U9) -> RIZKI | U9: RIZKI | Y9: ="TTD_"&T9&"" -> TTD_RIZKI
A10: SUMBER CONTOH / SAMPLE SOURCE | D10: {=IF( INDEX('DATA INDUK'!$I$28:$I$151, MATCH($D$7,'DATA INDUK'!$H$28:$H$151,0))="", INDEX('DATA INDUK'!$C$28:$C$151, MATCH($D$7,'DATA INDUK'!$H$28:$H$151,0)) & " (" & INDEX('DATA INDUK'!$J$28:$J$151, MATCH($D$7,'DATA INDUK'!$H$28:$H$151,0)) & ")", _xlfn.TEXTJOIN(CHAR(10),TRUE, _xlfn._xlws.FILTER( 'DATA INDUK'!$C$28:$C$151 & " (" & 'DATA INDUK'!$J$28:$J$151 & ")", 'DATA INDUK'!$I$28:$I$151= INDEX('DATA INDUK'!$I$28:$I$151, MATCH($D$7,'DATA INDUK'!$H$28:$H$151,0)) )) )} -> #N/A | G10: KODE | Q10: DIPERIKSA OLEH / Checked By | T10: =IF($D$7="","",U10) -> NOUFAL | U10: NOUFAL | Y10: =IF(T9=T10,"TTD_","TTD_"&T10&"") -> TTD_NOUFAL
A11: JENIS CONTOH / Sample Type | D11: =IFERROR(INDEX('DATA INDUK'!$D$27:$D$152,MATCH(ROW(D1),'DATA INDUK'!$AQ$27:$AQ$152,0)),"") -> Disturbed Sample | G11: =IFERROR(INDEX($R$23:$R$34, MATCH(D12,$U$23:$U$34,0)), "CHECK DESKRIPSI") -> CL | Q11: DISETUJUI OLEH | T11: =IF($D$7="","",U11) -> A.SUMARTADJI | U11: A.SUMARTADJI | Y11: ="TTD_"&T11&"" -> TTD_A.SUMARTADJI
A12: DESKRIPSI TANAH / Soil Description | D12: Lempung / Clay | Q12: TGL. PENGUJIAN / Date Tested | T12: 46027
A13: WARNA TANAH / Soil Color | D13: Coklat Kekuningan / Yellowish Brown
B21: SPECIFIC GRAVITY TEST (SNI 1964 : 2008) | R21: DB DESKRIPSI
R22: Kode | S22: Deskripsi Indonesia | T22: English | U22: Bilingual
B23: Pycnometer No. | H23: 1 | I23: 2 | R23: CL | S23: Lempung | T23: Clay | U23: Lempung / Clay
B24: Wt. Of dry Soil (A) | G24: g | H24: 10.487 | I24: 10.139 | R24: CLS | S24: Lempung Pasiran | T24: Sandy Clay | U24: Lempung Pasiran / Sandy Clay
B25: Temperature (T) | G25: 0C | H25: 22 | I25: 22 | R25: CSL | S25: Lempung Lanauan | T25: Silty Clay | U25: Lempung Lanauan / Silty Clay
B26: Wt. Pycnometer + Water + Soil (B) | G26: g | H26: 170.13 | I26: 144.183 | R26: CLG | S26: Lempung Kerikilan | T26: Gravelly Clay | U26: Lempung Kerikilan / Gravelly Clay | Z26: temperature | AA26: relative density | AB26: correction | AE26: 45819.675 | AG26: 0
B27: Wt Pycnometer + Water at T 0C (C) | G27: g | H27: =IF(OR(H23="",H24="",H25="",H26=""),"",((VLOOKUP(H25,$Z$27:$AB$40,2)/$AA$30)*(VLOOKUP(H23,$AD$28:$AE$85,2)-VLOOKUP(H23,$AH$29:$AI$86,2)))+VLOOKUP(H23,$AH$29:$AI$86,2,FALSE)) -> 163.5539 | I27: =IF(OR(I23="",I24="",I25="",I26=""),"",((VLOOKUP(I25,$Z$27:$AB$40,2)/$AA$30)*(VLOOKUP(I23,$AD$28:$AE$85,2)-VLOOKUP(I23,$AH$29:$AI$86,2)))+VLOOKUP(I23,$AH$29:$AI$86,2,FALSE)) -> 137.8194 | R27: SD | S27: Pasir | T27: Sand | U27: Pasir / Sand | AA27: of water | AB27: factor of K | AD27: calibration of picnometer + water at 25 C | AH27: berat picnometer | AK27: LAB CONFIG. BERAT CAWAN
B28: A+(C-B) | G28: g | H28: =IF(OR(H23="",H24="",H25="",H26=""),"",H24+(H27-H26)) -> 3.9109036 | I28: =IF(OR(I23="",I24="",I25="",I26=""),"",I24+(I27-I26)) -> 3.7753991 | R28: SDC | S28: Pasir Lempungan | T28: Clayey Sand | U28: Pasir Lempungan / Clayey Sand | Z28: 18 | AA28: 0.9986244 | AB28: 1.0004 | AD28: No | AE28: weight (gr) | AH28: No. | AI28: berat (gr) | AK28: 1 | AL28: 9.03
B29: Specific Gravity (Gs) | H29: =IF(OR(H24="",H25="",H26=""),"",(H24/H28)*(VLOOKUP(H25,$Z$27:$AB$40,3))) -> 2.6804049 | I29: =IF(OR(I24="",I25="",I26=""),"",(I24/I28)*(VLOOKUP(I25,$Z$27:$AB$40,3))) -> 2.6844697 | R29: SDS | S29: Pasir Lanauan | T29: Silty Sand | U29: Pasir Lanauan / Silty Sand | Z29: 19 | AA29: 0.9984347 | AB29: 1.0002 | AD29: 1 | AE29: 163.599 | AH29: 1 | AI29: 59.49 | AK29: 2 | AL29: 8.842
B30: SPECIFIC GRAVITY Average (Gs) | H30: =IF(OR(H23="",H24="",H25="",H26=""),"",AVERAGE(H29:I29)) -> 2.6824373 | R30: SDG | S30: Pasir Kerikilan | T30: Gravelly Sand | U30: Pasir Kerikilan / Gravelly Sand | Z30: 20 | AA30: 0.9982343 | AB30: 1 | AD30: 2 | AE30: 137.862 | AH30: 2 | AI30: 39.514 | AK30: 3 | AL30: 9.041
R31: SLT | S31: Lanau | T31: Silt | U31: Lanau / Silt | Z31: 21 | AA31: 0.9980233 | AB31: 0.9998 | AD31: 3 | AE31: 151.183 | AH31: 3 | AI31: 51.446 | AK31: 4 | AL31: 8.936
R32: SLC | S32: Lanau Lempungan | T32: Clayey Silt | U32: Lanau Lempungan / Clayey Silt | Z32: 22 | AA32: 0.9978019 | AB32: 0.9996 | AD32: 4 | AE32: 153.062 | AH32: 4 | AI32: 53.871 | AK32: 5 | AL32: 8.856
R33: SLS | S33: Lanau Pasiran | T33: Sandy Silt | U33: Lanau Pasiran / Sandy Silt | Z33: 23 | AA33: 0.9975702 | AB33: 0.9993 | AD33: 5 | AE33: 152.278 | AH33: 5 | AI33: 53.022 | AK33: 6 | AL33: 8.726
R34: GR | S34: Kerikil | T34: Gravel | U34: Kerikil / Gravel | Z34: 24 | AA34: 0.9973286 | AB34: 0.9991 | AD34: 6 | AE34: 153.265 | AH34: 6 | AI34: 54.015 | AK34: 7 | AL34: 8.882
Z35: 25 | AA35: 0.997077 | AB35: 0.9989 | AD35: 7 | AE35: 153.689 | AH35: 7 | AI35: 59.771 | AK35: 8 | AL35: 8.818
A36: KODE LABORATORIUM / Laboratory Id. | D36: =IFERROR(INDEX('DATA INDUK'!$H$27:$H$152,MATCH(ROW(D1),'DATA INDUK'!$AO$27:$AO$152,0)),"") -> 26-001-DS-001 | Z36: 26 | AA36: 0.9968156 | AB36: 0.9986 | AD36: 8 | AE36: 158.886 | AH36: 8 | AI36: 62.706 | AK36: 9 | AL36: 8.799
A37: AL | Z37: 27 | AA37: 0.9965451 | AB37: 0.9983 | AD37: 9 | AE37: 158.674 | AH37: 9 | AI37: 61.072 | AK37: 10 | AL37: 8.793
B38: MOISTURE CONTENT TEST (SNI 1965 : 2008) | Z38: 28 | AA38: 0.9962652 | AB38: 0.998 | AD38: 10 | AE38: 153.58 | AH38: 10 | AI38: 53.568 | AK38: 11 | AL38: 8.804
B39: No. Container | H39: 18 | I39: 77 | Z39: 29 | AA39: 0.9959761 | AB39: 0.9977 | AD39: 11 | AE39: 156.951 | AH39: 11 | AI39: 58.058 | AK39: 12 | AL39: 8.928
B40: Wt. Container + Wet Soil | G40: g | H40: 63.231 | I40: 48.72 | Z40: 30 | AA40: 0.995678 | AB40: 0.9974 | AD40: 12 | AE40: 157.653 | AH40: 12 | AI40: 63.726 | AK40: 13 | AL40: 8.877
B41: Wt. Container + Dry Soil | G41: g | H41: 49.533 | I41: 38.822 | AD41: 13 | AE41: 155.423 | AH41: 13 | AI41: 60.343 | AK41: 14 | AL41: 8.892
B42: Wt. Container | G42: g | H42: =IFERROR(VLOOKUP(H39,$AK$28:$AL144,2,0),"") -> 8.934 | I42: =IFERROR(VLOOKUP(I39,$AK$28:$AL144,2,0),"") -> 8.843 | AD42: 14 | AE42: 156.63 | AH42: 14 | AI42: 59.336 | AK42: 15 | AL42: 8.993
B43: Wt. Water | G43: g | H43: =H40-H41 -> 13.698 | I43: =I40-I41 -> 9.898 | J43: =IF(OR(J39="",J40="",J41="",J42=""),"",J40-J41) | AD43: 15 | AE43: 159.75 | AH43: 15 | AI43: 63.115 | AK43: 16 | AL43: 8.909
B44: Wt. Dry Soil | G44: g | H44: =+H41-H42 -> 40.599 | I44: =+I41-I42 -> 29.979 | J44: =IF(OR(J39="",J40="",J41="",J42=""),"",J41-J42) | AD44: 16 | AE44: 159.772 | AH44: 16 | AI44: 62.986 | AK44: 17 | AL44: 9.049
B45: Moisture Content (w) | G45: % | H45: =+(H43/H44)*100 -> 33.739747 | I45: =+(I43/I44)*100 -> 33.016445 | J45: =IF(OR(J39="",J40="",J41="",J42=""),"",(J43/J44)*100) | AD45: 17 | AE45: 156.251 | AH45: 17 | AI45: 59.396 | AK45: 18 | AL45: 8.934
B46: MOISTURE CONTENT Average (w) | G46: % | I46: =IF(OR(I39="",I40="",I41="",I42=""),"",AVERAGE(H45:I45)) -> 33.378096 | AD46: 18 | AE46: 155.575 | AH46: 18 | AI46: 59.034 | AK46: 19 | AL46: 8.961
AD47: 19 | AE47: 156.809 | AH47: 19 | AI47: 60.026 | AK47: 20 | AL47: 8.776
A48: KODE LABORATORIUM / Laboratory Id. | D48: =IFERROR(INDEX('DATA INDUK'!$H$27:$H$152,MATCH(ROW(D1),'DATA INDUK'!$AP$27:$AP$152,0)),"") -> 26-001-DS-001 | AD48: 20 | AE48: 155.062 | AH48: 20 | AI48: 55.041 | AK48: 21 | AL48: 8.903
A49: AM | Z49: no | AA49: berat (gr) | AB49: vol (cm3) | AK49: 22 | AL49: 8.843
...

Sheet LHU_PP
D1: LABORATORIUM MEKANIKA TANAH
D2: PT.TERRAFORMA GEOTEKNIK INDONESIA
F3: LABORATORY TEST REPORT
A6: No. Laporan / Report No. | E6: =": " & IF('DATA INDUK'!$H$17="","",'DATA INDUK'!$H$17) -> : 23/MGS/53/II/2026
A7: Revisi / Revision | E7: =": "&IF('DATA INDUK'!H18="","",'DATA INDUK'!H18) -> : R0 | I7: Tgl. Laporan / Report Date | M7: =": "&IF('DATA INDUK'!H19="","",TEXT('DATA INDUK'!H19,"dd mmmm yyyy")) -> : 29 January 2026 | U7: Halaman/Pages | X7: =": 1 dari 1" -> : 1 dari 1
A9: INFORMASI PROYEK /PROJECT INFORMATION | N9: INFORMASI CONTOH / SAMPLE INFORMATION
A11: Nama Proyek / Project Name | N11: Kode Laboratorium / Laboratory Id.
A12: =IF('DATA INDUK'!H2="","",'DATA INDUK'!H2) -> BSI Candrian Waste Dump Extension Study | N12: =IF('WS-PP'!D7="","",'WS-PP'!D7) -> 26-001-DS-001
A13: Lokasi Proyek / Location | E13: =": "&IF('DATA INDUK'!H3="","",'DATA INDUK'!H3) -> : Banyuwangi - JAWA TIMUR | N13: Sumber Contoh / Sample Source | S13: : | T13: =IF('WS-PP'!D10="","",'WS-PP'!D10) -> #N/A
A14: No. PO / PO Number | E14: =": "&IF('DATA INDUK'!H9="","",'DATA INDUK'!H9) -> : PO-GQT-001
N15: Jenis Contoh / Sample Type | S15: : | T15: =IF('WS-PP'!D11="","",'WS-PP'!D11) -> Disturbed Sample
A17: IDENTITAS KLIEN / CLIENT INFORMATION | N17: Deskripsi Tanah / Soil Description | S17: : | T17: =IF('WS-PP'!D12="","",'WS-PP'!D12) -> Lempung / Clay
N18: Warna Tanah / Soil Color | S18: : | T18: =IF('WS-PP'!D13="","",'WS-PP'!D13) -> Coklat Kekuningan / Yellowish Brown
A19: Klien / Client | E19: =": "&IF('DATA INDUK'!H4="","",'DATA INDUK'!H4) -> : PT. GEOLAND QUATRO TECHNOLAB
N20: Tgl.Diterima / Date Received | S20: : | T20: =IF('DATA INDUK'!H13="","",TEXT('DATA INDUK'!H13,"dd mmmm yyyy")) -> 05 January 2026
A21: Alamat / Address | E21: =": "&IF('DATA INDUK'!H6="","",'DATA INDUK'!H6) -> : Kab. Bandung - JAWA BARAT
N22: Tgl Pengujian / Date Tested | S22: : | T22: =IF('WS-PP'!T12="","",TEXT('WS-PP'!T12,"dd mmmm yyyy")) -> 05 January 2026
A26: ='WS-PP'!A2 -> UJI SIFAT FISIK TANAH
A27: ='WS-PP'!A3 -> SOIL PHYSICAL PROPERTIES TEST
E34: Parameter | L34: Metode / Method | O34: Hasil / Result
E36: Berat Jenis Butiran / Specific Gravity, Gs | L36: ='DATA INDUK'!$BS$30 -> 1964:2008 | O36: ='WS-PP'!H66 -> 2.6824373
E37: Kadar Air / Moisture Content, w (%) | L37: ='DATA INDUK'!$BS$31 -> 1965:2008 | O37: ='WS-PP'!H67 -> 33.378096
E38: Berat Isi Basah / Bulk Density (g/cm³) | L38: ='DATA INDUK'!$BS$35 -> 03-3637-1994 | O38: ='WS-PP'!H68 -> 1.6647356
E39: Berat Isi Kering / Dry Unit Weight (g/m³) | L39: ='DATA INDUK'!$BS$35 -> 03-3637-1994 | O39: ='WS-PP'!H69 -> 1.2481327 | AB39: ="LHU No. : "& IF('DATA INDUK'!$H$17="","",'DATA INDUK'!$H$17) -> LHU No. : 23/MGS/53/II/2026
AB40: ="LAB ID. : "&$N$12&"" -> LAB ID. : 26-001-DS-001
AA41: Physical Properties | AB41: ="TEST TYPE : "&AA41&"" -> TEST TYPE : Physical Properties
AB42: ="DATE : "&TEXT('DATA INDUK'!$H$19,"yyyy-mm-dd") -> DATE : 2026-01-29
U58: SCAN FOR REPORT VERIFICATION
C59: DIUJI OLEH / | H59: DIPERIKSA OLEH / | M59: DISETUJUI OLEH /
C60: TESTED BY | H60: CHECKED BY | M60: APPROVED BY
C64: =IF('WS-PP'!T9="","",'WS-PP'!T9) -> RIZKI | H64: =IF(C64='WS-PP'!T10," - ",'WS-PP'!T10) -> NOUFAL | M64: =IF('WS-PP'!T11="","",'WS-PP'!T11) -> A.SUMARTADJI
C65: Teknisi/Analis | H65: Koordinator Teknis | M65: Kepala Laboratorium
C66: Tgl./Date : | E66: =IF('DATA INDUK'!$H$19="","",'DATA INDUK'!$H$19-1) -> 46050 | H66: Tgl./Date : | J66: =IF('DATA INDUK'!$H$19="","",'DATA INDUK'!$H$19-1) -> 46050 | M66: Tgl./Date : | P66: =IF('DATA INDUK'!$H$19="","",'DATA INDUK'!$H$19-1) -> 46050
A68: KETERANGAN / NOTES | D68: - Laporan hasil Uji ini hanya berlaku untuk contoh yang diuji | M68: - | N68: This test report applies only to the tested sample.
D69: - Dilarang memperbanyak laporan tanpa ijin tertulis dari Laboratorium | M69: - | N69: This report shall not be reproduced except in full without written approval from
D70: Mekanika Tanah PT. TERRAFORMA GEOTEKNIK INDONESIA. | N70: PT. TERRAFORMA GEOTEKNIK INDONESIA Soil Mechanics Laboratory.
D71: - Laboratorium tidak bertanggung jawab atas kegiatan pengambilan | M71: - | N71: The laboratory is not responsible for sampling,handling and sample transportation
D72: dan transportasi contoh yang dilakukan oleh pihak lain. | N72: conducted by others.
U73: ='DATA INDUK'!$BT$30 -> 23-MINEARTH-RM-LHU-PP-R0
A74: Jl. Leuwisari VII No.23, Kota Bandung | K74: Telp : 022-4572503 | T74: Email : Soil_test@minearth.co.id
...

Sheet WS-ATB
A1: LEMBAR PENGUJIAN / TESTING WORKSHEET
A2: UJI BATAS CAIR DAN BATAS PLASTIS
A3: LIQUID LIMIT AND PLASTIC LIMIT TEST
A5: AN
A7: KODE LABORATORIUM / Laboratory Id. | D7: =IFERROR(INDEX('DATA INDUK'!$H$27:$H$152,MATCH(ROW(D1),'DATA INDUK'!$AQ$27:$AQ$152,0)),"") -> 26-001-DS-001
D8: =IFERROR(INDEX('DATA INDUK'!$H$27:$H$38,MATCH(ROW(D2),'DATA INDUK'!$Z$27:$Z$38,0)),"")
A9: NO. CONTOH / Sample Id. | D9: {=IF( INDEX('DATA INDUK'!$I$28:$I$151, MATCH($D$7,'DATA INDUK'!$H$28:$H$151,0))="", INDEX('DATA INDUK'!$C$28:$C$151, MATCH($D$7,'DATA INDUK'!$H$28:$H$151,0)) & " (" & INDEX('DATA INDUK'!$J$28:$J$151, MATCH($D$7,'DATA INDUK'!$H$28:$H$151,0)) & ")", _xlfn.TEXTJOIN(CHAR(10),TRUE, _xlfn._xlws.FILTER( 'DATA INDUK'!$C$28:$C$151 & " (" & 'DATA INDUK'!$J$28:$J$151 & ")", 'DATA INDUK'!$I$28:$I$151= INDEX('DATA INDUK'!$I$28:$I$151, MATCH($D$7,'DATA INDUK'!$H$28:$H$151,0)) )) )} -> #N/A | L9: DIUJI OLEH / Tested By | O9: =IF($D$7="","",P9) -> NOUFAL | P9: NOUFAL | T9: ="TTD_"&O9&"" -> TTD_NOUFAL
A10: KEDALAMAN / Depth (m) | L10: DIPERIKSA OLEH / Checked By | O10: =IF($D$7="","",P10) -> NOUFAL | P10: NOUFAL | T10: =IF(O9=O10,"TTD_","TTD_"&O10&"") -> TTD_
A11: JENIS CONTOH / Sample Type | D11: =IFERROR(INDEX('DATA INDUK'!$D$27:$D$152,MATCH(ROW(D1),'DATA INDUK'!$AQ$27:$AQ$152,0)),"") -> Disturbed Sample | F11: KODE | L11: DISETUJUI OLEH | O11: =IF($D$7="","",P11) -> A.SUMARTADJI | P11: A.SUMARTADJI | T11: ="TTD_"&O11&"" -> TTD_A.SUMARTADJI
A12: DESKRIPSI TANAH / Soil Description | D12: Lempung / Clay | F12: =IFERROR(INDEX($W$29:$W$40, MATCH(D12,$Z$29:$Z$40,0)), "CHECK DESKRIPSI") -> CL | L12: TGL. PENGUJIAN / Date Tested | O12: 46035
A13: WARNA TANAH / Soil Color | D13: Coklat / Brown
D14: =IFERROR(INDEX('DATA INDUK'!$H$27:$H$38,MATCH(ROW(D9),'DATA INDUK'!$Z$27:$Z$38,0)),"")
A26: UJI BATAS CAIR
Q27: LAB CONFIG. BERAT CAWAN | W27: DB DESKRIPSI
A28: PARAMETER | F28: 1 | G28: 2 | H28: 3 | I28: 4 | L28: Vertical Iine | N28: Horizontal Line | Q28: 1 | R28: 9.03 | T28: x | U28: Y | W28: Kode | X28: Deskripsi Indonesia | Y28: English | Z28: Bilingual
A29: Banyak Pukulan/No. of blows | F29: 40 | G29: 31 | H29: 20 | I29: 12 | L29: X | M29: Y | N29: X | O29: Y | Q29: 2 | R29: 8.842 | T29: =F29 -> 40 | U29: =IF($D$7="",NA(),F37) -> 43.333333 | W29: CL | X29: Lempung | Y29: Clay | Z29: Lempung / Clay
A30: No. Cawan | F30: 50 | G30: 42 | H30: 63 | I30: 22 | L30: 25 | M30: 0 | N30: 1 | O30: =L41 -> 46.879858 | Q30: 3 | R30: 9.041 | T30: =G29 -> 31 | U30: =IF($D$7="",NA(),G37) -> 45.272466 | W30: CLS | X30: Lempung Pasiran | Y30: Sandy Clay | Z30: Lempung Pasiran / Sandy Clay
A31: Berat cawan kosong / wt. empty can | E31: ( gr ) | F31: =IFERROR(VLOOKUP(F30,$Q$28:$R$149,2,0),"") -> 8.781 | G31: =IFERROR(VLOOKUP(G30,$Q$28:$R$149,2,0),"") -> 8.8 | H31: =IFERROR(VLOOKUP(H30,$Q$28:$R$149,2,0),"") -> 8.86 | I31: =IFERROR(VLOOKUP(I30,$Q$28:$R$149,2,0),"") -> 8.843 | L31: 25 | M31: =L41 -> 46.879858 | N31: 25 | O31: =O30 -> 46.879858 | Q31: 4 | R31: 8.936 | T31: =H29 -> 20 | U31: =IF($D$7="",NA(),H37) -> 48.219351 | W31: CSL | X31: Lempung Lanauan | Y31: Silty Clay | Z31: Lempung Lanauan / Silty Clay
A32: Berat cawan + Tanah basah / wt.of can + moist soil | E32: ( gr ) | F32: 26.325 | G32: 28.021 | H32: 27.672 | I32: 29.368 | Q32: 5 | R32: 8.856 | T32: =I29 -> 12 | U32: =IF($D$7="",NA(),I37) -> 51.789676 | W32: CLG | X32: Lempung Kerikilan | Y32: Gravelly Clay | Z32: Lempung Kerikilan / Gravelly Clay
A33: Berat cawan + Tanah Kering / wt. of can + dry soil | E33: ( gr ) | F33: 21.021 | G33: 22.031 | H33: 21.552 | I33: 22.365 | L33: Graphic Trend line | Q33: 6 | R33: 8.726 | W33: SD | X33: Pasir | Y33: Sand | Z33: Pasir / Sand
A34: Berat tanah basah / wt. of moist soil | E34: ( gr ) | F34: =IF(OR(F31="",F32=""),"",(F32-F31)) -> 17.544 | G34: =IF(OR(G31="",G32=""),"",(G32-G31)) -> 19.221 | H34: =IF(OR(H31="",H32=""),"",(H32-H31)) -> 18.812 | I34: =IF(OR(I31="",I32=""),"",(I32-I31)) -> 20.525 | Q34: 7 | R34: 8.882 | T34: X | U34: Y | W34: SDC | X34: Pasir Lempungan | Y34: Clayey Sand | Z34: Pasir Lempungan / Clayey Sand
